Workbook
Name a: Qüestionari!$A$1:$J$38
Name AccionsGD: Llistes!#REF!
Name Ajuntament: Llistes!$E$3:$E$313
Name Àrea: Llistes!$G$3:$G$173
Name Dificultat: Llistes!$M$3:$M$5
Name Impacte: Llistes!$K$3:$K$5
Name ImpacteCost: Llistes!$K$3:$K$5
Name Organisme: Llistes!$C$3:$C$21
Name Rols: Llistes!$I$3:$I$4
Name SiNo: #REF!
Name Termini: Llistes!$O$3:$O$7
Name Tipus: Llistes!$A$3:$A$6

Sheet Instruccions
B4: Qüestionari d'avaluació de la maduresa
B5: Instruccions
B9: - El qüestionari s'ha de respondre a les pestanyes Info, Sistemes i Qüestionari
B11: - L'emplenament de les dades s'ha de realitzar segons les especificacions de la pestanya Llegenda.
B13: - El personal designat per l'Ajuntament, Organisme o Àrea és el responsables d'emplenar el qüestionari, amb el suport de l'Oficina de Govern de la dada de la DIBA.
B15: - La pestanya Info ajudarà a identificar les persones clau en l'àmbit de les dades de l'Ajuntament o Organisme, així com quina és la seva organització per àrees o dominis de dades, Processos clau, Projectes estratègics i Objectius del PAM.
B17: - La pestanya Sistemes dona suport a la identificació dels sistemes de dades, de manera que hauria d'estar complimentat amb el suport de l'arquitecte de dades i dels administradors de sistemes,
B19: - La pestanya Qüestionari dona suport a l'avaluació de la maduresa del govern de la dada, ha de complimentar-se pel Responsable de dades amb suport de l'Oficina de Govern de la dada de la DIBA.
B21: - Per tal que el qüestionari es consideri complet, hauran d'estar emplenats tots els atributs obligatoris detallats a la pestanya Llegenda.
B23: v20250305

Sheet MapaResponsables
B4: Qüestionari d'avaluació de la situació actual
B6: Mapa Responsables
B8: Data | C8: 45716
B9: Avaluador
B10: Àmbit | C10: Ajuntament
B11: =C10 -> Ajuntament | C11: Berga
B12: Àrea | C12: <Totes>
B15: Rols Clau
C16: Rol | D16: Responsable | E16: Correu responsable | F16: Telèfon responsable | G16: Observacions
C17: Responsable de dades (Data Stewart)
C18: Propietari de dades (Data Owner)
B23: Processos clau
C24: Nom del procés | D24: Responsable | E24: Correu responsable | F24: Telèfon responsable | G24: Observacions
B31: Projectes estratègics (p.e. PAM, Dades obertes etc.)
C32: Nom del projecte | D32: Responsable | E32: Correu responsable | F32: Telèfon responsable | G32: Observacions
B39: Altres responsables
C40: Àmbit de responsabilitat | D40: Responsable | E40: Correu responsable | F40: Telèfon responsable | G40: Observacions
C41: Responsable de Tecnologia
C42: Responsable de Seguretat

Sheet Qüestionari
B2: Qüestionari d'avaluació de la maduresa
D4: Id. | E4: Procés | F4: Qüestió | G4: Resposta | H4: Observacions | I4: Evidències i documentació | M4: Respostes | R4: Accions
B5: Govern | J5: =AVERAGE(J6,J9,J12,J14) -> 3.1666667 | M5: 1 | N5: 2 | O5: 3 | P5: 4 | R5: 1 | S5: 2 | T5: 3 | U5: 4 | W5: Àmbit | X5: Procés | Y5: Pla acció | Z5: Prioritat | AA5: Prioritat | AB5: Calendari
E6: Establiment d'estàndards, polítiques, bones pràctiques i procediments | J6: =SUM(J7:J8)/COUNT(J7:J8) -> 2 | W6: =IF(B5="",W5,B5) -> Govern | X6: =IF(E6="",X5,E6) -> Establiment d'estàndards, polítiques, bones pràctiques i procediments
D7: GA01 | F7: Existeix un marc de Govern de la dada establert? (Polítiques, estàndards, procediments, inventari de dades, bones pràctiques, …) | G7: Si, però cada Àrea identifica i desenvolupa els seus processos amb el seu propi criteri | J7: =SUMIF(M7:P7,G7,$M$5:$P$5) -> 2 | L7: =D7 -> GA01 | M7: No, no existeix un marc de Govern de la dada establert | N7: Si, però cada Àrea identifica i desenvolupa els seus processos amb el seu propi criteri | O7: Sí, hi ha un marc de Govern de la dada establert i publicat, que coneixen i utilitzen les diferents Àrees | P7: Sí, hi ha un marc de Govern de la dada establert i publicat, que coneixen i utilitzen les diferents Àrees, i que està subjecte a processos de millora continua de manera periòdica. | R7: Definir un Marc de Govern de la dada de marea senzilla i escalable alineat amb els objectius de l'Ajuntament/Organisme, definint regles clares de gestió de les dades (qualitat, seguretat i accés), rols i responsabilitats i processos clau) | S7: Establir un marc de Govern del Dada unificat per garantir coherència i alineació entre àrees fent un treball de centralització de la governança i unificació de criteris. | T7: Assegurar la aplicació del Marc de Govern de la dada de manera efectiva, avaluant el compliment i efectivitat, i executant processos de millora contínua | U7: - | W7: =IF(B6="",W6,B6) -> Govern | X7: =IF(E7="",X6,E7) -> Establiment d'estàndards, polítiques, bones pràctiques i procediments | Y7: =IF(OR($G7=$M7,$G7=""),CONCATENATE(J7," - ",$R7),IF($G7=$N7,CONCATENATE(J7," - ",$S7),IF($G7=$O7,CONCATENATE(J7," - ",$T7),""))) -> 2 - Establir un marc de Govern del Dada unificat per garantir coherència i alineació entre àrees fent un treball de centralització de la governança i unificació de criteris. | Z7: =J7 -> 2
D8: GA02 | F8: Estan documentades les Polítiques de Govern de la dada i aquestes estan orientades a optimitzar el valor de les dades? (estan publicades, el personal les coneix, s'actualitzen periòdicament, i es mesura i monitoritza el compliment) | G8: Sí, hi ha algunes polítiques, però no s'implementen adequadament | J8: =SUMIF(M8:P8,G8,$M$5:$P$5) -> 2 | L8: =D8 -> GA02 | M8: No, no hi ha polítiques per a la optimització del valor de les dades | N8: Sí, hi ha algunes polítiques, però no s'implementen adequadament | O8: Sí, hi ha polítiques per a la optimització del valor de les dades i s'implementen adequadament | P8: Sí, hi ha polítiques per a la optimització del valor de les dades, s'implementen adequadament, i es porten a terme accions periòdiques de millora continua | R8: Cal definir la Política de Govern de la dada, es pot iniciar amb regles bàsiques que defineixin les responsabilitats, classifiquin les dades, estableixin normes d'accés i seguretat, i projectar un Inventari de dades. Per tal de fer aquest camí més senzill i aprofitant l'experiència de la DIBA, aquesta facilita el procediment d'adhesió a les seves Polítiques. | S8: Cal revisar que les Polítiques definides son aplicables, si es poden simplificar i assegurar un lideratge en l'àmbit del Govern de la dada. Addicionalment, seria positiu reforçar la comunicació, assegurar la capacitació dels implicats i portar a terme accions que facin que el Govern de la dada s'integri a la operació diària. | T8: És recomanable revisar les Polítiques periòdicament per tal d'optimitzar-les i assegurar que s'adapten a les noves necessitats. | U8: _ | W8: =IF(B7="",W7,B7) -> Govern | X8: =IF(E8="",X7,E8) -> Establiment d'estàndards, polítiques, bones pràctiques i procediments | Y8: =IF(OR($G8=$M8,$G8=""),CONCATENATE(J8," - ",$R8),IF($G8=$N8,CONCATENATE(J8," - ",$S8),IF($G8=$O8,CONCATENATE(J8," - ",$T8),""))) -> 2 - Cal revisar que les Polítiques definides son aplicables, si es poden simplificar i assegurar un lideratge en l'àmbit del Govern de la dada. Addicionalment, seria positiu reforçar la comunicació, assegurar la capacitació dels implicats i portar a terme accions que facin que el Govern de la dada s'integri a la operació diària. | Z8: =J8 -> 2
E9: Establiment d'estratègies de dades | J9: =SUM(J10:J11)/COUNT(J10:J11) -> 4 | W9: =IF(B8="",W8,B8) -> Govern | X9: =IF(E9="",X8,E9) -> Establiment d'estratègies de dades
D10: GB01 | F10: Existeix una estratègia de dades que inclogui iniciatives, objectius i fites, i aquesta es coneguda per l'Ajuntament/Organisme? | G10: Si, existeix una estratègia de dades coneguda que inclou el detall d'iniciatives, objectius i fites, i es fa un seguiment periòdic del compliment. | J10: =SUMIF(M10:P10,G10,$M$5:$P$5) -> 4 | L10: =D10 -> GB01 | M10: No, no hi ha una estratègia de dades coneguda | N10: Sí, existeix una estratègia de dades però no es molt coneguda o no defineix clarament les iniciatives, objectius o fites. | O10: Si, existeix una estratègia de dades coneguda que inclou el detall d'iniciatives, objectius i fites | P10: Si, existeix una estratègia de dades coneguda que inclou el detall d'iniciatives, objectius i fites, i es fa un seguiment periòdic del compliment. | R10: Definir una estratègia de dades de manera clara i accessible per a tots els actors implicats, que detalli els objectius estratègics, concreti iniciatives/un pla d'acció amb prioritats i involucrar als equips de treball | S10: Revisar 'l'estratègia de dades per concretar iniciatives, objectius mesurables i fites clares, i assegurar que tots els equips implicats la coneguin i facin seva | T10: Assegurar el compliment de l'estratègia de dades fent un seguiment regular de les iniciatives, revisant els objectius i les fites i fomentant la millora continua | U10: - | W10: =IF(B9="",W9,B9) -> Govern | X10: =IF(E10="",X9,E10) -> Establiment d'estratègies de dades | Y10: =IF(OR($G10=$M10,$G10=""),CONCATENATE(J10," - ",$R10),IF($G10=$N10,CONCATENATE(J10," - ",$S10),IF($G10=$O10,CONCATENATE(J10," - ",$T10),""))) | Z10: =J10 -> 4
D11: GB02 | F11: Hi ha mètriques d'utilització i rendiment de les dades? | G11: Si, hi ha mètriques d'utilització i rendiment a les àrees, es fa un seguiment i utilització d'aquestes dades, i periòdicament es revisen (definició, necessitat, llindars, etc.) per tal de garantir una millora contínua | J11: =SUMIF(M11:P11,G11,$M$5:$P$5) -> 4 | L11: =D11 -> GB02 | M11: No, no hi ha mètriques d'utilització i rendiment de les dades | N11: Si, per a alguna àrea hi ha alguna mètrica d'utilització i rendiment, però no es fa un seguiment | O11: Si, hi ha mètriques d'utilització i rendiment a les àrees, i es fa un seguiment i utilització d'aquestes dades | P11: Si, hi ha mètriques d'utilització i rendiment a les àrees, es fa un seguiment i utilització d'aquestes dades, i periòdicament es revisen (definició, necessitat, llindars, etc.) per tal de garantir una millora contínua | R11: Cal establir indicadors clau (KPIs) per a mesurar la qualitat, accessibilitat i efectivitat de les dades. Aquestes mètriques haurien de mesurar qualitats com la precisió, integritat, consistència i rendiment de les dades. Això facilitarà la gestió i millora de les dades. | S11: Es recomana fer un monitoreig de les mètriques d'ús i rendiment per a analitzar les mètriques de manera periòdica, i estendre l'activitat a les principals àrees de l'Ajuntament o Organització. Fer el seguiment d'aquestes mètriques ajudarà a identificar possibles millores. | T11: Es recomana optimitzar els processos d'anàlisi per tal d'identificar tendències i punts de millora de manera proactiva, i fer revisions periòdiques per alinear les mètriques amb els objectius estratègics (p.e. el PAM de l'Ajuntament). | U11: _ | W11: =IF(B10="",W10,B10) -> Govern | X11: =IF(E11="",X10,E11) -> Establiment d'estratègies de dades | Y11: =IF(OR($G11=$M11,$G11=""),CONCATENATE(J11," - ",$R11),IF($G11=$N11,CONCATENATE(J11," - ",$S11),IF($G11=$O11,CONCATENATE(J11," - ",$T11),""))) | Z11: =J11 -> 4
E12: Establiment d'estructures organitzacionals | J12: =SUM(J13)/COUNT(J13) -> 3 | W12: =IF(B11="",W11,B11) -> Govern | X12: =IF(E12="",X11,E12) -> Establiment d'estructures organitzacionals
D13: GC01 | F13: Existeix una estructura organitzativa formal per al Govern de la dada i es porten a terme comitès de dades? | G13: Si, existeix una estructura organitzativa formal per al Govern de la dada i si es porten a terme comitès de dades de manera regular | J13: =SUMIF(M13:P13,G13,$M$5:$P$5) -> 3 | L13: =D13 -> GC01 | M13: No existeix una estructura organitzativa formal per al Govern de la dada ni es porten a terme comitès de dades | N13: Si, existeix una estructura organitzativa formal per al Govern de la dada, però no es porten a terme comitès de dades de manera regular | O13: Si, existeix una estructura organitzativa formal per al Govern de la dada i si es porten a terme comitès de dades de manera regular | P13: Si, existeix una estructura organitzativa formal per al Govern de la dada i si es porten a terme comitès de dades de manera regular amb un alt grau de col·laboració entre les diferents àrees | R13: Crear una estructura organitzativa mínima viable que permeti iniciar la governança de manera efectiva, definint rols clau, com Responsable de dades i Propietari de dades, i establir un Comitè de Dades per a la coordinació entre àrees | S13: Establir reunions del comitè de dades amb la periodicitat que sigui necessari per fer seguiment de la governança de les dades | T13: Assegurar que les decisions i accions derivades dels comitès estan alineats amb l'estratègia, avaluar i optimitzar els resultats dels Comitès | U13: - | W13: =IF(B12="",W12,B12) -> Govern | X13: =IF(E13="",X12,E13) -> Establiment d'estructures organitzacionals | Y13: =IF(OR($G13=$M13,$G13=""),CONCATENATE(J13," - ",$R13),IF($G13=$N13,CONCATENATE(J13," - ",$S13),IF($G13=$O13,CONCATENATE(J13," - ",$T13),""))) -> 3 - Assegurar que les decisions i accions derivades dels comitès estan alineats amb l'estratègia, avaluar i optimitzar els resultats dels Comitès | Z13: =J13 -> 3
E14: Gestió de recursos humans | J14: =SUM(J15:J17)/COUNT(J15:J17) -> 3.6666667 | W14: =IF(B13="",W13,B13) -> Govern | X14: =IF(E14="",X13,E14) -> Gestió de recursos humans
D15: GD01 | F15: Estan definits els rols i responsabilitats per al Govern de la dada (al menys Responsable de les dades i Propietari de les dades)? | G15: Sí, estan definits els rols i responsabilitats, es revisen periòdicament i es forma al personal assignat per a garantir una millora continua | J15: =SUMIF(M15:P15,G15,$M$5:$P$5) -> 4 | L15: =D15 -> GD01 | M15: No, no estan definits els rols i responsabilitats adequadament | N15: Sí, estan definits els rols i responsabilitats, però no estan assignats a personal qualificat. | O15: Sí, estan definits els rols i responsabilitats, i estan assignats a personal qualificat | P15: Sí, estan definits els rols i responsabilitats, es revisen periòdicament i es forma al personal assignat per a garantir una millora continua | R15: És fonamental assignar definir i assignar els rols de Propietari de la dada (Data Owners) i de Responsable de la dada (Data Steward) per a garantitzar la qualitat, seguretat i us adequat de la informació. La definició d'aquests rols ha de deixar clares les funcions i les responsabilitats. | S15: Cal identificar a les persones adequades dins de l'Ajuntament o Organisme i formalitzar l'assignació de rols, comunicar clarament les responsabilitats, capacitar-los i fer seguiment de les seves funcions. | T15: Cal considerar establir mètriques d'ús i rendiment, assegurar que s'utilitzen a la presa de decisions, i implantar processos de millora contínua. | U15: _ | W15: =IF(B14="",W14,B14) -> Govern | X15: =IF(E15="",X14,E15) -> Gestió de recursos humans | Y15: =IF(OR($G15=$M15,$G15=""),CONCATENATE(J15," - ",$R15),IF($G15=$N15,CONCATENATE(J15," - ",$S15),IF($G15=$O15,CONCATENATE(J15," - ",$T15),""))) | Z15: =J15 -> 4
D16: GD02 | F16: Està definit i assignat el rol de Responsable de les dades? | G16: Sí, està definit i assignat i el personal coneix clarament les seves funcions i es fan accions periòdiques per tal de garantir una millora continua | J16: =SUMIF(M16:P16,G16,$M$5:$P$5) -> 4 | L16: =D16 -> GD02 | M16: No, no està definit clarament aquest rol i no hi ha personal assignat | N16: Sí, està definit i assignat però, però el personal no coneix clarament les seves funcions | O16: Sí, està definit i assignat, i el personal coneix clarament les seves funcions | P16: Sí, està definit i assignat i el personal coneix clarament les seves funcions i es fan accions periòdiques per tal de garantir una millora continua | R16: S'hauria de definir clarament les funcions del Responsable de dades (Data Stewart), identificar els perfils adequats dins de l'Ajuntament o Organisme i capacitar-los per a portar a terme les seves funcions de manera efectiva. | S16: Cal capacitar al Responsable de dades (Data Stewart) i comunicar clarament les seves funcions dins l'Ajuntament o Organisme per a que pugui desenvolupar les seves funcions de manera efectiva. | T16: És recomanable establir mètriques, optimitzar processos contínuament i fomentar la col·laboració entre els diferents rols per enfortir la governança de dades. | U16: _ | W16: =IF(B15="",W15,B15) -> Govern | X16: =IF(E16="",X15,E16) -> Gestió de recursos humans | Y16: =IF(OR($G16=$M16,$G16=""),CONCATENATE(J16," - ",$R16),IF($G16=$N16,CONCATENATE(J16," - ",$S16),IF($G16=$O16,CONCATENATE(J16," - ",$T16),""))) | Z16: =J16 -> 4
D17: GD03 | F17: Està identificat i es coneix el propietari de les dades de cada Àrea? | G17: Sí, està definit i assignat, i el personal a cada àrea coneix clarament les seves funcions. | J17: =SUMIF(M17:P17,G17,$M$5:$P$5) -> 3 | L17: =D17 -> GD03 | M17: No, no està definit clarament aquest rol i no hi ha personal assignat | N17: Sí, està definit i assignat però, però el personal no coneix clarament les seves funcions, o hi ha alguna àrea per a les que no hi ha personal assignat | O17: Sí, està definit i assignat, i el personal a cada àrea coneix clarament les seves funcions. | P17: Sí, està definit i assignat, i el personal a cada àrea coneix clarament les seves funcions, i es fan accions periòdiques per tal de garantir una millora continua | R17: És important definir el rol de Propietari de dades (Data Owner) i assignar-lo a persones amb gran coneixement funcional i responsabilitat sobre les dades. El Responsable de dades ha de ser responsable de la qualitat , seguretat i accés a les dades, i tenir l'autoritat per a la presa de decisions i garantir que les dades es gestionen adequadament. | S17: Cal comunicar l'existència del rol de Propietari de dades, el personal que té assignat i les responsabilitats de manera clara dins l'Ajuntament o Organisme. | T17: És interessant garantir l'autoritat i visibilitat dels Propietaris de dades, assegurant que tingui els recursos i que s'implementen activitats de millora contínua. | U17: _ | W17: =IF(B16="",W16,B16) -> Govern | X17: =IF(E17="",X16,E17) -> Gestió de recursos humans | Y17: =IF(OR($G17=$M17,$G17=""),CONCATENATE(J17," - ",$R17),IF($G17=$N17,CONCATENATE(J17," - ",$S17),IF($G17=$O17,CONCATENATE(J17," - ",$T17),""))) -> 3 - És interessant garantir l'autoritat i visibilitat dels Propietaris de dades, assegurant que tingui els recursos i que s'implementen activitats de millora contínua. | Z17: =J17 -> 3
B18: Gestió de dades | J18: =AVERAGE(J19,J22,J24,J27,J29) -> 1.4 | W18: =IF(B17="",W17,B17) -> Govern | X18: =IF(E18="",X17,E18) -> Gestió de recursos humans
E19: Gestió de seguretat de dades | J19: =SUM(J20:J21)/COUNT(J20:J21) -> 1.5 | W19: =IF(B18="",W18,B18) -> Gestió de dades | X19: =IF(E19="",X18,E19) -> Gestió de seguretat de dades
D20: MA01 | F20: Existeixen Polítiques de seguretat i privadesa de les dades alineades amb les regulacions vigents i s'avalua el seu compliment? | G20: Si, hi ha Polítiques de seguretat i privadesa alineades amb les regulacions vigents, però no son conegudes pel personal i/o no s'avalua el seu compliment | J20: =SUMIF(M20:P20,G20,$M$5:$P$5) -> 2 | L20: =D20 -> MA01 | M20: No, no hi ha Polítiques de seguretat i privadesa alineades amb les regulacions vigents | N20: Si, hi ha Polítiques de seguretat i privadesa alineades amb les regulacions vigents, però no son conegudes pel personal i/o no s'avalua el seu compliment | O20: Si, hi ha Polítiques de seguretat i privadesa alineades amb les regulacions vigents que son conegudes pel personal, i es fan revisions del seu compliment | P20: Si, hi ha Polítiques de seguretat i privadesa alineades amb les regulacions vigents que son conegudes pel personal, i es fan revisions del seu compliment. Addicionalment es fan revisions d'aquestes per tal assegurar l'alineament amb noves regulacions i per optimitzar els processos | R20: Definir les Polítiques de seguretat i privadesa alineades amb les regulacions vigents. Per tal de fer aquest camí més senzill i aprofitant l'experiència de la DIBA, aquesta facilita el procediment d'adhesió a les seves Polítiques. | S20: Divulgar les Polítiques de seguretat i privadesa entre el personal per tal que aquestes siguin conegudes, i fer avaluacions periòdiques del seu compliment | T20: Fer revisions periòdiques de les Polítiques per tal d'assegurar que aquestes es mantenen actualitzades amb les regulacions vigents i cercar oportunitats de millora continua | U20: - | W20: =IF(B19="",W19,B19) -> Gestió de dades | X20: =IF(E20="",X19,E20) -> Gestió de seguretat de dades | Y20: =IF(OR($G20=$M20,$G20=""),CONCATENATE(J20," - ",$R20),IF($G20=$N20,CONCATENATE(J20," - ",$S20),IF($G20=$O20,CONCATENATE(J20," - ",$T20),""))) -> 2 - Divulgar les Polítiques de seguretat i privadesa entre el personal per tal que aquestes siguin conegudes, i fer avaluacions periòdiques del seu compliment | Z20: =J20 -> 2
D21: MA02 | F21: Les dades s'identifiquen i classifiquen en nivells de sensibilitat en funció de l'àmbit d'actuació dins de l'Ajuntament/Organisme? | G21: No, no es classifiquen les dades en funció de la seva sensibilitat | J21: =SUMIF(M21:P21,G21,$M$5:$P$5) -> 1 | L21: =D21 -> MA02 | M21: No, no es classifiquen les dades en funció de la seva sensibilitat | N21: Si, algunes dades es classifiquen en funció de la seva sensibilitat i/o el personal no coneix aquesta classificació | O21: Si, les dades es classifiquen en funció de la seva sensibilitat i el personal coneix i utilitza les dades d'acord a aquesta classificació | P21: Si, les dades es classifiquen en funció de la seva sensibilitat i el personal coneix i utilitza les dades d'acord a aquesta classificació, i es fan auditories periòdiques per tal de detectar possibles errors i fer millora continua | R21: Identificar i classificar les dades clau en funció de la seva sensibilitat | S21: Assegurar que estan identificades i classificades totes les dades clau en funció de la seva sensibilitat i que el personal utilitza les dades d'acord a aquesta classificació | T21: Es recomana establir auditories que ajudin a detectar errors i definir accions de millora continua | U21: _ | W21: =IF(B20="",W20,B20) -> Gestió de dades | X21: =IF(E21="",X20,E21) -> Gestió de seguretat de dades | Y21: =IF(OR($G21=$M21,$G21=""),CONCATENATE(J21," - ",$R21),IF($G21=$N21,CONCATENATE(J21," - ",$S21),IF($G21=$O21,CONCATENATE(J21," - ",$T21),""))) -> 1 - Identificar i classificar les dades clau en funció de la seva sensibilitat | Z21: =J21 -> 1
E22: Gestió de dades històriques | J22: =SUM(J23)/COUNT(J23) -> 1 | W22: =IF(B21="",W21,B21) -> Gestió de dades | X22: =IF(E22="",X21,E22) -> Gestió de dades històriques
D23: MB01 | F23: Existeixen Polítiques d'arxivat i restauració de dades? | G23: No, no hi ha Polítiques d'arxivat i restauració de dades | J23: =SUMIF(M23:P23,G23,$M$5:$P$5) -> 1 | L23: =D23 -> MB01 | M23: No, no hi ha Polítiques d'arxivat i restauració de dades | N23: Si, hi ha Polítiques d'arxivat i restauració de dades, però no s'apliquen adequadament | O23: Si, hi ha Polítiques d'arxivat i restauració de dades que s'apliquen adequadament | P23: Si, hi ha Polítiques d'arxivat i restauració de dades que s'apliquen adequadament i son revisades de forma periòdica per tal de millorar-les | R23: Definir les Polítiques d'arxivat i restauració de dades . Per tal de fer aquest camí més senzill i aprofitant l'experiència de la DIBA, aquesta facilita el procediment d'adhesió a les seves Polítiques. | S23: Revisar i implicar al personal en l'aplicació de les Polítiques d'arxivat i restauració de dades | T23: Portar a terme accions de millora continua de les Polítiques d'arxivat i restauració de dades | U23: - | W23: =IF(B22="",W22,B22) -> Gestió de dades | X23: =IF(E23="",X22,E23) -> Gestió de dades històriques | Y23: =IF(OR($G23=$M23,$G23=""),CONCATENATE(J23," - ",$R23),IF($G23=$N23,CONCATENATE(J23," - ",$S23),IF($G23=$O23,CONCATENATE(J23," - ",$T23),""))) -> 1 - Definir les Polítiques d'arxivat i restauració de dades . Per tal de fer aquest camí més senzill i aprofitant l'experiència de la DIBA, aquesta facilita el procediment d'adhesió a les seves Polítiques. | Z23: =J23 -> 1
E24: Gestió de fonts i destinacions de dades | J24: =SUM(J25:J26)/COUNT(J25:J26) -> 1.5 | W24: =IF(B23="",W23,B23) -> Gestió de dades | X24: =IF(E24="",X23,E24) -> Gestió de fonts i destinacions de dades
D25: MC01 | F25: Existeix un Inventari de dades, que inclou conjunts de dades, dades mestre i de referència, i metadades, i on s'identifiquen les fonts de dades de l'Ajuntament/Organisme que és compartit i conegut pel personal? | G25: Si, existeix el Catàleg de dades i l'Inventari de dades, però aquest no és complet i/o el seu us és bastant limitat | J25: =SUMIF(M25:P25,G25,$M$5:$P$5) -> 2 | L25: =D25 -> MC01 | M25: No, no existeix un Catàleg de dades ni Inventari de dades | N25: Si, existeix el Catàleg de dades i l'Inventari de dades, però aquest no és complet i/o el seu us és bastant limitat | O25: Si, existeix el Catàleg de dades i l'Inventari de dades, on s'identifiquen les fonts de dades de l'Ajuntament/Organisme, les dades clau, i son coneguts i utilitzats de manera regular | P25: Si, existeix el Catàleg de dades i l'Inventari de dades, on s'identifiquen les fonts de dades de l'Ajuntament/Organisme, les dades clau, son coneguts i utilitzats de manera regular, i regularment es revisa per tal de fer millora continua i avaluar el seu us | R25: Iniciar les tasques d'implementació de l'Inventari de dades | S25: Ampliar l'Inventari de dades a totes les dades clau, i difondre i promoure la seva utilització | T25: Fer revisions periòdiques de l'Inventari de dades per tal d'assegurar que aquest es manté actualitzat i cercar oportunitats de millora continua | U25: - | W25: =IF(B24="",W24,B24) -> Gestió de dades | X25: =IF(E25="",X24,E25) -> Gestió de fonts i destinacions de dades | Y25: =IF(OR($G25=$M25,$G25=""),CONCATENATE(J25," - ",$R25),IF($G25=$N25,CONCATENATE(J25," - ",$S25),IF($G25=$O25,CONCATENATE(J25," - ",$T25),""))) -> 2 - Ampliar l'Inventari de dades a totes les dades clau, i difondre i promoure la seva utilització | Z25: =J25 -> 2
D26: MC02 | F26: Estan identificades les dades i fonts de dades externes i aquestes es gestionen mitjançant acords formals i s'estableixen controls de qualitat específics? | G26: No, no estan identificades les dades ni fonts de dades externes | J26: =SUMIF(M26:P26,G26,$M$5:$P$5) -> 1 | L26: =D26 -> MC02 | M26: No, no estan identificades les dades ni fonts de dades externes | N26: Si, estan identificades les dades i les fonts de dades externes però no hi ha una gestió específica sobre aquestes | O26: Si, estan identificades les dades i les fonts de dades externes i es fa una gestió específica sobre aquestes per tal d'assegurar que son de qualitat i segures | P26: Si, estan identificades les dades i les fonts de dades externes i es fa una gestió específica sobre aquestes per tal d'assegurar que son de qualitat i segures, i es fan avaluacions periòdiques per tal de trobar punts de millora continua | R26: Identificar les fonts de dades externes i les dades associades per tal de poder fer una gestió específica d'aquestes | S26: Fer una gestió específica sobre les fonts de dades i dades externes per tal d'assegurar que son de qualitat i segures | T26: Establir mecanismes de millora continua als processos de gestió de dades i fonts de dades externes | U26: _ | W26: =IF(B25="",W25,B25) -> Gestió de dades | X26: =IF(E26="",X25,E26) -> Gestió de fonts i destinacions de dades | Y26: =IF(OR($G26=$M26,$G26=""),CONCATENATE(J26," - ",$R26),IF($G26=$N26,CONCATENATE(J26," - ",$S26),IF($G26=$O26,CONCATENATE(J26," - ",$T26),""))) -> 1 - Identificar les fonts de dades externes i les dades associades per tal de poder fer una gestió específica d'aquestes | Z26: =J26 -> 1
E27: Gestió de la integració de les dades | J27: =SUM(J28)/COUNT(J28) -> 1 | W27: =IF(B26="",W26,B26) -> Gestió de dades | X27: =IF(E27="",X26,E27) -> Gestió de la integració de les dades
D28: MD01 | F28: Existeixen Polítiques i procediments d'integració, gestió i utilització de les dades? | G28: No, no hi ha Polítiques ni procediments d'integració, gestió ni utilització de les dades | J28: =SUMIF(M28:P28,G28,$M$5:$P$5) -> 1 | L28: =D28 -> MD01 | M28: No, no hi ha Polítiques ni procediments d'integració, gestió ni utilització de les dades | N28: Si, hi ha Polítiques i procediments d'integració, gestió i utilització de les dades, però no s'apliquen adequadament | O28: Si, hi ha Polítiques i procediments d'integració, gestió i utilització de les dades, que s'apliquen adequadament | P28: Si, hi ha Polítiques i procediments d'integració, gestió i utilització de les dades, que s'apliquen adequadament, que son avaluats paròdicament per tal de trobar punts de millora continua | R28: Definir les Polítiques i procediments d'integració, gestió i utilització de les dades . Per tal de fer aquest camí més senzill i aprofitant l'experiència de la DIBA, aquesta facilita el procediment d'adhesió a les seves Polítiques. | S28: Revisar i implicar al personal en l'aplicació de les Polítiques i procediments d'integració, gestió i utilització de les dades | T28: Portar a terme accions de millora continua de les Polítiques i procediments d'integració, gestió i utilització de les dades | U28: - | W28: =IF(B27="",W27,B27) -> Gestió de dades | X28: =IF(E28="",X27,E28) -> Gestió de la integració de les dades | Y28: =IF(OR($G28=$M28,$G28=""),CONCATENATE(J28," - ",$R28),IF($G28=$N28,CONCATENATE(J28," - ",$S28),IF($G28=$O28,CONCATENATE(J28," - ",$T28),""))) -> 1 - Definir les Polítiques i procediments d'integració, gestió i utilització de les dades . Per tal de fer aquest camí més senzill i aprofitant l'experiència de la DIBA, aquesta facilita el procediment d'adhesió a les seves Polítiques. | Z28: =J28 -> 1
E29: Gestió de Dades Mestre i Dades de Referència | J29: =SUM(J30)/COUNT(J30) -> 2 | W29: =IF(B28="",W28,B28) -> Gestió de dades | X29: =IF(E29="",X28,E29) -> Gestió de Dades Mestre i Dades de Referència
D30: ME01 | F30: Estan identificades les Dades Mestre i les Dades de Referència? Dades Mestre son les dades que representen la informació fonamental per a l'Ajuntament/Organisme (p.e. nom, cognoms, tributs, empleats, etc.) Dades de Referència son les dades que s'utilitzen como referència o estàndard per a contextualitzar altres dades (p.e. codis postals, municipis, calendaris de festius, llistat de tributs, CNAE, etc.) | G30: Si, hi ha identificades Dades Mestre i les Dades de Referència, però la identificació no és completa | J30: =SUMIF(M30:P30,G30,$M$5:$P$5) -> 2 | L30: =D30 -> ME01 | M30: No, no estan identificades les Dades Mestre ni les Dades de Referència | N30: Si, hi ha identificades Dades Mestre i les Dades de Referència, però la identificació no és completa | O30: Si, hi ha identificades totes les Dades Mestre i les Dades de Referència clau per a l'Ajuntament/Organisme | P30: Si, hi ha identificades totes les Dades Mestre i les Dades de Referència clau per a l'Ajuntament/Organisme, i periòdicament es revisen les definicions d'aquestes, la completitut i es porten a terme tasques de millora continua | R30: Definir les Polítiques i procediments d'integració, gestió i utilització de les dades . Per tal de fer aquest camí més senzill i aprofitant l'experiència de la DIBA, aquesta facilita el procediment d'adhesió a les seves Polítiques. | S30: Revisar i implicar al personal en l'aplicació de les Polítiques i procediments d'integració, gestió i utilització de les dades | T30: Portar a terme accions de millora continua de les Polítiques i procediments d'integració, gestió i utilització de les dades | U30: - | W30: =IF(B29="",W29,B29) -> Gestió de dades | X30: =IF(E30="",X29,E30) -> Gestió de Dades Mestre i Dades de Referència | Y30: =IF(OR($G30=$M30,$G30=""),CONCATENATE(J30," - ",$R30),IF($G30=$N30,CONCATENATE(J30," - ",$S30),IF($G30=$O30,CONCATENATE(J30," - ",$T30),""))) -> 2 - Revisar i implicar al personal en l'aplicació de les Polítiques i procediments d'integració, gestió i utilització de les dades | Z30: =J30 -> 2
B31: Qualitat de la dada | J31: =AVERAGE(J32,J36,J34) -> 1.3333333 | W31: =IF(B30="",W30,B30) -> Gestió de dades | X31: =IF(E31="",X30,E31) -> Gestió de Dades Mestre i Dades de Referència
E32: Establiment d'estàndards, polítiques, bones pràctiques i procediments | J32: =SUM(J33:J33)/COUNT(J33:J33) -> 2 | W32: =IF(B31="",W31,B31) -> Qualitat de la dada | X32: =IF(E32="",X31,E32) -> Establiment d'estàndards, polítiques, bones pràctiques i procediments
D33: QA01 | F33: Estan documentats els requeriments de qualitat de les dades (precisió, integritat, consistència, completitut, puntualitat, etc.? | G33: Si, estan documentats alguns requeriments de qualitat d'algunes dades | J33: =SUMIF(M33:P33,G33,$M$5:$P$5) -> 2 | L33: =D33 -> QA01 | M33: No, no estan documentats els requeriments de qualitat de les dades | N33: Si, estan documentats alguns requeriments de qualitat d'algunes dades | O33: Si, estan documentats els requeriments de qualitat de les dades i hi ha processos automàtics orientats a garantir la qualitat de les dades | P33: Si, estan documentats els requeriments de qualitat de les dades i hi ha processos automàtics orientats a garantir la qualitat de les dades, i aquests es revisen de manera regular per tal d'identificar i aplicar millores | R33: Iniciar la documentació dels requeriments de qualitat de les dades, prioritzant les dades clau i crítiques | S33: Completar la documentació de requeriments de qualitat de les dades i valorar l'automatització de processos que ajudin a garantir la qualitat de les dades | T33: Maximitzar l'automatització de processos que ajudin a garantir la qualitat de les dades i establir mecanismes de millora continua | U33: - | W33: =IF(B32="",W32,B32) -> Qualitat de la dada | X33: =IF(E33="",X32,E33) -> Establiment d'estàndards, polítiques, bones pràctiques i procediments | Y33: =IF(OR($G33=$M33,$G33=""),CONCATENATE(J33," - ",$R33),IF($G33=$N33,CONCATENATE(J33," - ",$S33),IF($G33=$O33,CONCATENATE(J33," - ",$T33),""))) -> 2 - Completar la documentació de requeriments de qualitat de les dades i valorar l'automatització de processos que ajudin a garantir la qualitat de les dades | Z33: =J33 -> 2
E34: Control i monitorització de la qualitat de les dades | J34: =SUM(J35:J35)/COUNT(J35:J35) -> 1 | W34: =IF(B33="",W33,B33) -> Qualitat de la dada | X34: =IF(E34="",X33,E34) -> Control i monitorització de la qualitat de les dades
D35: QB01 | F35: Es fa un seguiment actiu i monitoratge de la qualitat de les dades? | G35: No, no es fa un seguiment actiu ni es monitoritza la qualitat de les dades | J35: =SUMIF(M35:P35,G35,$M$5:$P$5) -> 1 | L35: =D35 -> QB01 | M35: No, no es fa un seguiment actiu ni es monitoritza la qualitat de les dades | N35: Si, es fan seguiments i monitorització de la qualitat de les dades de manera esporàdica únicament quan es detecten errors, i s'estableixen mesures correctives. | O35: Si, es fan seguiments i monitorització de la qualitat de les dades de manera regular i planificada, per implantar mesures correctives i preventives | P35: Si, es fan seguiments i monitorització de la qualitat de les dades de manera regular i planificada, per implantar mesures correctives i preventives, i s'avaluen els propis criteris de seguiment i monitorització per tal d'optimitzar-los | R35: Començar a fer seguiment actiu i monitorització de la qualitat de les dades | S35: Periodificar i ampliar l'abast del seguiment i monitorització de la qualitat de les dades per tal que doni suport a la implantació accions orientades a la prevenció | T35: Implantar revisions periòdiques d'avaluació dels propis criteris de seguiment i monitorització de la qualitat per tal d'optimitzar-los | U35: _ | W35: =IF(B33="",W33,B33) -> Qualitat de la dada | X35: =IF(E35="",X33,E35) -> Establiment d'estàndards, polítiques, bones pràctiques i procediments | Y35: =IF(OR($G35=$M35,$G35=""),CONCATENATE(J35," - ",$R35),IF($G35=$N35,CONCATENATE(J35," - ",$S35),IF($G35=$O35,CONCATENATE(J35," - ",$T35),""))) -> 1 - Començar a fer seguiment actiu i monitorització de la qualitat de les dades | Z35: =J35 -> 1
E36: Planificació de la qualitat de les dades | J36: =SUM(J37:J37)/COUNT(J37:J37) -> 1 | W36: =IF(B35="",W35,B35) -> Qualitat de la dada | X36: =IF(E36="",X35,E36) -> Planificació de la qualitat de les dades
D37: QC01 | F37: Existeix una planificació de les activitats d'assegurament de la qualitat de les dades que detalla els objectius de qualitat, planifica el seguiment i monitorització de la qualitat de les dades, etc.? | G37: No, no es planifiquen les activitats d'assegurament de la qualitat de les dades | J37: =SUMIF(M37:P37,G37,$M$5:$P$5) -> 1 | L37: =D37 -> QC01 | M37: No, no es planifiquen les activitats d'assegurament de la qualitat de les dades | N37: Si, es planifiquen les activitats d'assegurament de la qualitat de les dades, però aquesta planificació no detalla els objectius de qualitat o les activitats de seguiment i monitorització de la qualitat | O37: Si, es planifiquen les activitats d'assegurament de la qualitat de les dades, detallant els objectius de qualitat i les activitats de seguiment i monitorització de la qualitat | P37: Si, es planifiquen les activitats d'assegurament de la qualitat de les dades, detallant els objectius de qualitat i les activitats de seguiment i monitorització de la qualitat, i es fan activitats de millora continua de les pròpies activitats de planificació | R37: Preparar un pla d'assegurament de la qualitat de les dades, que inicialment posi el focus en les dades crítiques i dades clau | S37: Ampliar el detall del pla d'assegurament de la qualitat de les dades, assegurant que aquest detalla els objectius de qualitat, i les activitats de seguiment i monitorització | T37: Incorporar avaluacions de millora continua per al propi procés de planificació de la qualitat de les dades. | U37: - | W37: =IF(B36="",W36,B36) -> Qualitat de la dada | X37: =IF(E37="",X36,E37) -> Planificació de la qualitat de les dades | Y37: =IF(OR($G37=$M37,$G37=""),CONCATENATE(J37," - ",$R37),IF($G37=$N37,CONCATENATE(J37," - ",$S37),IF($G37=$O37,CONCATENATE(J37," - ",$T37),""))) -> 1 - Preparar un pla d'assegurament de la qualitat de les dades, que inicialment posi el focus en les dades crítiques i dades clau | Z37: =J37 -> 1

Sheet Gestió de la dada
B2: Gestió de dades | H2: =H6/P6 -> 0
C4: La Gestió de Dades es refereix al conjunt d'activitats i procediments utilitzats per recollir, emmagatzemar, organitzar, mantenir i utilitzar dades de manera eficient. Aquest procés és crucial per garantir que les dades siguin accessibles, fiables i segures. L'objectiu principal de la Gestió de Dades és assegurar que les dades siguin utilitzades de manera eficient i efectiva per aportar valor a l'Ajuntament, Organisme o Àrea.
C6: Id. | D6: Qüestió | E6: Resposta | F6: Observacions | G6: Evidències i documentació | H6: =SUM(H7:H16) -> 0 | K6: 0 | L6: 1 | M6: 2 | N6: 3 | P6: =SUM(P7:P16) -> 26
C7: CD.01 | D7: Existeix un catàleg de dades? (una relació de les agrupacions de dades de l'Ajuntament) | H7: =SUMIF(K7:N7,E7,$K$6:$N$6) -> 0 | J7: CD.01 | K7: No | L7: Si, però no el coneix tothom qui el pot necessitar | M7: Si, i és conegut per l'Ajuntament | P7: =COUNTA(L7:N7) -> 2
C8: CD.02 | D8: El Catàleg de dades està implementat i poblat amb els actius de dades existents? | H8: =SUMIF(K8:N8,E8,$K$6:$N$6) -> 0 | J8: CD.02 | K8: No | L8: Si, però és poc complet | M8: Si, agrupa una gran quantitat de dades | P8: =COUNTA(L8:N8) -> 2
C9: CD.03 | D9: Existeix un Inventari de dades? (recopilació centralitzada de metadades de l'Ajuntament) | H9: =SUMIF(K9:N9,E9,$K$6:$N$6) -> 0 | J9: CD.03 | K9: No | L9: Si, però és poc complet | M9: Si, és bastant complet | N9: Si, és complet | P9: =COUNTA(L9:N9) -> 3
C10: CD.04 | D10: Estan definits els rols i les responsabilitats associades al Catàleg de dades i a l'Inventari de dades? | H10: =SUMIF(K10:N10,E10,$K$6:$N$6) -> 0 | J10: CD.04 | K10: No | L10: No sempre estan definits els rols/responsabilitats | M10: Estan definits els rols però les responsabilitats no estan clares | N10: Si, tant els rols com les responsabilitats estan clares | P10: =COUNTA(L10:N10) -> 3
C11: CD.05 | D11: El Catàleg de dades inclou Metadades de Negoci? (que descriuen les dades des de una perspectiva d'usuari de negoci) | H11: =SUMIF(K11:N11,E11,$K$6:$N$6) -> 0 | J11: CD.05 | K11: No | L11: Si, però és poc complet | M11: Si, és bastant complet | N11: Si, és complet | P11: =COUNTA(L11:N11) -> 3
C12: CD.06 | D12: El Catàleg de dades inclou Metadades tècniques? (que descriuen els aspectes tècnics de les dades, com estructures de base de dades, tipus, longituds, allotjament, etc.) | H12: =SUMIF(K12:N12,E12,$K$6:$N$6) -> 0 | J12: CD.06 | K12: No | L12: Si, però és poc complet | M12: Si, és bastant complet | N12: Si, és complet | P12: =COUNTA(L12:N12) -> 3
C13: CD.07 | D13: El Catàleg de dades inclou Metadades operacionals? (que descriuen els aspectes d'utilització i flux de les dades, com origen, registres d'auditoria, historial de canvis, processos ETL, etc.) | H13: =SUMIF(K13:N13,E13,$K$6:$N$6) -> 0 | J13: CD.07 | K13: No | L13: Si, però és poc complet | M13: Si, és bastant complet | N13: Si, és complet | P13: =COUNTA(L13:N13) -> 3
C14: CD.08 | D14: Els diferents tipus d'Usuari coneixen i tenen accés al Catàleg de dades i tenen les capacitats per a utilitzar-lo? | H14: =SUMIF(K14:N14,E14,$K$6:$N$6) -> 0 | J14: CD.08 | K14: No | L14: Si, però únicament uns usuaris avançats | M14: Si, tots els potencials usuaris | P14: =COUNTA(L14:N14) -> 2
C15: CD.09 | D15: Es monitoritza la qualitat i completitud del Catàleg de dades? | H15: =SUMIF(K15:N15,E15,$K$6:$N$6) -> 0 | J15: CD.09 | K15: No | L15: Si, però únicament quan es detecten errors | M15: Si, es fan revisions periòdiques planificades, i d'aquestes es generen activitats de millora | P15: =COUNTA(L15:N15) -> 2
C16: CD.10 | D16: Es recullen dades dels usuaris de les dades i es tenen en compte a un procés de millora contínua? | H16: =SUMIF(K16:N16,E16,$K$6:$N$6) -> 0 | J16: CD.10 | K16: No | L16: Per a algunes àrees, alguna vegada | M16: Per a algunes àrees de manera sistemàtica | N16: De manera sistemàtica per a totes les àrees | P16: =COUNTA(L16:N16) -> 3

Sheet Qualitat de la dada
B2: Qualitat de la dada | H2: =H6/P6 -> 0.0625
C4: La Gestió de la Qualitat de la Dada és refereix a tot un conjunt de pràctiques i processos destinats a assegurar que les dades compleixin amb els criteris de qualitat establerts. L'objectiu final és assegurar que les dades siguin fiables, precises i útils, permetent així la presa de decisions informades i millorant l'eficiència operativa de l'Ajuntament, Organisme o Àrea.
C6: Id. | D6: Qüestió | E6: Resposta | F6: Observacions | G6: Evidències i documentació | H6: =SUM(H7:H13) -> 1 | K6: 0 | L6: 1 | M6: 2 | N6: 3 | P6: =SUM(P7:P14) -> 16
C7: QD.01 | D7: Es planifiquen activitats orientades a garantir la qualitat de les dades | H7: =SUMIF(K7:N7,E7,$K$6:$N$6) -> 0 | J7: =C7 -> QD.01 | K7: No, mai | L7: S'ha fet alguna vegada puntualment | M7: Es planifica però no sempre s'executa | N7: És una activitat planificada que s'executa amb periodicitat | P7: =COUNTA(L7:N7) -> 3
C8: QD.02 | D8: Hi ha documentats criteris de qualitat de les dades? | H8: =SUMIF(K8:N8,E8,$K$6:$N$6) -> 0 | J8: =C8 -> QD.02 | K8: No | L8: Si, però és poc complet | M8: Si, estan documentats els criteris de qualitat | P8: =COUNTA(L8:N8) -> 2
C9: QD.03 | D9: Es fa un seguiment actiu i monitoratge de la qualitat de les dades? | E9: S'ha fet alguna vegada puntualment | H9: =SUMIF(K9:N9,E9,$K$6:$N$6) -> 1 | J9: =C9 -> QD.03 | K9: No | L9: S'ha fet alguna vegada puntualment | M9: Es planifica però no sempre s'executa | N9: És una activitat planificada que s'executa amb periodicitat | P9: =COUNTA(L9:N9) -> 3
C10: QD.04 | D10: Hi ha activitats d'assegurament de la qualitat de les dades al moment en que aquestes es generen? | H10: =SUMIF(K10:N10,E10,$K$6:$N$6) -> 0 | J10: =C10 -> QD.04 | K10: No | L10: Si, però es tracta d'activitats puntuals no sistemàtiques | M10: Si, es tracta d'activitats que es fan de manera planificada i sistemàtica | P10: =COUNTA(L10:N10) -> 2
C11: QD.05 | D11: Hi ha activitats d'assegurament de la qualitat de les dades ja existents? (p.e. processos de neteja i correcció) | H11: =SUMIF(K11:N11,E11,$K$6:$N$6) -> 0 | J11: =C11 -> QD.05 | K11: No | L11: Si, però es tracta d'activitats puntuals no sistemàtiques | M11: Si, es tracta d'activitats que es fan de manera planificada i sistemàtica | P11: =COUNTA(L11:N11) -> 2
C12: QD.06 | D12: Es fa reporting de la qualitat de les dades? | H12: =SUMIF(K12:N12,E12,$K$6:$N$6) -> 0 | J12: =C12 -> QD.06 | K12: No | L12: Si, però es tracta d'activitats puntuals no sistemàtiques | M12: Si, es tracta d'activitats que es fan de manera planificada i sistemàtica | P12: =COUNTA(L12:N12) -> 2
C13: QD.07 | D13: S'implementen processos de millora contínua? | H13: =SUMIF(K13:N13,E13,$K$6:$N$6) -> 0 | J13: =C13 -> QD.07 | K13: No | L13: Si, però es tracta d'activitats puntuals no sistemàtiques | M13: Si, es tracta d'activitats que es fan de manera planificada i sistemàtica | P13: =COUNTA(L13:N13) -> 2

Sheet Pla d'accions (anàlisi)
B2: Qüestionari d'avaluació de la maduresa
B4: Pla d'accions
G5: Prioritat aut. | H5: Impacte | I5: Dificultat | J5: Impacte + Dificultat | K5: Termini objectiu
B6: Govern
D7: Establiment d'estàndards, polítiques, bones pràctiques i procediments
E8: GA01 | F8: =IF(VLOOKUP(E8,Qüestionari!D:Z,22,0)="","<No aplica>",VLOOKUP(E8,Qüestionari!D:Z,22,0)) -> 2 - Establir un marc de Govern del Dada unificat per garantir coherència i alineació entre àrees fent un treball de centralització de la governança i unificació de criteris. | G8: =IF(VLOOKUP(E8,Qüestionari!D:Z,23,0)=4,"",VLOOKUP(E8,Qüestionari!D:Z,23,0)) -> 2 | H8: 2 - Mig | I8: 3 - Alta | J8: =IF(AND(H8<>"",I8<>""),INT(LEFT(H8,1))+INT(LEFT(I8,1)),"") -> 5 | K8: Mig termini (6 – 18 mesos)
E9: GA02 | F9: =IF(VLOOKUP(E9,Qüestionari!D:Z,22,0)="","<No aplica>",VLOOKUP(E9,Qüestionari!D:Z,22,0)) -> 2 - Cal revisar que les Polítiques definides son aplicables, si es poden simplificar i assegurar un lideratge en l'àmbit del Govern de la dada. Addicionalment, seria positiu reforçar la comunicació, assegurar la capacitació dels implicats i portar a terme accions que facin que el Govern de la dada s'integri a la operació diària. | G9: =IF(VLOOKUP(E9,Qüestionari!D:Z,23,0)=4,"",VLOOKUP(E9,Qüestionari!D:Z,23,0)) -> 2 | H9: 1 - Alt | I9: 1 - Baixa | J9: =IF(AND(H9<>"",I9<>""),INT(LEFT(H9,1))+INT(LEFT(I9,1)),"") -> 2 | K9: Curt termini (0 – 6 Mesos)
D10: Establiment d'estratègies de dades
E11: GB01 | F11: =IF(VLOOKUP(E11,Qüestionari!D:Z,22,0)="","<No aplica>",VLOOKUP(E11,Qüestionari!D:Z,22,0)) -> <No aplica> | G11: =IF(VLOOKUP(E11,Qüestionari!D:Z,23,0)=4,"",VLOOKUP(E11,Qüestionari!D:Z,23,0)) | J11: =IF(AND(H11<>"",I11<>""),INT(LEFT(H11,1))+INT(LEFT(I11,1)),"")
E12: GB02 | F12: =IF(VLOOKUP(E12,Qüestionari!D:Z,22,0)="","<No aplica>",VLOOKUP(E12,Qüestionari!D:Z,22,0)) -> <No aplica> | G12: =IF(VLOOKUP(E12,Qüestionari!D:Z,23,0)=4,"",VLOOKUP(E12,Qüestionari!D:Z,23,0)) | J12: =IF(AND(H12<>"",I12<>""),INT(LEFT(H12,1))+INT(LEFT(I12,1)),"")
D13: Establiment d'estructures organitzacionals
E14: GC01 | F14: =IF(VLOOKUP(E14,Qüestionari!D:Z,22,0)="","<No aplica>",VLOOKUP(E14,Qüestionari!D:Z,22,0)) -> 3 - Assegurar que les decisions i accions derivades dels comitès estan alineats amb l'estratègia, avaluar i optimitzar els resultats dels Comitès | G14: =IF(VLOOKUP(E14,Qüestionari!D:Z,23,0)=4,"",VLOOKUP(E14,Qüestionari!D:Z,23,0)) -> 3 | H14: 2 - Mig | I14: 3 - Alta | J14: =IF(AND(H14<>"",I14<>""),INT(LEFT(H14,1))+INT(LEFT(I14,1)),"") -> 5 | K14: <No aplica>
D15: Gestió de recursos humans
E16: GD01 | F16: =IF(VLOOKUP(E16,Qüestionari!D:Z,22,0)="","<No aplica>",VLOOKUP(E16,Qüestionari!D:Z,22,0)) -> <No aplica> | G16: =IF(VLOOKUP(E16,Qüestionari!D:Z,23,0)=4,"",VLOOKUP(E16,Qüestionari!D:Z,23,0)) | J16: =IF(AND(H16<>"",I16<>""),INT(LEFT(H16,1))+INT(LEFT(I16,1)),"")
E17: GD02 | F17: =IF(VLOOKUP(E17,Qüestionari!D:Z,22,0)="","<No aplica>",VLOOKUP(E17,Qüestionari!D:Z,22,0)) -> <No aplica> | G17: =IF(VLOOKUP(E17,Qüestionari!D:Z,23,0)=4,"",VLOOKUP(E17,Qüestionari!D:Z,23,0)) | J17: =IF(AND(H17<>"",I17<>""),INT(LEFT(H17,1))+INT(LEFT(I17,1)),"")
E18: GD03 | F18: =IF(VLOOKUP(E18,Qüestionari!D:Z,22,0)="","<No aplica>",VLOOKUP(E18,Qüestionari!D:Z,22,0)) -> 3 - És interessant garantir l'autoritat i visibilitat dels Propietaris de dades, assegurant que tingui els recursos i que s'implementen activitats de millora contínua. | G18: =IF(VLOOKUP(E18,Qüestionari!D:Z,23,0)=4,"",VLOOKUP(E18,Qüestionari!D:Z,23,0)) -> 3 | H18: 3 - Baix | I18: 2 - Mitja | J18: =IF(AND(H18<>"",I18<>""),INT(LEFT(H18,1))+INT(LEFT(I18,1)),"") -> 5 | K18: Llarg termini (18-36 mesos)
B19: Gestió de dades
D20: Gestió de seguretat de dades
E21: MA01 | F21: =IF(VLOOKUP(E21,Qüestionari!D:Z,22,0)="","<No aplica>",VLOOKUP(E21,Qüestionari!D:Z,22,0)) -> 2 - Divulgar les Polítiques de seguretat i privadesa entre el personal per tal que aquestes siguin conegudes, i fer avaluacions periòdiques del seu compliment | G21: =IF(VLOOKUP(E21,Qüestionari!D:Z,23,0)=4,"",VLOOKUP(E21,Qüestionari!D:Z,23,0)) -> 2 | J21: =IF(AND(H21<>"",I21<>""),INT(LEFT(H21,1))+INT(LEFT(I21,1)),"")
E22: MA02 | F22: =IF(VLOOKUP(E22,Qüestionari!D:Z,22,0)="","<No aplica>",VLOOKUP(E22,Qüestionari!D:Z,22,0)) -> 1 - Identificar i classificar les dades clau en funció de la seva sensibilitat | G22: =IF(VLOOKUP(E22,Qüestionari!D:Z,23,0)=4,"",VLOOKUP(E22,Qüestionari!D:Z,23,0)) -> 1 | J22: =IF(AND(H22<>"",I22<>""),INT(LEFT(H22,1))+INT(LEFT(I22,1)),"")
D23: Gestió de dades històriques
E24: MB01 | F24: =IF(VLOOKUP(E24,Qüestionari!D:Z,22,0)="","<No aplica>",VLOOKUP(E24,Qüestionari!D:Z,22,0)) -> 1 - Definir les Polítiques d'arxivat i restauració de dades . Per tal de fer aquest camí més senzill i aprofitant l'experiència de la DIBA, aquesta facilita el procediment d'adhesió a les seves Polítiques. | G24: =IF(VLOOKUP(E24,Qüestionari!D:Z,23,0)=4,"",VLOOKUP(E24,Qüestionari!D:Z,23,0)) -> 1 | J24: =IF(AND(H24<>"",I24<>""),INT(LEFT(H24,1))+INT(LEFT(I24,1)),"")
D25: Gestió de fonts i destinacions de dades
E26: MC01 | F26: =IF(VLOOKUP(E26,Qüestionari!D:Z,22,0)="","<No aplica>",VLOOKUP(E26,Qüestionari!D:Z,22,0)) -> 2 - Ampliar l'Inventari de dades a totes les dades clau, i difondre i promoure la seva utilització | G26: =IF(VLOOKUP(E26,Qüestionari!D:Z,23,0)=4,"",VLOOKUP(E26,Qüestionari!D:Z,23,0)) -> 2 | J26: =IF(AND(H26<>"",I26<>""),INT(LEFT(H26,1))+INT(LEFT(I26,1)),"")
E27: MC02 | F27: =IF(VLOOKUP(E27,Qüestionari!D:Z,22,0)="","<No aplica>",VLOOKUP(E27,Qüestionari!D:Z,22,0)) -> 1 - Identificar les fonts de dades externes i les dades associades per tal de poder fer una gestió específica d'aquestes | G27: =IF(VLOOKUP(E27,Qüestionari!D:Z,23,0)=4,"",VLOOKUP(E27,Qüestionari!D:Z,23,0)) -> 1 | J27: =IF(AND(H27<>"",I27<>""),INT(LEFT(H27,1))+INT(LEFT(I27,1)),"")
D28: Gestió de la integració de les dades
E29: MD01 | F29: =IF(VLOOKUP(E29,Qüestionari!D:Z,22,0)="","<No aplica>",VLOOKUP(E29,Qüestionari!D:Z,22,0)) -> 1 - Definir les Polítiques i procediments d'integració, gestió i utilització de les dades . Per tal de fer aquest camí més senzill i aprofitant l'experiència de la DIBA, aquesta facilita el procediment d'adhesió a les seves Polítiques. | G29: =IF(VLOOKUP(E29,Qüestionari!D:Z,23,0)=4,"",VLOOKUP(E29,Qüestionari!D:Z,23,0)) -> 1 | J29: =IF(AND(H29<>"",I29<>""),INT(LEFT(H29,1))+INT(LEFT(I29,1)),"")
D30: Gestió de Dades Mestre i Dades de Referència
E31: ME01 | F31: =IF(VLOOKUP(E31,Qüestionari!D:Z,22,0)="","<No aplica>",VLOOKUP(E31,Qüestionari!D:Z,22,0)) -> 2 - Revisar i implicar al personal en l'aplicació de les Polítiques i procediments d'integració, gestió i utilització de les dades | G31: =IF(VLOOKUP(E31,Qüestionari!D:Z,23,0)=4,"",VLOOKUP(E31,Qüestionari!D:Z,23,0)) -> 2 | J31: =IF(AND(H31<>"",I31<>""),INT(LEFT(H31,1))+INT(LEFT(I31,1)),"")
B32: Qualitat de la dada
D33: Establiment d'estàndards, polítiques, bones pràctiques i procediments
E34: QA01 | F34: =IF(VLOOKUP(E34,Qüestionari!D:Z,22,0)="","<No aplica>",VLOOKUP(E34,Qüestionari!D:Z,22,0)) -> 2 - Completar la documentació de requeriments de qualitat de les dades i valorar l'automatització de processos que ajudin a garantir la qualitat de les dades | G34: =IF(VLOOKUP(E34,Qüestionari!D:Z,23,0)=4,"",VLOOKUP(E34,Qüestionari!D:Z,23,0)) -> 2 | J34: =IF(AND(H34<>"",I34<>""),INT(LEFT(H34,1))+INT(LEFT(I34,1)),"")
D35: Control i monitorització de la qualitat de les dades
E36: QB01 | F36: =IF(VLOOKUP(E36,Qüestionari!D:Z,22,0)="","<No aplica>",VLOOKUP(E36,Qüestionari!D:Z,22,0)) -> 1 - Començar a fer seguiment actiu i monitorització de la qualitat de les dades | G36: =IF(VLOOKUP(E36,Qüestionari!D:Z,23,0)=4,"",VLOOKUP(E36,Qüestionari!D:Z,23,0)) -> 1 | J36: =IF(AND(H36<>"",I36<>""),INT(LEFT(H36,1))+INT(LEFT(I36,1)),"")
D37: Planificació de la qualitat de les dades
E38: QC01 | F38: =IF(VLOOKUP(E38,Qüestionari!D:Z,22,0)="","<No aplica>",VLOOKUP(E38,Qüestionari!D:Z,22,0)) -> 1 - Preparar un pla d'assegurament de la qualitat de les dades, que inicialment posi el focus en les dades crítiques i dades clau | G38: =IF(VLOOKUP(E38,Qüestionari!D:Z,23,0)=4,"",VLOOKUP(E38,Qüestionari!D:Z,23,0)) -> 1 | J38: =IF(AND(H38<>"",I38<>""),INT(LEFT(H38,1))+INT(LEFT(I38,1)),"")

Sheet Pla d'accions
B2: Qüestionari d'avaluació de la maduresa
B4: Pla d'accions
B7: Govern
B8: Establiment d'estratègies de dades
B10: Establiment d'estructures organitzacionals
B11: 3 - Assegurar que les decisions i accions derivades dels comitès estan alineats amb l'estratègia, avaluar i optimitzar els resultats dels Comitès
B12: Gestió de recursos humans
B14: 3 - És interessant garantir l'autoritat i visibilitat dels Propietaris de dades, assegurant que tingui els recursos i que s'implementen activitats de millora contínua.
B15: Establiment d'estàndards, polítiques, bones pràctiques i procediments
B17: Gestió de dades
B18: Gestió de seguretat de dades
B19: 1 - Identificar i classificar les dades clau en funció de la seva sensibilitat
... B35: 2 - Completar la documentació de requeriments de qualitat de les dades i valorar l'automatització de processos que ajudin a garantir la qualitat de les dades

Sheet Resultat
B4: Qüestionari d'avaluació de la maduresa
B6: Resultat
B8: Data | C8: Avaluador | D8: Àmbit | E8: Ajuntament/Organisme | F8: Àrea | G8: GA01 | H8: GA02 | I8: GB01 | J8: GB02 | K8: GC01 | L8: GD01 | M8: GD02 | N8: GD03 | O8: MA01 | P8: MA02 | Q8: MB01 | R8: MC01 | S8: MC02 | T8: MD01 | U8: ME01 | V8: QA01 | W8: QB01 | X8: QC01
B9: =MapaResponsables!C8 -> 45716 | C9: =MapaResponsables!C9 -> 0 | D9: =MapaResponsables!C10 -> Ajuntament | E9: =MapaResponsables!C11 -> Berga | F9: =MapaResponsables!C12 -> <Totes> | G9: =SUMIF(Qüestionari!$D:$D,G8,Qüestionari!$J:$J) -> 2 | H9: =SUMIF(Qüestionari!$D:$D,H8,Qüestionari!$J:$J) -> 2 | I9: =SUMIF(Qüestionari!$D:$D,I8,Qüestionari!$J:$J) -> 4 | J9: =SUMIF(Qüestionari!$D:$D,J8,Qüestionari!$J:$J) -> 4 | K9: =SUMIF(Qüestionari!$D:$D,K8,Qüestionari!$J:$J) -> 3 | L9: =SUMIF(Qüestionari!$D:$D,L8,Qüestionari!$J:$J) -> 4 | M9: =SUMIF(Qüestionari!$D:$D,M8,Qüestionari!$J:$J) -> 4 | N9: =SUMIF(Qüestionari!$D:$D,N8,Qüestionari!$J:$J) -> 3 | ... X9: =SUMIF(Qüestionari!$D:$D,X8,Qüestionari!$J:$J) -> 1
H11: =AVERAGE(H12,H18,H25) -> 1.9666667
B12: Govern | H12: =AVERAGE(G13:G16) -> 3.1666667
C13: =Qüestionari!E6 -> Establiment d'estàndards, polítiques, bones pràctiques i procediments | G13: =AVERAGE(G9:H9) -> 2
C14: =Qüestionari!E9 -> Establiment d'estratègies de dades | G14: =AVERAGE(I9:J9) -> 4
C15: =Qüestionari!E12 -> Establiment d'estructures organitzacionals | G15: =AVERAGE(K9) -> 3
C16: =Qüestionari!E14 -> Gestió de recursos humans | G16: =AVERAGE(L9:N9) -> 3.6666667
B18: Gestió de dades | H18: =AVERAGE(G19:G23) -> 1.4
C19: =Qüestionari!E19 -> Gestió de seguretat de dades | G19: =AVERAGE(O9:P9) -> 1.5
C20: =Qüestionari!E22 -> Gestió de dades històriques | G20: =AVERAGE(Q9) -> 1
C21: =Qüestionari!E24 -> Gestió de fonts i destinacions de dades | G21: =AVERAGE(R9:S9) -> 1.5
C22: =Qüestionari!E27 -> Gestió de la integració de les dades | G22: =AVERAGE(T9) -> 1
C23: =Qüestionari!E29 -> Gestió de Dades Mestre i Dades de Referència | G23: =AVERAGE(U9) -> 2
B25: Qualitat de la dada | H25: =AVERAGE(G26:G28) -> 1.3333333
C26: =Qüestionari!E32 -> Establiment d'estàndards, polítiques, bones pràctiques i procediments | G26: =AVERAGE(V9) -> 2
C27: =Qüestionari!E34 -> Control i monitorització de la qualitat de les dades | G27: =AVERAGE(W9) -> 1
C28: =Qüestionari!E36 -> Planificació de la qualitat de les dades | G28: =AVERAGE(X9) -> 1
B31: =B12 -> Govern | C31: =H12 -> 3.1666667
B32: =B18 -> Gestió de dades | C32: =H18 -> 1.4
B33: =B25 -> Qualitat de la dada | C33: =H25 -> 1.3333333

Sheet Llegenda
B4: Qüestionari d'avaluació de la maduresa
B5: Llegenda
C7: Info
B9: Atribut | C9: Descripció | D9: Requerimient de l'atribut
B10: Data | C10: Data de l'estudi | D10: Obligatori
B11: Avaluador | C11: Persona que lidera l'estudi | D11: Obligatori
B12: Àmbit | C12: Detall de l'àmbit de l'estudi, pot ser Ajuntament o Organisme | D12: Obligatori
B13: Ajuntament/Organisme | C13: Ajuntament o Organisme concret subjecte d'estudi | D13: Obligatori
B14: Àrea | C14: Detall de l'Àrea de l'Ajuntament o Organisme que s'avalua (pot identificar un àrea concreta o totes) | D14: Obligatori
B16: Rol | C16: Nom del rol a l'Ajuntament o Organisme identificat al quadre de Rols | D16: Obligatori
B17: Nom de l'àrea | C17: Nom de l'Area o Domini dades identificat al quadre d'Àrees i Dominis | D17: Obligatori
B18: Nom del procés | C18: Nom del Procés identificat al quadre de Processos clau | D18: Obligatori
B19: Nom del projecte | C19: Nom del Procés identificat al quadre de Projectes estratègics i PAM | D19: Obligatori
B20: Àmbit de responsabilitat | C20: Nom del rol a l'Ajuntament o Organisme identificat al quadre de altres responsables | D20: Obligatori
B22: Responsable | C22: Nom complet del responsable | D22: Obligatori
... B25: Observacions | C25: Qualsevol comentari addicional que es consideri que ha de tenir-se en compte | D25: Obligatori
C27: Sistema
B29: Atribut | C29: Descripció | D29: Requerimient de l'atribut
B30: Nom curt | C30: Nom curt del sistema d'informació | D30: Obligatori
B31: Nom llarg | C31: Nom llarg del sistema d'informació | D31: Opcional
B32: És extern? | C32: Indica si el sistema és extern (Si) o intern (No). | D32: Obligatori
B33: Descripció | C33: Descripció del sistema | D33: Obligatori
B34: Tipus | C34: Indica el tipus de tecnologia del sistema. Existeixen les següents possibilitats però s'en poden afegir de noves si fos necessari: - Oracle - PostgreSQL - MongoDB - Sistema d'arxius - CDP - Cloudera Data Platform | D34: Obligatori
B35: Nom curt del sistema pare | C35: Nom del sistema pare, en cas que en tingui. | D35: Opcional
B36: Codi d'aplicació | C36: Codi d'aplicació segons l'inventari. | D36: Opcional
B37: Administrador de sistemes | C37: Nom de l'Administrador de sistemes | D37: Obligatori
B38: Correu electrònic de l'Administrador de sistemes | C38: Correu electrònic de l'Administrador de sistemes | D38: Obligatori
B39: Unitat orgànica/Departament Administrador de sistemes | C39: Unitat orgànica/Departament Administrador de sistemes | D39: Obligatori
B40: Arquitecte de la dada | C40: Nom de l'Arquitecte de la dada | D40: Obligatori
... B42: Unitat orgànica/Departament Arquitecte de la dada | C42: Unitat orgànica/Departament Arquitecte de la dada | D42: Obligatori
C45: Qüestionari
B47: Atribut | C47: Descripció | D47: Requeriment de l'atribut
B48: Id | C48: Es tracta d'un identificador clau de la qüestió. | D48: <No aplica>
B49: Qüestió | C49: Pregunta que serveix per a obtenir una resposta precisa de l'estat de maduresa. | D49: <No aplica>
B50: Resposta | C50: El responsable d'omplir el qüestionari escollirà de la llista de respostes possibles, aquella que defineix millor la situació actual. | D50: Obligatori
