Workbook
Name a: Qüestionari!$A$1:$J$38
Name AccionsGD: Llistes!#REF!
Name Ajuntament: Llistes!$E$3:$E$313
Name Àrea: Llistes!$G$3:$G$173
Name Dificultat: Llistes!$M$3:$M$5
Name Impacte: Llistes!$K$3:$K$5
Name ImpacteCost: Llistes!$K$3:$K$5
Name Organisme: Llistes!$C$3:$C$21
Name Rols: Llistes!$I$3:$I$4
Name SiNo: #REF!
Name Termini: Llistes!$O$3:$O$7
Name Tipus: Llistes!$A$3:$A$6

Sheet Instruccions
B4: Qüestionari d'avaluació de la maduresa
B5: Instruccions
B9: - El qüestionari s'ha de respondre a les pestanyes MapaResponsables, Sistemes i Qüestionari
B11: - L'emplenament de les dades s'ha de realitzar segons les especificacions de la pestanya Llegenda.
B13: - El personal designat per l'Ajuntament, Organisme o Àrea és el responsables d'emplenar el qüestionari, amb el suport de l'Oficina de Govern de la dada de la DIBA.
B15: - La pestanya Info ajudarà a identificar les persones clau en l'àmbit de les dades de l'Ajuntament o Organisme, així com quina és la seva organització per àrees o dominis de dades, Processos clau, Projectes estratègics i Objectius del PAM.
B17: - La pestanya Sistemes dona suport a la identificació dels sistemes de dades, de manera que hauria d'estar complimentat amb el suport de l'arquitecte de dades i dels administradors de sistemes,
B19: - La pestanya Qüestionari dona suport a l'avaluació de la maduresa del govern de la dada, ha de complimentar-se pel Responsable de dades amb suport de l'Oficina de Govern de la dada de la DIBA.
B21: - Per tal que el qüestionari es consideri complet, hauran d'estar emplenats tots els atributs obligatoris detallats a la pestanya Llegenda.
B23: v20250305

Sheet MapaResponsables
B4: Qüestionari d'avaluació de la situació actual
B6: Mapa Responsables
B8: Data | C8: 45716
B9: Tècnic suport
B10: Àmbit | C10: Ajuntament
B11: =C10 -> Ajuntament | C11: Berga
B12: Àrea | C12: <Totes>
B15: Rols Clau
C16: Rol | D16: Responsable | E16: Correu responsable | F16: Telèfon responsable | G16: Observacions
C17: Responsable de dades (Data Stewart)
C18: Propietari de dades (Data Owner)
C19: Referent de dades (Data Stewart) | D19: Gemma Àlvarez | E19: alvarezmgm@premiadedalt.cat | F19: 936931509 | G19: Cap de Recursos humans i de Serveis a les persones: sol·licita accés a Informàtica per un treballador nou. RESPONSABLE DE DADES DE RECURSOS HUMANS - Decideix sobre les dades/estructura de nòmines, de treballadors. -Nòmines (SIGEP) - NetTime (control horaris), Spec - TOts tenen accès al gestor d'Expedients.
C20: Referent de dades (Data Stewart) | D20: Nuria Riera | E20: rieraan@premiadedalt.cat | F20: 674951891 | G20: Serveis Socials, demana a Informàtica per afegir un treballador nou. - Fan servir HESTIA del consell comarcal. Gestor d'expedients. Unitat compartida. No tè capacitat de modificar estructura de les dades
C21: Responsable de dades (Data Stewart) | D21: Teresa Pallarés | E21: pallaresrmr@premiadedalt.cat | F21: 670961003 | G21: Tresoreria i Intervenció, mateixa dinàmica. Gestor d'expedients. Tè accès a comptabilitat.
D22: Pedro Obrero Román | E22: obrerorp@premiadedalt.cat | F22: 607118371 | G22: Responsable d'Informàtica que accedeix a les peticions dels diferents departaments. Dona els permisos, sota indicació del responsable de cada departament. Per exemple: La interventora, li fa un document indicant qui ha de tenir accesos a que.
C23: Referent de dades (Data Stewart) | D23: Lluis García | E23: garciajll@premiadedalt.cat | F23: 666530168 | G23: Urbanisme o territori, mateixa dinàmica que abans. - Accès al Gestor d'Expedients. - Si comença algun tècnic li dona un document a Pedro Obrero indicant quins permisos ha de tenir cadascú. - Tothom tè accés a la unitat compartida. (Com tothom) - Geoportal (Web) on publiquen normativa del poble. - La resta al gestor d'expedients o a la unitat compartida. Responsable de tot lo relatiu a Serveis Territorials
D24: Virginia Merlos | E24: merloscv@premiadedalt.cat | F24: 637755094 | G24: Promoció econòmica, mateixa dinàmica. - Gestor d'expedients. No te capacitat de decissió sobre modificació d'estructura de dades, es nomès tècnica.
C25: Responsable de dades (Data Stewart) | D25: Eli Gummà | E25: gummabe@premiadedalt.cat | F25: 667470681 | G25: Educació i joventut, mateixa dinàmica. -Gestor d'expedients. - Responsable d'educació. Tenen una aplicació de gestió d'altes i baixes dels alumnes del curs, i algo del menjador. (No sabem exactament el nom). Té poder de decissió sobre aquesta aplicació.
C26: Propietari de dades (Data Owner) | D26: Carlos Matallan | E26: prmd.pl1335@premiadedalt.cat | F26: 936931500 | G26: Policia, sargent cap. - Accedeixen a l'aplicació dels Mossos. - Aplicació Eurocop (al estiu probablement la canviaràn per DRAG), gestió policial, grues, gestió d'atestats. Eurocop el tenen al servidor POSSE (Base de dades SQL). Al estiu ho migraran a DRAG que un SAAS.
C27: Responsable de dades (Data Stewart) | D27: Mireia Boté | E27: botemmr@premiadedalt.cat | F27: 936931511 | G27: Secretaria (firmar informes juridics, assesorar). Fa servir el gestor d'expedients. Tè accés. Tè poder per establir protocols.
C28: Responsable de dades (Data Stewart) | D28: Monica Farré | E28: farresm@premiadedalt.cat | F28: 936931502 | G28: Gestor de dades Lectura, Te acces al gestor d'expedients permisos CRUD, dintre de la seva area. Porta la gestió de la pàgina web i el tema de Transparència
C29: Responsable de dades (Data Stewart) | D29: Eva Roig | E29: prmd.alcaldia@premiadedalt.cat | G29: Porta la base de dades del cementiri dels ninxols. Porta el registre d'expedients, les entrades que van cap a alcaldia.
C30: Responsable de dades (Data Stewart) | D30: Ricard Amaya | E30: amayaar@premiadedalt.cat | G30: Tresorer. Responsable de les dades de comptabilitat. Dels bancs, dels comptes corrents. Fa pagament de nòmines i factures. Fa l'autorització de pagament. Tota entrada i sortida monetaria la controla ell.
C31: Referent de dades (Data Stewart) | D31: Gemma Ferran | E31: ferrancg@premiadedalt.cat | G31: Directora escoles bressol. Tè acces a l'aplicació de les Escoles bressol. A nivell de gestió
D32: Enric Miralles | G32: Tècnic Cultura te acces al gestor d'expedients. Però rol baix.
D33: Gemma Planas | G33: Directora de la Biblioteca. - Treballa amb eines de la diputació per gestionar el catàleg de llibres i qui ho ha llogat.
D34: Ester Àvila | E34: avilaae@premiadedalt.cat | G34: Reponsable de la interacció amb la AOC i de tots els datasets que hi resideixin al AOC. Per exemple, donar IDCat als ciutadans, la que controla el tema del padró.
D35: Dolors Ollero | E35: ollerobd@premiadedalt.cat | G35: Arquitecte. - Te accès al gestor d'expedients. Geoportal i a la ùnitat compartida.
B39: Àrees / Dominis
C40: Nom de l'àrea | D40: Responsable | E40: Correu responsable | F40: Telèfon responsable | G40: Observacions
C41: Recursos Humans
C42: Serveis Socials
C43: Tesorería i Intervenció
C44: Informàtica
C45: Organigrames tècnic i funcional — Ajuntament de Premià de Dalt
B51: Processos clau
C52: Nom del procés | D52: Responsable | E52: Correu responsable | F52: Telèfon responsable | G52: Observacions
C53: Contractes menors | D53: Cada departament | G53: Contractació
C54: Subvencions | D54: Cada departament | G54: Cada departament gestiona les seves
C55: Licitacions | D55: Secretaria | E55: botemmr@premiadedalt.cat | F55: 936931511
...

Sheet Sistemes
B4: Sistemes
B6: Nom curt | C6: Nom llarg | D6: És extern? | E6: Descripció | F6: Tipus | G6: Proveïdor | H6: Administrador de sistemes | I6: Correu electrònic de l'Administrador de sistemes | J6: Unitat orgànica/Departament Administrador de sistemes | K6: Arquitecte de la dada | L6: Correu electrònic de l'Arquitecte de la dada | M6: Unitat orgànica/Departament Arquitecte de la dada
B7: Servidor POSSE | C7: Aplicació de Nòmines. Sigep. Està al Servidor PC630. | D7: No | F7: Servidor amb un programa que es diu SIGEP instalat al servidor | G7: AITOS es l'empresa que va instalar i mante el programa SIGEP al servidor | H7: Departament d'Informàtica | I7: Pedro Obrero (mail) | J7: Politiques Digitals (cambiar el nom d'informàtica) | K7: AITOS | L7: AITOS | M7: AITOS | N7: Aquest sistema deixarà de funcionar al estiu serà substituit pel de la linea 8
B8: Gestor d'expedients | C8: S'ha de licitar encara | D8: Si | E8: Gestor d'expedients | F8: S'ha de licitar (Posiblement Sabia) | G8: Audifilm | H8: Responsable de Recursos Humans / Dpt Informàtica | N8: S'ha de licitar
B9: Comptabilitat Diputació | C9: Genesis | D9: Si | E9: Comptabilitat | F9: Gestor d'expedients | G9: Diputació Barcelona (Berger LEvraux) | H9: Lali Rivera (Secretaria) i Polítiques Digitals | K9: Audifirm | L9: Audifirm | M9: Audifirm
B10: Factures | C10: SIcalwin | D10: Si | E10: Factures | F10: Comptabilitat | G10: Diputació Barcelona (Berger LEvraux) | H10: Politiques Digitals dona acces a la aplicació a través del SVUS i Administrativa (Carme Hernando) de Intervenció la que dona permisos dins de l'aplicació | I10: hernandobc@premiadedalt.cat / obrerorp@premiadedalt.cat | J10: Informatica i Intervencio | K10: AITOS | L10: AITOS | M10: AITOS
B11: Tràmits | C11: Firmadoc | D11: Si | E11: Portal de tràmits (per exemple on es demanen subvencions) | F11: Factures | G11: Diputació Barcelona | H11: Politiques Digitals dona acces a la aplicació a través del SVUS i Administrativa (Carme Hernando) de Intervenció la que dona permisos dins de l'aplicació | I11: hernandobc@premiadedalt.cat / obrerorp@premiadedalt.cat | J11: Informatica i Intervencio | K11: Audifilm | L11: Audifilm | M11: Audifilm
B12: Servidor En Local | C12: Portal de Tràmits (PMT) | D12: No | F12: Portal de tràmits (per exemple on es demanen subvencions) | G12: Suprema | H12: Politiques Digitals dona accés directe a un treballador i li assignen els permisos directament. | I12: otrerorp@premiadedalt.cat | J12: Informatica i Intervencio | K12: Informàtica / Intervenció
B13: Base de dades del Cementiri | D13: No | E13: Base de dades del Cementiri | F13: Software d'Acces als edificis (Biostar - (empresa Suprema), agafa la petjada dactilar. | G13: Desenvolupament propi amb BBDD Access | H13: Departmanet d'Informàtica | K13: Informàtica / Intervenció
B14: Servidor en físic a la Policia (diferent del de l'ajuntament) | D14: No | E14: Servidor en físic a la Policia (diferent del de l'ajuntament) | F14: Gestió de les càmeres | G14: Aplicació Milestone | H14: Departament d'Informàtica / Empresa externa Controlcat | K14: Informàtica / Intervenció
B15: Lector de matrícules (Identools) | D15: Si | E15: Es un sistema de càmeres, que va enregistrant les matrícules, fa foto de la matrícula i la emmagatzema | F15: Seguretat Viària | G15: Controlcat es l'empresa | H15: Identools
B16: Eurocop | D16: No | E16: Base de dades per gestionar les grues, atestats policials, gestió policial. | F16: Seguretat Ciutadana | G16: Eurocop (NT Consulting) tot i que l'aplicació es antiga i probablement l'empresa ja ni existeixi | H16: Departament d'Informàtica
B17: CST / DRAG | D17: Si | E17: Software de GEstió Policial que substituirà a EUrocop, està licitat, probablement sigui DRAG | F17: Seguretat Ciutadana | G17: ECityclic | H17: ECityclic
B18: Padro Diputacio | D18: Si | E18: Padró (Diputació de Barcelona) | F18: Padró municipal d'habitants | G18: Diputació Barcelona | H18: Diputació Barcelona
B19: Nexus Geographics | D19: Si | E19: Geoportal (Fan servir a Urbanisme) | F19: Gestio d'urbanisme i llicències | G19: Nexus Geographics | H19: Nexus Geographics
B20: PMT Diputació de Barcelona | D20: Si | E20: Subvencions | F20: Gestio Subvencions | G20: Diputació de Barcelona | H20: Diputació de Barcelona

Sheet Capacitats tecnologiques
A1: Capacitats tecnológiques
A3: Producte | B3: Proveïdor | C3: Tipus | D3: Volumetria | E3: Grau d'ús i desplegament | F3: Descripció

Sheet Talent
A1: Dades de formació
A2: Curs de formació | B2: Proveïdor | C2: Persones | D2: Observacions
A5: Llocs de treball específics a la RLT
A6: Descripció del LLT | B6: Places | C6: Categoria
A9: Perfils identificats
A11: Persona | B11: Àrea funcional | C11: Perfil

Sheet Instruments aprovats
A1: Instruments aprovats
A2: Nom de l'instrument | B2: Any | C2: Enllaç

Sheet Reptes de mandat o amb dades
A9: Instruments aprovats
A10: Nom del repte | B10: Descripció | C10: Estat

Sheet Qüestionari
B2: Qüestionari d'avaluació de la maduresa
D4: Id. | E4: Procés | F4: Qüestió | G4: Resposta | H4: Observacions | I4: Evidències i documentació | M4: Respostes | R4: Accions
B5: Govern | J5: =AVERAGE(J6,J9,J12,J14) -> 1 | M5: 1 | N5: 2 | O5: 3 | P5: 4 | R5: 1 | S5: 2 | T5: 3 | U5: 4 | W5: Àmbit | X5: Procés | Y5: Pla acció | Z5: Prioritat | AA5: Prioritat | AB5: Calendari
E6: Establiment d'estàndards, polítiques, bones pràctiques i procediments | J6: =SUM(J7:J8)/COUNT(J7:J8) -> 1 | W6: =IF(B5="",W5,B5) -> Govern | X6: =IF(E6="",X5,E6) -> Establiment d'estàndards, polítiques, bones pràctiques i procediments
D7: GA01 | F7: Existeix un marc de Govern de la dada establert? (Polítiques, estàndards, procediments, inventari de dades, bones pràctiques, …) | G7: No, no existeix un marc de Govern de la dada establert | H7: No tenen cap marc establert ni rreconegut per tota l'organització sobre com s'han de governar le dades | J7: =SUMIF(M7:P7,G7,$M$5:$P$5) -> 1 | L7: =D7 -> GA01 | M7: No, no existeix un marc de Govern de la dada establert | N7: Si, però cada Àrea identifica i desenvolupa els seus processos amb el seu propi criteri | O7: Sí, hi ha un marc de Govern de la dada establert i publicat, que coneixen i utilitzen les diferents Àrees | P7: Sí, hi ha un marc de Govern de la dada establert i publicat, que coneixen i utilitzen les diferents Àrees, i que està subjecte a processos de millora continua de manera periòdica. | R7: Definir un Marc de Govern de la dada de marea senzilla i escalable alineat amb els objectius de l'Ajuntament/Organisme, definint regles clares de gestió de les dades (qualitat, seguretat i accés), rols i responsabilitats i processos clau) | S7: Establir un marc de Govern del Dada unificat per garantir coherència i alineació entre àrees fent un treball de centralització de la governança i unificació de criteris. | T7: Assegurar la aplicació del Marc de Govern de la dada de manera efectiva, avaluant el compliment i efectivitat, i executant processos de millora contínua | U7: - | W7: =IF(B6="",W6,B6) -> Govern | X7: =IF(E7="",X6,E7) -> Establiment d'estàndards, polítiques, bones pràctiques i procediments | Y7: =IF(OR($G7=$M7,$G7=""),CONCATENATE(J7," - ",$R7),IF($G7=$N7,CONCATENATE(J7," - ",$S7),IF($G7=$O7,CONCATENATE(J7," - ",$T7),""))) -> 1 - Definir un Marc de Govern de la dada de marea senzilla i escalable alineat amb els objectius de l'Ajuntament/Organisme, definint regles clares de gestió de les dades (qualitat, seguretat i accés), rols i responsabilitats i processos clau) | Z7: =J7 -> 1
D8: GA02 | F8: Estan documentades les Polítiques de Govern de la dada i aquestes estan orientades a optimitzar el valor de les dades? (estan publicades, el personal les coneix, s'actualitzen periòdicament, i es mesura i monitoritza el compliment) | G8: No, no hi ha polítiques per a la optimització del valor de les dades | H8: No existeix cap repositori compartit per l'organització sobre els conjunts de dades que hi ha a disposició dels diferents departaments i/o personal | J8: =SUMIF(M8:P8,G8,$M$5:$P$5) -> 1 | L8: =D8 -> GA02 | M8: No, no hi ha polítiques per a la optimització del valor de les dades | N8: Sí, hi ha algunes polítiques, però no s'implementen adequadament | O8: Sí, hi ha polítiques per a la optimització del valor de les dades i s'implementen adequadament | P8: Sí, hi ha polítiques per a la optimització del valor de les dades, s'implementen adequadament, i es porten a terme accions periòdiques de millora continua | R8: Cal definir la Política de Govern de la dada, es pot iniciar amb regles bàsiques que defineixin les responsabilitats, classifiquin les dades, estableixin normes d'accés i seguretat, i projectar un Inventari de dades. Per tal de fer aquest camí més senzill i aprofitant l'experiència de la DIBA, aquesta facilita el procediment d'adhesió a les seves Polítiques. | S8: Cal revisar que les Polítiques definides son aplicables, si es poden simplificar i assegurar un lideratge en l'àmbit del Govern de la dada. Addicionalment, seria positiu reforçar la comunicació, assegurar la capacitació dels implicats i portar a terme accions que facin que el Govern de la dada s'integri a la operació diària. | T8: És recomanable revisar les Polítiques periòdicament per tal d'optimitzar-les i assegurar que s'adapten a les noves necessitats. | U8: _ | W8: =IF(B7="",W7,B7) -> Govern | X8: =IF(E8="",X7,E8) -> Establiment d'estàndards, polítiques, bones pràctiques i procediments | Y8: =IF(OR($G8=$M8,$G8=""),CONCATENATE(J8," - ",$R8),IF($G8=$N8,CONCATENATE(J8," - ",$S8),IF($G8=$O8,CONCATENATE(J8," - ",$T8),""))) -> 1 - Cal definir la Política de Govern de la dada, es pot iniciar amb regles bàsiques que defineixin les responsabilitats, classifiquin les dades, estableixin normes d'accés i seguretat, i projectar un Inventari de dades. Per tal de fer aquest camí més senzill i aprofitant l'experiència de la DIBA, aquesta facilita el procediment d'adhesió a les seves Polítiques. | Z8: =J8 -> 1
E9: Establiment d'estratègies de dades | J9: =SUM(J10:J11)/COUNT(J10:J11) -> 1 | W9: =IF(B8="",W8,B8) -> Govern | X9: =IF(E9="",X8,E9) -> Establiment d'estratègies de dades
D10: GB01 | F10: Existeix una estratègia de dades que inclogui iniciatives, objectius i fites, i aquesta es coneguda per l'Ajuntament/Organisme? | G10: No, no hi ha una estratègia de dades coneguda | H10: Les dades no son reconegudes com un actiu de l'organització sobre les que extreure informació de valor. Per tant no hi ha una estratègia al respecte | J10: =SUMIF(M10:P10,G10,$M$5:$P$5) -> 1 | L10: =D10 -> GB01 | M10: No, no hi ha una estratègia de dades coneguda | N10: Sí, existeix una estratègia de dades però no es molt coneguda o no defineix clarament les iniciatives, objectius o fites. | O10: Si, existeix una estratègia de dades coneguda que inclou el detall d'iniciatives, objectius i fites | P10: Si, existeix una estratègia de dades coneguda que inclou el detall d'iniciatives, objectius i fites, i es fa un seguiment periòdic del compliment. | R10: Definir una estratègia de dades de manera clara i accessible per a tots els actors implicats, que detalli els objectius estratègics, concreti iniciatives/un pla d'acció amb prioritats i involucrar als equips de treball | S10: Revisar 'l'estratègia de dades per concretar iniciatives, objectius mesurables i fites clares, i assegurar que tots els equips implicats la coneguin i facin seva | T10: Assegurar el compliment de l'estratègia de dades fent un seguiment regular de les iniciatives, revisant els objectius i les fites i fomentant la millora continua | U10: - | W10: =IF(B9="",W9,B9) -> Govern | X10: =IF(E10="",X9,E10) -> Establiment d'estratègies de dades | Y10: =IF(OR($G10=$M10,$G10=""),CONCATENATE(J10," - ",$R10),IF($G10=$N10,CONCATENATE(J10," - ",$S10),IF($G10=$O10,CONCATENATE(J10," - ",$T10),""))) -> 1 - Definir una estratègia de dades de manera clara i accessible per a tots els actors implicats, que detalli els objectius estratègics, concreti iniciatives/un pla d'acció amb prioritats i involucrar als equips de treball | Z10: =J10 -> 1
D11: GB02 | F11: Hi ha mètriques d'utilització i rendiment de les dades? | G11: No, no hi ha mètriques d'utilització i rendiment de les dades | H11: Al no ser considerades un actiu, no hi ha cap tipus de mètrica al voltant de la dada. | J11: =SUMIF(M11:P11,G11,$M$5:$P$5) -> 1 | L11: =D11 -> GB02 | M11: No, no hi ha mètriques d'utilització i rendiment de les dades | N11: Si, per a alguna àrea hi ha alguna mètrica d'utilització i rendiment, però no es fa un seguiment | O11: Si, hi ha mètriques d'utilització i rendiment a les àrees, i es fa un seguiment i utilització d'aquestes dades | P11: Si, hi ha mètriques d'utilització i rendiment a les àrees, es fa un seguiment i utilització d'aquestes dades, i periòdicament es revisen (definició, necessitat, llindars, etc.) per tal de garantir una millora contínua | R11: Cal establir indicadors clau (KPIs) per a mesurar la qualitat, accessibilitat i efectivitat de les dades. Aquestes mètriques haurien de mesurar qualitats com la precisió, integritat, consistència i rendiment de les dades. Això facilitarà la gestió i millora de les dades. | S11: Es recomana fer un monitoreig de les mètriques d'ús i rendiment per a analitzar les mètriques de manera periòdica, i estendre l'activitat a les principals àrees de l'Ajuntament o Organització. Fer el seguiment d'aquestes mètriques ajudarà a identificar possibles millores. | T11: Es recomana optimitzar els processos d'anàlisi per tal d'identificar tendències i punts de millora de manera proactiva, i fer revisions periòdiques per alinear les mètriques amb els objectius estratègics (p.e. el PAM de l'Ajuntament). | U11: _ | W11: =IF(B10="",W10,B10) -> Govern | X11: =IF(E11="",X10,E11) -> Establiment d'estratègies de dades | Y11: =IF(OR($G11=$M11,$G11=""),CONCATENATE(J11," - ",$R11),IF($G11=$N11,CONCATENATE(J11," - ",$S11),IF($G11=$O11,CONCATENATE(J11," - ",$T11),""))) -> 1 - Cal establir indicadors clau (KPIs) per a mesurar la qualitat, accessibilitat i efectivitat de les dades. Aquestes mètriques haurien de mesurar qualitats com la precisió, integritat, consistència i rendiment de les dades. Això facilitarà la gestió i millora de les dades. | Z11: =J11 -> 1
E12: Establiment d'estructures organitzacionals | J12: =SUM(J13)/COUNT(J13) -> 1 | W12: =IF(B11="",W11,B11) -> Govern | X12: =IF(E12="",X11,E12) -> Establiment d'estructures organitzacionals
D13: GC01 | F13: Existeix una estructura organitzativa formal per al Govern de la dada i es porten a terme comitès de dades? | G13: No existeix una estructura organitzativa formal per al Govern de la dada ni es porten a terme comitès de dades | H13: No, no hi ha cap estructura interna que fixi polítiques i protocols d'us de les dades. Sí que tenen la regulació de protecció de dades | J13: =SUMIF(M13:P13,G13,$M$5:$P$5) -> 1 | L13: =D13 -> GC01 | M13: No existeix una estructura organitzativa formal per al Govern de la dada ni es porten a terme comitès de dades | N13: Si, existeix una estructura organitzativa formal per al Govern de la dada, però no es porten a terme comitès de dades de manera regular | O13: Si, existeix una estructura organitzativa formal per al Govern de la dada i si es porten a terme comitès de dades de manera regular | P13: Si, existeix una estructura organitzativa formal per al Govern de la dada i si es porten a terme comitès de dades de manera regular amb un alt grau de col·laboració entre les diferents àrees | R13: Crear una estructura organitzativa mínima viable que permeti iniciar la governança de manera efectiva, definint rols clau, com Responsable de dades i Propietari de dades, i establir un Comitè de Dades per a la coordinació entre àrees | S13: Establir reunions del comitè de dades amb la periodicitat que sigui necessari per fer seguiment de la governança de les dades | T13: Assegurar que les decisions i accions derivades dels comitès estan alineats amb l'estratègia, avaluar i optimitzar els resultats dels Comitès | U13: - | W13: =IF(B12="",W12,B12) -> Govern | X13: =IF(E13="",X12,E13) -> Establiment d'estructures organitzacionals | Y13: =IF(OR($G13=$M13,$G13=""),CONCATENATE(J13," - ",$R13),IF($G13=$N13,CONCATENATE(J13," - ",$S13),IF($G13=$O13,CONCATENATE(J13," - ",$T13),""))) -> 1 - Crear una estructura organitzativa mínima viable que permeti iniciar la governança de manera efectiva, definint rols clau, com Responsable de dades i Propietari de dades, i establir un Comitè de Dades per a la coordinació entre àrees | Z13: =J13 -> 1
E14: Gestió de recursos humans | J14: =SUM(J15:J17)/COUNT(J15:J17) -> 1 | W14: =IF(B13="",W13,B13) -> Govern | X14: =IF(E14="",X13,E14) -> Gestió de recursos humans
D15: GD01 | F15: Estan definits els rols i responsabilitats per al Govern de la dada (al menys Responsable de les dades i Propietari de les dades)? | G15: No, no estan definits els rols i responsabilitats adequadament | H15: No, no tenen una estructura definida i publicada per tal de definir els rols de propietari, gestor, custodi, etc.. de les dades que gestionen. Cal definir tots els rols per tal de que el govern de la dada sigui efectiu. | I15: En la reunió es va fer laès que era necessari tenir | J15: =SUMIF(M15:P15,G15,$M$5:$P$5) -> 1 | L15: =D15 -> GD01 | M15: No, no estan definits els rols i responsabilitats adequadament | N15: Sí, estan definits els rols i responsabilitats, però no estan assignats a personal qualificat. | O15: Sí, estan definits els rols i responsabilitats, i estan assignats a personal qualificat | P15: Sí, estan definits els rols i responsabilitats, es revisen periòdicament i es forma al personal assignat per a garantir una millora continua | R15: És fonamental assignar definir i assignar els rols de Propietari de la dada (Data Owners) i de Responsable de la dada (Data Steward) per a garantitzar la qualitat, seguretat i us adequat de la informació. La definició d'aquests rols ha de deixar clares les funcions i les responsabilitats. | S15: Cal identificar a les persones adequades dins de l'Ajuntament o Organisme i formalitzar l'assignació de rols, comunicar clarament les responsabilitats, capacitar-los i fer seguiment de les seves funcions. | T15: Cal considerar establir mètriques d'ús i rendiment, assegurar que s'utilitzen a la presa de decisions, i implantar processos de millora contínua. | U15: _ | W15: =IF(B14="",W14,B14) -> Govern | X15: =IF(E15="",X14,E15) -> Gestió de recursos humans | Y15: =IF(OR($G15=$M15,$G15=""),CONCATENATE(J15," - ",$R15),IF($G15=$N15,CONCATENATE(J15," - ",$S15),IF($G15=$O15,CONCATENATE(J15," - ",$T15),""))) -> 1 - És fonamental assignar definir i assignar els rols de Propietari de la dada (Data Owners) i de Responsable de la dada (Data Steward) per a garantitzar la qualitat, seguretat i us adequat de la informació. La definició d'aquests rols ha de deixar clares les funcions i les responsabilitats. | Z15: =J15 -> 1
D16: GD02 | F16: Està definit i assignat el rol de Responsable de les dades? | G16: No, no està definit clarament aquest rol i no hi ha personal assignat | H16: Actualment tenen un responsable extern com a respnsable protecció de dades, però no tenen cap respnsable gbeneral de l'organització que vetlli per la bona gestió de les dades | I16: Tenim identificat el responsable de la LOPD. Ho enen externalitzat | J16: =SUMIF(M16:P16,G16,$M$5:$P$5) -> 1 | L16: =D16 -> GD02 | M16: No, no està definit clarament aquest rol i no hi ha personal assignat | N16: Sí, està definit i assignat però, però el personal no coneix clarament les seves funcions | O16: Sí, està definit i assignat, i el personal coneix clarament les seves funcions | P16: Sí, està definit i assignat i el personal coneix clarament les seves funcions i es fan accions periòdiques per tal de garantir una millora continua | R16: S'hauria de definir clarament les funcions del Responsable de dades (Data Stewart), identificar els perfils adequats dins de l'Ajuntament o Organisme i capacitar-los per a portar a terme les seves funcions de manera efectiva. | S16: Cal capacitar al Responsable de dades (Data Stewart) i comunicar clarament les seves funcions dins l'Ajuntament o Organisme per a que pugui desenvolupar les seves funcions de manera efectiva. | T16: És recomanable establir mètriques, optimitzar processos contínuament i fomentar la col·laboració entre els diferents rols per enfortir la governança de dades. | U16: _ | W16: =IF(B15="",W15,B15) -> Govern | X16: =IF(E16="",X15,E16) -> Gestió de recursos humans | Y16: =IF(OR($G16=$M16,$G16=""),CONCATENATE(J16," - ",$R16),IF($G16=$N16,CONCATENATE(J16," - ",$S16),IF($G16=$O16,CONCATENATE(J16," - ",$T16),""))) -> 1 - S'hauria de definir clarament les funcions del Responsable de dades (Data Stewart), identificar els perfils adequats dins de l'Ajuntament o Organisme i capacitar-los per a portar a terme les seves funcions de manera efectiva. | Z16: =J16 -> 1
D17: GD03 | F17: Està identificat i es coneix el propietari de les dades de cada Àrea? | G17: No, no està definit clarament aquest rol i no hi ha personal assignat | H17: De manera oficiosa cada cap de departament és el responsable de l'ús que s'en fa de les dades. Però en cap cas això es oficial dins de l'organització | I17: Cal reflectir la responsabilitat en temes d'us de dades per art dels caps de cada àrea. | J17: =SUMIF(M17:P17,G17,$M$5:$P$5) -> 1 | L17: =D17 -> GD03 | M17: No, no està definit clarament aquest rol i no hi ha personal assignat | N17: Sí, està definit i assignat però, però el personal no coneix clarament les seves funcions, o hi ha alguna àrea per a les que no hi ha personal assignat | O17: Sí, està definit i assignat, i el personal a cada àrea coneix clarament les seves funcions. | P17: Sí, està definit i assignat, i el personal a cada àrea coneix clarament les seves funcions, i es fan accions periòdiques per tal de garantir una millora continua | R17: És important definir el rol de Propietari de dades (Data Owner) i assignar-lo a persones amb gran coneixement funcional i responsabilitat sobre les dades. El Responsable de dades ha de ser responsable de la qualitat , seguretat i accés a les dades, i tenir l'autoritat per a la presa de decisions i garantir que les dades es gestionen adequadament. | S17: Cal comunicar l'existència del rol de Propietari de dades, el personal que té assignat i les responsabilitats de manera clara dins l'Ajuntament o Organisme. | T17: És interessant garantir l'autoritat i visibilitat dels Propietaris de dades, assegurant que tingui els recursos i que s'implementen activitats de millora contínua. | U17: _ | W17: =IF(B16="",W16,B16) -> Govern | X17: =IF(E17="",X16,E17) -> Gestió de recursos humans | Y17: =IF(OR($G17=$M17,$G17=""),CONCATENATE(J17," - ",$R17),IF($G17=$N17,CONCATENATE(J17," - ",$S17),IF($G17=$O17,CONCATENATE(J17," - ",$T17),""))) -> 1 - És important definir el rol de Propietari de dades (Data Owner) i assignar-lo a persones amb gran coneixement funcional i responsabilitat sobre les dades. El Responsable de dades ha de ser responsable de la qualitat , seguretat i accés a les dades, i tenir l'autoritat per a la presa de decisions i garantir que les dades es gestionen adequadament. | Z17: =J17 -> 1
B18: Gestió de dades | J18: =AVERAGE(J19,J22,J24,J27,J29) -> 1.5 | W18: =IF(B17="",W17,B17) -> Govern | X18: =IF(E18="",X17,E18) -> Gestió de recursos humans
E19: Gestió de seguretat de dades | J19: =SUM(J20:J21)/COUNT(J20:J21) -> 2.5 | W19: =IF(B18="",W18,B18) -> Gestió de dades | X19: =IF(E19="",X18,E19) -> Gestió de seguretat de dades
D20: MA01 | F20: Existeixen Polítiques de seguretat i privadesa de les dades alineades amb les regulacions vigents i s'avalua el seu compliment? | G20: Si, hi ha Polítiques de seguretat i privadesa alineades amb les regulacions vigents, però no son conegudes pel personal i/o no s'avalua el seu compliment | H20: Sí, com ja s'ha comentat anteriorment tenen un servei externalitzat que els proveeix de la normativa de privacitat i protecció de dades | I20: Tot i que sí han fet auditoria sobre la privacitat de les dades de la LOPD. Tenen una empresa que es la responsable de dades des de el punt de vista de la LOPD, dona suport també al conjunt de l'organització sobre dubtes que puguin sorgir respecte del compliment. | J20: =SUMIF(M20:P20,G20,$M$5:$P$5) -> 2 | L20: =D20 -> MA01 | M20: No, no hi ha Polítiques de seguretat i privadesa alineades amb les regulacions vigents | N20: Si, hi ha Polítiques de seguretat i privadesa alineades amb les regulacions vigents, però no son conegudes pel personal i/o no s'avalua el seu compliment | O20: Si, hi ha Polítiques de seguretat i privadesa alineades amb les regulacions vigents que son conegudes pel personal, i es fan revisions del seu compliment | P20: Si, hi ha Polítiques de seguretat i privadesa alineades amb les regulacions vigents que son conegudes pel personal, i es fan revisions del seu compliment. Addicionalment es fan revisions d'aquestes per tal assegurar l'alineament amb noves regulacions i per optimitzar els processos | R20: Definir les Polítiques de seguretat i privadesa alineades amb les regulacions vigents. Per tal de fer aquest camí més senzill i aprofitant l'experiència de la DIBA, aquesta facilita el procediment d'adhesió a les seves Polítiques. | S20: Divulgar les Polítiques de seguretat i privadesa entre el personal per tal que aquestes siguin conegudes, i fer avaluacions periòdiques del seu compliment | T20: Fer revisions periòdiques de les Polítiques per tal d'assegurar que aquestes es mantenen actualitzades amb les regulacions vigents i cercar oportunitats de millora continua | U20: - | W20: =IF(B19="",W19,B19) -> Gestió de dades | X20: =IF(E20="",X19,E20) -> Gestió de seguretat de dades | Y20: =IF(OR($G20=$M20,$G20=""),CONCATENATE(J20," - ",$R20),IF($G20=$N20,CONCATENATE(J20," - ",$S20),IF($G20=$O20,CONCATENATE(J20," - ",$T20),""))) -> 2 - Divulgar les Polítiques de seguretat i privadesa entre el personal per tal que aquestes siguin conegudes, i fer avaluacions periòdiques del seu compliment | Z20: =J20 -> 2
D21: MA02 | F21: Les dades s'identifiquen i classifiquen en nivells de sensibilitat en funció de l'àmbit d'actuació dins de l'Ajuntament/Organisme? | G21: Si, les dades es classifiquen en funció de la seva sensibilitat i el personal coneix i utilitza les dades d'acord a aquesta classificació | H21: Sí, el responsable de protecció de dades juntament amb cada departament classifiquen la criticitat de cada tipologia de dada per saber quines dades han de tenir una protecció determinada | J21: =SUMIF(M21:P21,G21,$M$5:$P$5) -> 3 | L21: =D21 -> MA02 | M21: No, no es classifiquen les dades en funció de la seva sensibilitat | N21: Si, algunes dades es classifiquen en funció de la seva sensibilitat i/o el personal no coneix aquesta classificació | O21: Si, les dades es classifiquen en funció de la seva sensibilitat i el personal coneix i utilitza les dades d'acord a aquesta classificació | P21: Si, les dades es classifiquen en funció de la seva sensibilitat i el personal coneix i utilitza les dades d'acord a aquesta classificació, i es fan auditories periòdiques per tal de detectar possibles errors i fer millora continua | R21: Identificar i classificar les dades clau en funció de la seva sensibilitat | S21: Assegurar que estan identificades i classificades totes les dades clau en funció de la seva sensibilitat i que el personal utilitza les dades d'acord a aquesta classificació | T21: Es recomana establir auditories que ajudin a detectar errors i definir accions de millora continua | U21: _ | W21: =IF(B20="",W20,B20) -> Gestió de dades | X21: =IF(E21="",X20,E21) -> Gestió de seguretat de dades | Y21: =IF(OR($G21=$M21,$G21=""),CONCATENATE(J21," - ",$R21),IF($G21=$N21,CONCATENATE(J21," - ",$S21),IF($G21=$O21,CONCATENATE(J21," - ",$T21),""))) -> 3 - Es recomana establir auditories que ajudin a detectar errors i definir accions de millora continua | Z21: =J21 -> 3
E22: Gestió de dades històriques | J22: =SUM(J23)/COUNT(J23) -> 2 | W22: =IF(B21="",W21,B21) -> Gestió de dades | X22: =IF(E22="",X21,E22) -> Gestió de dades històriques
D23: MB01 | F23: Existeixen Polítiques d'arxivat i restauració de dades? | G23: Si, hi ha Polítiques d'arxivat i restauració de dades, però no s'apliquen adequadament | H23: Tenen regulat la part dels expdients,. toa la resta de documentació no ho tenen sota polítiques de gestió de documenació | I23: La part de documnetació de gestió d'expedients sí, la resta de dades no. | J23: =SUMIF(M23:P23,G23,$M$5:$P$5) -> 2 | L23: =D23 -> MB01 | M23: No, no hi ha Polítiques d'arxivat i restauració de dades | N23: Si, hi ha Polítiques d'arxivat i restauració de dades, però no s'apliquen adequadament | O23: Si, hi ha Polítiques d'arxivat i restauració de dades que s'apliquen adequadament | P23: Si, hi ha Polítiques d'arxivat i restauració de dades que s'apliquen adequadament i son revisades de forma periòdica per tal de millorar-les | R23: Definir les Polítiques d'arxivat i restauració de dades . Per tal de fer aquest camí més senzill i aprofitant l'experiència de la DIBA, aquesta facilita el procediment d'adhesió a les seves Polítiques. | S23: Revisar i implicar al personal en l'aplicació de les Polítiques d'arxivat i restauració de dades | T23: Portar a terme accions de millora continua de les Polítiques d'arxivat i restauració de dades | U23: - | W23: =IF(B22="",W22,B22) -> Gestió de dades | X23: =IF(E23="",X22,E23) -> Gestió de dades històriques | Y23: =IF(OR($G23=$M23,$G23=""),CONCATENATE(J23," - ",$R23),IF($G23=$N23,CONCATENATE(J23," - ",$S23),IF($G23=$O23,CONCATENATE(J23," - ",$T23),""))) -> 2 - Revisar i implicar al personal en l'aplicació de les Polítiques d'arxivat i restauració de dades | Z23: =J23 -> 2
E24: Gestió de fonts i destinacions de dades | J24: =SUM(J25:J26)/COUNT(J25:J26) -> 1 | W24: =IF(B23="",W23,B23) -> Gestió de dades | X24: =IF(E24="",X23,E24) -> Gestió de fonts i destinacions de dades
D25: MC01 | F25: Existeix un Inventari de dades, que inclou conjunts de dades, dades mestre i de referència, i metadades, i on s'identifiquen les fonts de dades de l'Ajuntament/Organisme que és compartit i conegut pel personal? | G25: No, no existeix un Catàleg de dades ni Inventari de dades | H25: No existeix cap repositori sobre totes les dades que existeix a la pròpia organització. El 2006 van fer un recull de totes les bases de dades que hi havia per departament de cada a la protecció de dades | I25: Va fer una auditoria per al compliment de la LOPD per a totes les àrees a excepció de serveis econòmics i secretaria. Fer referència tots els dossiers on s'identifica totes les taules. | J25: =SUMIF(M25:P25,G25,$M$5:$P$5) -> 1 | L25: =D25 -> MC01 | M25: No, no existeix un Catàleg de dades ni Inventari de dades | N25: Si, existeix el Catàleg de dades i l'Inventari de dades, però aquest no és complet i/o el seu us és bastant limitat | O25: Si, existeix el Catàleg de dades i l'Inventari de dades, on s'identifiquen les fonts de dades de l'Ajuntament/Organisme, les dades clau, i son coneguts i utilitzats de manera regular | P25: Si, existeix el Catàleg de dades i l'Inventari de dades, on s'identifiquen les fonts de dades de l'Ajuntament/Organisme, les dades clau, son coneguts i utilitzats de manera regular, i regularment es revisa per tal de fer millora continua i avaluar el seu us | R25: Iniciar les tasques d'implementació de l'Inventari de dades | S25: Ampliar l'Inventari de dades a totes les dades clau, i difondre i promoure la seva utilització | T25: Fer revisions periòdiques de l'Inventari de dades per tal d'assegurar que aquest es manté actualitzat i cercar oportunitats de millora continua | U25: - | W25: =IF(B24="",W24,B24) -> Gestió de dades | X25: =IF(E25="",X24,E25) -> Gestió de fonts i destinacions de dades | Y25: =IF(OR($G25=$M25,$G25=""),CONCATENATE(J25," - ",$R25),IF($G25=$N25,CONCATENATE(J25," - ",$S25),IF($G25=$O25,CONCATENATE(J25," - ",$T25),""))) -> 1 - Iniciar les tasques d'implementació de l'Inventari de dades | Z25: =J25 -> 1
D26: MC02 | F26: Estan identificades les dades i fonts de dades externes i aquestes es gestionen mitjançant acords formals i s'estableixen controls de qualitat específics? | G26: No, no estan identificades les dades ni fonts de dades externes | H26: No, no existeix cap desenvolupament en aquest sentit | J26: =SUMIF(M26:P26,G26,$M$5:$P$5) -> 1 | L26: =D26 -> MC02 | M26: No, no estan identificades les dades ni fonts de dades externes | N26: Si, estan identificades les dades i les fonts de dades externes però no hi ha una gestió específica sobre aquestes | O26: Si, estan identificades les dades i les fonts de dades externes i es fa una gestió específica sobre aquestes per tal d'assegurar que son de qualitat i segures | P26: Si, estan identificades les dades i les fonts de dades externes i es fa una gestió específica sobre aquestes per tal d'assegurar que son de qualitat i segures, i es fan avaluacions periòdiques per tal de trobar punts de millora continua | R26: Identificar les fonts de dades externes i les dades associades per tal de poder fer una gestió específica d'aquestes | S26: Fer una gestió específica sobre les fonts de dades i dades externes per tal d'assegurar que son de qualitat i segures | T26: Establir mecanismes de millora continua als processos de gestió de dades i fonts de dades externes | U26: _ | W26: =IF(B25="",W25,B25) -> Gestió de dades | X26: =IF(E26="",X25,E26) -> Gestió de fonts i destinacions de dades | Y26: =IF(OR($G26=$M26,$G26=""),CONCATENATE(J26," - ",$R26),IF($G26=$N26,CONCATENATE(J26," - ",$S26),IF($G26=$O26,CONCATENATE(J26," - ",$T26),""))) -> 1 - Identificar les fonts de dades externes i les dades associades per tal de poder fer una gestió específica d'aquestes | Z26: =J26 -> 1
E27: Gestió de la integració de les dades | J27: =SUM(J28)/COUNT(J28) -> 1 | W27: =IF(B26="",W26,B26) -> Gestió de dades | X27: =IF(E27="",X26,E27) -> Gestió de la integració de les dades
D28: MD01 | F28: Existeixen Polítiques i procediments d'integració, gestió i utilització de les dades? | G28: No, no hi ha Polítiques ni procediments d'integració, gestió ni utilització de les dades | H28: No toes les fonts i aactius de dades operen de manera independent i sota els objectius de cada departament. | J28: =SUMIF(M28:P28,G28,$M$5:$P$5) -> 1 | L28: =D28 -> MD01 | M28: No, no hi ha Polítiques ni procediments d'integració, gestió ni utilització de les dades | N28: Si, hi ha Polítiques i procediments d'integració, gestió i utilització de les dades, però no s'apliquen adequadament | O28: Si, hi ha Polítiques i procediments d'integració, gestió i utilització de les dades, que s'apliquen adequadament | P28: Si, hi ha Polítiques i procediments d'integració, gestió i utilització de les dades, que s'apliquen adequadament, que son avaluats paròdicament per tal de trobar punts de millora continua | R28: Definir les Polítiques i procediments d'integració, gestió i utilització de les dades . Per tal de fer aquest camí més senzill i aprofitant l'experiència de la DIBA, aquesta facilita el procediment d'adhesió a les seves Polítiques. | S28: Revisar i implicar al personal en l'aplicació de les Polítiques i procediments d'integració, gestió i utilització de les dades | T28: Portar a terme accions de millora continua de les Polítiques i procediments d'integració, gestió i utilització de les dades | U28: - | W28: =IF(B27="",W27,B27) -> Gestió de dades | X28: =IF(E28="",X27,E28) -> Gestió de la integració de les dades | Y28: =IF(OR($G28=$M28,$G28=""),CONCATENATE(J28," - ",$R28),IF($G28=$N28,CONCATENATE(J28," - ",$S28),IF($G28=$O28,CONCATENATE(J28," - ",$T28),""))) -> 1 - Definir les Polítiques i procediments d'integració, gestió i utilització de les dades . Per tal de fer aquest camí més senzill i aprofitant l'experiència de la DIBA, aquesta facilita el procediment d'adhesió a les seves Polítiques. | Z28: =J28 -> 1
E29: Gestió de Dades Mestre i Dades de Referència | J29: =SUM(J30)/COUNT(J30) -> 1 | W29: =IF(B28="",W28,B28) -> Gestió de dades | X29: =IF(E29="",X28,E29) -> Gestió de Dades Mestre i Dades de Referència
D30: ME01 | F30: Estan identificades les Dades Mestre i les Dades de Referència? Dades Mestre son les dades que representen la informació fonamental per a l'Ajuntament/Organisme (p.e. nom, cognoms, tributs, empleats, etc.) Dades de Referència son les dades que s'utilitzen como referència o estàndard per a contextualitzar altres dades (p.e. codis postals, municipis, calendaris de festius, llistat de tributs, CNAE, etc.) | G30: No, no estan identificades les Dades Mestre ni les Dades de Referència | H30: No han fet aquest treball d'identificar i classificar la tipologia de dades si son Mestres o de Referència | J30: =SUMIF(M30:P30,G30,$M$5:$P$5) -> 1 | L30: =D30 -> ME01 | M30: No, no estan identificades les Dades Mestre ni les Dades de Referència | N30: Si, hi ha identificades Dades Mestre i les Dades de Referència, però la identificació no és completa | O30: Si, hi ha identificades totes les Dades Mestre i les Dades de Referència clau per a l'Ajuntament/Organisme | P30: Si, hi ha identificades totes les Dades Mestre i les Dades de Referència clau per a l'Ajuntament/Organisme, i periòdicament es revisen les definicions d'aquestes, la completitut i es porten a terme tasques de millora continua | R30: Definir les Polítiques i procediments d'integració, gestió i utilització de les dades . Per tal de fer aquest camí més senzill i aprofitant l'experiència de la DIBA, aquesta facilita el procediment d'adhesió a les seves Polítiques. | S30: Revisar i implicar al personal en l'aplicació de les Polítiques i procediments d'integració, gestió i utilització de les dades | T30: Portar a terme accions de millora continua de les Polítiques i procediments d'integració, gestió i utilització de les dades | U30: - | W30: =IF(B29="",W29,B29) -> Gestió de dades | X30: =IF(E30="",X29,E30) -> Gestió de Dades Mestre i Dades de Referència | Y30: =IF(OR($G30=$M30,$G30=""),CONCATENATE(J30," - ",$R30),IF($G30=$N30,CONCATENATE(J30," - ",$S30),IF($G30=$O30,CONCATENATE(J30," - ",$T30),""))) -> 1 - Definir les Polítiques i procediments d'integració, gestió i utilització de les dades . Per tal de fer aquest camí més senzill i aprofitant l'experiència de la DIBA, aquesta facilita el procediment d'adhesió a les seves Polítiques. | Z30: =J30 -> 1
B31: Qualitat de la dada | J31: =AVERAGE(J32,J36,J34) -> 1 | W31: =IF(B30="",W30,B30) -> Gestió de dades | X31: =IF(E31="",X30,E31) -> Gestió de Dades Mestre i Dades de Referència
E32: Establiment d'estàndards, polítiques, bones pràctiques i procediments | J32: =SUM(J33:J33)/COUNT(J33:J33) -> 1 | W32: =IF(B31="",W31,B31) -> Qualitat de la dada | X32: =IF(E32="",X31,E32) -> Establiment d'estàndards, polítiques, bones pràctiques i procediments
D33: QA01 | F33: Estan documentats els requeriments de qualitat de les dades (precisió, integritat, consistència, completitut, puntualitat, etc.? | G33: No, no estan documentats els requeriments de qualitat de les dades | H33: No hi ha un document que ho especifiqui tot i que els programaris ja defineix l'estructura de la dada a introduir. | J33: =SUMIF(M33:P33,G33,$M$5:$P$5) -> 1 | L33: =D33 -> QA01 | M33: No, no estan documentats els requeriments de qualitat de les dades | N33: Si, estan documentats alguns requeriments de qualitat d'algunes dades | O33: Si, estan documentats els requeriments de qualitat de les dades i hi ha processos automàtics orientats a garantir la qualitat de les dades | P33: Si, estan documentats els requeriments de qualitat de les dades i hi ha processos automàtics orientats a garantir la qualitat de les dades, i aquests es revisen de manera regular per tal d'identificar i aplicar millores | R33: Iniciar la documentació dels requeriments de qualitat de les dades, prioritzant les dades clau i crítiques | S33: Completar la documentació de requeriments de qualitat de les dades i valorar l'automatització de processos que ajudin a garantir la qualitat de les dades | T33: Maximitzar l'automatització de processos que ajudin a garantir la qualitat de les dades i establir mecanismes de millora continua | U33: - | W33: =IF(B32="",W32,B32) -> Qualitat de la dada | X33: =IF(E33="",X32,E33) -> Establiment d'estàndards, polítiques, bones pràctiques i procediments | Y33: =IF(OR($G33=$M33,$G33=""),CONCATENATE(J33," - ",$R33),IF($G33=$N33,CONCATENATE(J33," - ",$S33),IF($G33=$O33,CONCATENATE(J33," - ",$T33),""))) -> 1 - Iniciar la documentació dels requeriments de qualitat de les dades, prioritzant les dades clau i crítiques | Z33: =J33 -> 1
E34: Control i monitorització de la qualitat de les dades | J34: =SUM(J35:J35)/COUNT(J35:J35) -> 1 | W34: =IF(B33="",W33,B33) -> Qualitat de la dada | X34: =IF(E34="",X33,E34) -> Control i monitorització de la qualitat de les dades
D35: QB01 | F35: Es fa un seguiment actiu i monitoratge de la qualitat de les dades? | G35: No, no es fa un seguiment actiu ni es monitoritza la qualitat de les dades | H35: Al no tenir una política de qualitat de les dades no es fa el seguiment | I35: Aquí farem un quadre de comendament sobre la qualitat de dades sobre tots els indicadors del serveis tècnics. | J35: =SUMIF(M35:P35,G35,$M$5:$P$5) -> 1 | L35: =D35 -> QB01 | M35: No, no es fa un seguiment actiu ni es monitoritza la qualitat de les dades | N35: Si, es fan seguiments i monitorització de la qualitat de les dades de manera esporàdica únicament quan es detecten errors, i s'estableixen mesures correctives. | O35: Si, es fan seguiments i monitorització de la qualitat de les dades de manera regular i planificada, per implantar mesures correctives i preventives | P35: Si, es fan seguiments i monitorització de la qualitat de les dades de manera regular i planificada, per implantar mesures correctives i preventives, i s'avaluen els propis criteris de seguiment i monitorització per tal d'optimitzar-los | R35: Començar a fer seguiment actiu i monitorització de la qualitat de les dades | S35: Periodificar i ampliar l'abast del seguiment i monitorització de la qualitat de les dades per tal que doni suport a la implantació accions orientades a la prevenció | T35: Implantar revisions periòdiques d'avaluació dels propis criteris de seguiment i monitorització de la qualitat per tal d'optimitzar-los | U35: _ | W35: =IF(B33="",W33,B33) -> Qualitat de la dada | X35: =IF(E35="",X33,E35) -> Establiment d'estàndards, polítiques, bones pràctiques i procediments | Y35: =IF(OR($G35=$M35,$G35=""),CONCATENATE(J35," - ",$R35),IF($G35=$N35,CONCATENATE(J35," - ",$S35),IF($G35=$O35,CONCATENATE(J35," - ",$T35),""))) -> 1 - Començar a fer seguiment actiu i monitorització de la qualitat de les dades | Z35: =J35 -> 1
E36: Planificació de la qualitat de les dades | J36: =SUM(J37:J37)/COUNT(J37:J37) -> 1 | W36: =IF(B35="",W35,B35) -> Qualitat de la dada | X36: =IF(E36="",X35,E36) -> Planificació de la qualitat de les dades
D37: QC01 | F37: Existeix una planificació de les activitats d'assegurament de la qualitat de les dades que detalla els objectius de qualitat, planifica el seguiment i monitorització de la qualitat de les dades, etc.? | G37: No, no es planifiquen les activitats d'assegurament de la qualitat de les dades | H37: Exactament el mateix que en l'apartat anterior | J37: =SUMIF(M37:P37,G37,$M$5:$P$5) -> 1 | L37: =D37 -> QC01 | M37: No, no es planifiquen les activitats d'assegurament de la qualitat de les dades | N37: Si, es planifiquen les activitats d'assegurament de la qualitat de les dades, però aquesta planificació no detalla els objectius de qualitat o les activitats de seguiment i monitorització de la qualitat | O37: Si, es planifiquen les activitats d'assegurament de la qualitat de les dades, detallant els objectius de qualitat i les activitats de seguiment i monitorització de la qualitat | P37: Si, es planifiquen les activitats d'assegurament de la qualitat de les dades, detallant els objectius de qualitat i les activitats de seguiment i monitorització de la qualitat, i es fan activitats de millora continua de les pròpies activitats de planificació | R37: Preparar un pla d'assegurament de la qualitat de les dades, que inicialment posi el focus en les dades crítiques i dades clau | S37: Ampliar el detall del pla d'assegurament de la qualitat de les dades, assegurant que aquest detalla els objectius de qualitat, i les activitats de seguiment i monitorització | T37: Incorporar avaluacions de millora continua per al propi procés de planificació de la qualitat de les dades. | U37: - | W37: =IF(B36="",W36,B36) -> Qualitat de la dada | X37: =IF(E37="",X36,E37) -> Planificació de la qualitat de les dades | Y37: =IF(OR($G37=$M37,$G37=""),CONCATENATE(J37," - ",$R37),IF($G37=$N37,CONCATENATE(J37," - ",$S37),IF($G37=$O37,CONCATENATE(J37," - ",$T37),""))) -> 1 - Preparar un pla d'assegurament de la qualitat de les dades, que inicialment posi el focus en les dades crítiques i dades clau | Z37: =J37 -> 1

Sheet Gestió de la dada
B2: Gestió de dades | H2: =H6/P6 -> 0
C4: La Gestió de Dades es refereix al conjunt d'activitats i procediments utilitzats per recollir, emmagatzemar, organitzar, mantenir i utilitzar dades de manera eficient. Aquest procés és crucial per garantir que les dades siguin accessibles, fiables i segures. L'objectiu principal de la Gestió de Dades és assegurar que les dades siguin utilitzades de manera eficient i efectiva per aportar valor a l'Ajuntament, Organisme o Àrea.
C6: Id. | D6: Qüestió | E6: Resposta | F6: Observacions | G6: Evidències i documentació | H6: =SUM(H7:H16) -> 0 | K6: 0 | L6: 1 | M6: 2 | N6: 3 | P6: =SUM(P7:P16) -> 26
C7: CD.01 | D7: Existeix un catàleg de dades? (una relació de les agrupacions de dades de l'Ajuntament) | H7: =SUMIF(K7:N7,E7,$K$6:$N$6) -> 0 | J7: CD.01 | K7: No | L7: Si, però no el coneix tothom qui el pot necessitar | M7: Si, i és conegut per l'Ajuntament | P7: =COUNTA(L7:N7) -> 2
C8: CD.02 | D8: El Catàleg de dades està implementat i poblat amb els actius de dades existents? | H8: =SUMIF(K8:N8,E8,$K$6:$N$6) -> 0 | J8: CD.02 | K8: No | L8: Si, però és poc complet | M8: Si, agrupa una gran quantitat de dades | P8: =COUNTA(L8:N8) -> 2
C9: CD.03 | D9: Existeix un Inventari de dades? (recopilació centralitzada de metadades de l'Ajuntament) | H9: =SUMIF(K9:N9,E9,$K$6:$N$6) -> 0 | J9: CD.03 | K9: No | L9: Si, però és poc complet | M9: Si, és bastant complet | N9: Si, és complet | P9: =COUNTA(L9:N9) -> 3
C10: CD.04 | D10: Estan definits els rols i les responsabilitats associades al Catàleg de dades i a l'Inventari de dades? | H10: =SUMIF(K10:N10,E10,$K$6:$N$6) -> 0 | J10: CD.04 | K10: No | L10: No sempre estan definits els rols/responsabilitats | M10: Estan definits els rols però les responsabilitats no estan clares | N10: Si, tant els rols com les responsabilitats estan clares | P10: =COUNTA(L10:N10) -> 3
C11: CD.05 | D11: El Catàleg de dades inclou Metadades de Negoci? (que descriuen les dades des de una perspectiva d'usuari de negoci) | H11: =SUMIF(K11:N11,E11,$K$6:$N$6) -> 0 | J11: CD.05 | K11: No | L11: Si, però és poc complet | M11: Si, és bastant complet | N11: Si, és complet | P11: =COUNTA(L11:N11) -> 3
C12: CD.06 | D12: El Catàleg de dades inclou Metadades tècniques? (que descriuen els aspectes tècnics de les dades, com estructures de base de dades, tipus, longituds, allotjament, etc.) | H12: =SUMIF(K12:N12,E12,$K$6:$N$6) -> 0 | J12: CD.06 | K12: No | L12: Si, però és poc complet | M12: Si, és bastant complet | N12: Si, és complet | P12: =COUNTA(L12:N12) -> 3
C13: CD.07 | D13: El Catàleg de dades inclou Metadades operacionals? (que descriuen els aspectes d'utilització i flux de les dades, com origen, registres d'auditoria, historial de canvis, processos ETL, etc.) | H13: =SUMIF(K13:N13,E13,$K$6:$N$6) -> 0 | J13: CD.07 | K13: No | L13: Si, però és poc complet | M13: Si, és bastant complet | N13: Si, és complet | P13: =COUNTA(L13:N13) -> 3
C14: CD.08 | D14: Els diferents tipus d'Usuari coneixen i tenen accés al Catàleg de dades i tenen les capacitats per a utilitzar-lo? | H14: =SUMIF(K14:N14,E14,$K$6:$N$6) -> 0 | J14: CD.08 | K14: No | L14: Si, però únicament uns usuaris avançats | M14: Si, tots els potencials usuaris | P14: =COUNTA(L14:N14) -> 2
C15: CD.09 | D15: Es monitoritza la qualitat i completitud del Catàleg de dades? | H15: =SUMIF(K15:N15,E15,$K$6:$N$6) -> 0 | J15: CD.09 | K15: No | L15: Si, però únicament quan es detecten errors | M15: Si, es fan revisions periòdiques planificades, i d'aquestes es generen activitats de millora | P15: =COUNTA(L15:N15) -> 2
C16: CD.10 | D16: Es recullen dades dels usuaris de les dades i es tenen en compte a un procés de millora contínua? | H16: =SUMIF(K16:N16,E16,$K$6:$N$6) -> 0 | J16: CD.10 | K16: No | L16: Per a algunes àrees, alguna vegada | M16: Per a algunes àrees de manera sistemàtica | N16: De manera sistemàtica per a totes les àrees | P16: =COUNTA(L16:N16) -> 3

Sheet Qualitat de la dada
B2: Qualitat de la dada | H2: =H6/P6 -> 0.0625
C4: La Gestió de la Qualitat de la Dada és refereix a tot un conjunt de pràctiques i processos destinats a assegurar que les dades compleixin amb els criteris de qualitat establerts. L'objectiu final és assegurar que les dades siguin fiables, precises i útils, permetent així la presa de decisions informades i millorant l'eficiència operativa de l'Ajuntament, Organisme o Àrea.
C6: Id. | D6: Qüestió | E6: Resposta | F6: Observacions | G6: Evidències i documentació | H6: =SUM(H7:H13) -> 1 | K6: 0 | L6: 1 | M6: 2 | N6: 3 | P6: =SUM(P7:P14) -> 16
C7: QD.01 | D7: Es planifiquen activitats orientades a garantir la qualitat de les dades | H7: =SUMIF(K7:N7,E7,$K$6:$N$6) -> 0 | J7: =C7 -> QD.01 | K7: No, mai | L7: S'ha fet alguna vegada puntualment | M7: Es planifica però no sempre s'executa | N7: És una activitat planificada que s'executa amb periodicitat | P7: =COUNTA(L7:N7) -> 3
C8: QD.02 | D8: Hi ha documentats criteris de qualitat de les dades? | H8: =SUMIF(K8:N8,E8,$K$6:$N$6) -> 0 | J8: =C8 -> QD.02 | K8: No | L8: Si, però és poc complet | M8: Si, estan documentats els criteris de qualitat | P8: =COUNTA(L8:N8) -> 2
C9: QD.03 | D9: Es fa un seguiment actiu i monitoratge de la qualitat de les dades? | E9: S'ha fet alguna vegada puntualment | H9: =SUMIF(K9:N9,E9,$K$6:$N$6) -> 1 | J9: =C9 -> QD.03 | K9: No | L9: S'ha fet alguna vegada puntualment | M9: Es planifica però no sempre s'executa | N9: És una activitat planificada que s'executa amb periodicitat | P9: =COUNTA(L9:N9) -> 3
C10: QD.04 | D10: Hi ha activitats d'assegurament de la qualitat de les dades al moment en que aquestes es generen? | H10: =SUMIF(K10:N10,E10,$K$6:$N$6) -> 0 | J10: =C10 -> QD.04 | K10: No | L10: Si, però es tracta d'activitats puntuals no sistemàtiques | M10: Si, es tracta d'activitats que es fan de manera planificada i sistemàtica | P10: =COUNTA(L10:N10) -> 2
C11: QD.05 | D11: Hi ha activitats d'assegurament de la qualitat de les dades ja existents? (p.e. processos de neteja i correcció) | H11: =SUMIF(K11:N11,E11,$K$6:$N$6) -> 0 | J11: =C11 -> QD.05 | K11: No | L11: Si, però es tracta d'activitats puntuals no sistemàtiques | M11: Si, es tracta d'activitats que es fan de manera planificada i sistemàtica | P11: =COUNTA(L11:N11) -> 2
C12: QD.06 | D12: Es fa reporting de la qualitat de les dades? | H12: =SUMIF(K12:N12,E12,$K$6:$N$6) -> 0 | J12: =C12 -> QD.06 | K12: No | L12: Si, però es tracta d'activitats puntuals no sistemàtiques | M12: Si, es tracta d'activitats que es fan de manera planificada i sistemàtica | P12: =COUNTA(L12:N12) -> 2
C13: QD.07 | D13: S'implementen processos de millora contínua? | H13: =SUMIF(K13:N13,E13,$K$6:$N$6) -> 0 | J13: =C13 -> QD.07 | K13: No | L13: Si, però es tracta d'activitats puntuals no sistemàtiques | M13: Si, es tracta d'activitats que es fan de manera planificada i sistemàtica | P13: =COUNTA(L13:N13) -> 2

Sheet Pla d'accions (anàlisi)
B2: Qüestionari d'avaluació de la maduresa
B4: Pla d'accions
G5: Prioritat aut. | H5: Impacte | I5: Dificultat | J5: Impacte + Dificultat | K5: Termini objectiu
B6: Govern
D7: Establiment d'estàndards, polítiques, bones pràctiques i procediments
E8: GA01 | F8: =IF(VLOOKUP(E8,[1]Qüestionari!D:Z,22,0)="","<No aplica>",VLOOKUP(E8,[1]Qüestionari!D:Z,22,0)) -> 1 - Definir un Marc de Govern de la dada de marea senzilla i escalable alineat amb els objectius de l'Ajuntament/Organisme, definint regles clares de gestió de les dades (qualitat, seguretat i accés), rols i responsabilitats i processos clau) | G8: =IF(VLOOKUP(E8,[1]Qüestionari!D:Z,23,0)=4,"",VLOOKUP(E8,[1]Qüestionari!D:Z,23,0)) -> 1 | H8: 1 - Alt | I8: 3 - Alta | J8: =IF(AND(H8<>"",I8<>""),INT(LEFT(H8,1))+INT(LEFT(I8,1)),"") -> 4 | K8: Mig termini (6 – 18 mesos)
