Workbook
Name AbastOrganitzatiu: Llistes!$T$2:$T$6
Name AltValor: Llistes!$AA$2:$AA$10
Name Àmbit: Llistes!$R$2:$R$6
Name AnàlisiRiscos: Llistes!$BS$2:$BS$10
Name AnàlisiRiscosGrau: Llistes!$BT$2:$BT$10
Name Àrea: Llistes!$D$5:$D$37
Name ArquitecturaCloud: Llistes!$J$2:$J$7
Name Cadencia: Llistes!$AC$2:$AC$10
Name CategoriaConjuntDades: Llistes!$AO$2:$AO$7
Name Confidencialitat: Llistes!$BG$2:$BG$5
Name ConjuntsDades: 'Conjunts de dades'!$B$9:$B$200
Name ControlRelacions: 'Rel.Conjunts-Sistemes'!$G$9:$G$200
Name Criticitat: Llistes!$P$2:$P$6
Name DadesObertes: Llistes!$AM$2:$AM$8
Name Dominis: 'Dominis de dades'!$B$8:$B$62
Name Dominis_a_ConjuntsDades: 'Conjunts de dades'!$D$9:INDEX('Conjunts de dades'!$D:$D,COUNTA('Conjunts de dades'!$D:$D))
Name DominisDades: 'Dominis de dades'!$B$9:$E$62
Name EntitatsGlobals: Llistes!$AS$2:$AS$38
Name EstatSistemes: Llistes!$L$2:$L$12
Name Format: Llistes!$BI$2:$BI$12
Name LlistaConjunts: Llistes!$F$2:INDEX(Llistes!$F:$F,COUNTA(Llistes!$F:$F))
Name LlistaDominis: Llistes!$D$2:INDEX(Llistes!$D:$D,COUNTA(Llistes!$D:$D))
Name LlistaSistemes: Llistes!$B$2:INDEX(Llistes!$B:$B,COUNTA(Llistes!$B:$B))
Name NivellAccés: Llistes!$AE$2:$AE$10
Name Nom_Conjunt_de_dades: 'Conjunts de dades'!$B$8:$B$200
Name Origens: Llistes!$AK$2:$AK$9
Name Orígens: Llistes!$AK$2:$AK$7
Name Persistencia: Llistes!$AG$2:$AG$12
Name Prioritats: Llistes!$BQ$2:$BQ$6
Name Rel_Sistemes_Conjunts: 'Rel.Conjunts-Sistemes'!$C$9:$C$200
Name RelacióGlosari: Llistes!$BE$2:$BE$8
Name RelacionsConjuntsDades: 'Rel.Conjunts-Sistemes'!$B$9:$B$200
Name RelacionsConjuntsDades: 'Rel.Conjunts-Sistemes'!$B$9:$B$200
Name Retenció: Llistes!$AI$3:$AI$12
Name Reutilitzacio: Llistes!$BO$2:$BO$8
Name Seguretat: Llistes!$BK$2:$BK$7
Name SensibilitatDades: Llistes!$N$2:$N$8
Name SiNo: Llistes!$BV$2:$BV$3
Name SiNoParcialment: Llistes!$BV$2:$BV$4
Name Sistemes: Sistemes!$B$9:$B$66
Name TipusAtributs: Llistes!$AY$2:$AY$15
Name TipusConjunt: Llistes!$V$2:$V$7
Name TipusInformació: Llistes!$X$2:$X$12
Name TipusRelEntitats: Llistes!$BC$2:$BC$7
Name TipusServei: Llistes!$H$2:$H$7

Sheet Instruccions
B5: Instruccions
C8: La plantilla de l'inventari d'actius de dades s'organitza en les pestanyes següents:
D10: Sistemes: Registre i descripció dels sistemes d'informació de l'ens local vinculats a les dades.
D11: Dominis de dades: Recull els dominis de dades més habituals en un ens local. Per a cadascun cal completar la informació específica del domini. Es poden afegir dominis addicionals que no figurin a la proposta inicial.
D12: Conjunts de dades: Identificació, registre i descripció dels conjunts de dades associats a cada domini.
D13: Entitats: Identificació, registre i descripció de les entitats vinculades als conjunts de dades.
D14: Rel. Conjunts–Entitats: Documentació de les relacions entre conjunts de dades i entitats.
D15: Atributs: Registre i descripció dels atributs de cada entitat.
D16: Rel. Entitats–Entitats: Documentació de les relacions entre entitats.
D17: Qualitat: Avaluació de la completitud i la coherència de l'inventari.
D18: Llegenda: Instruccions per complimentar correctament totes les pestanyes.
D19: Relació inventaris: Fonts i referents tinguts en compte en el disseny de la plantilla.
D20: Llistes: Valors de referència vàlids per a les columnes amb valors restringits
C22: L'àmbit de suport en governança de dades municipal i el responsable de dades de l'ens local són els responsables de documentar, mantenir i gestionar l'inventari d'actius de dades.
C23: Dominis de dades. S'han agrupat en àmbits:
D25: Govern i administració: tot allò que té a veure amb la gestió administrativa.
D26: Gestió de l'espai públic: tot allò que te a veure amb la gestió de la ciutat (residus, clavegueram, informació geogràfica, etc.).
D27: Serveis a les persones: tot el que fa referència a serveis municipals.
D28: Corporatiu (dades mestres i de referència): Les dades de referència haurien de ser comunes a tot l'espai de dades

Sheet Sistemes
B5: Sistemes de dades
B7: =COUNTA(Sistemes) -> 40 | C7: =COUNTA(C$9:INDEX(C:C,$B7+8))/$B7 -> 0.5 | D7: =COUNTA(D$9:INDEX(D:D,$B7+8))/$B7 -> 0.625 | E7: =COUNTA(E$9:INDEX(E:E,$B7+8))/$B7 -> 0.975 | F7: =COUNTA(F$9:INDEX(F:F,$B7+8))/$B7 -> 0 | G7: =COUNTA(G$9:INDEX(G:G,$B7+8))/$B7 -> 0 | H7: =COUNTA(H$9:INDEX(H:H,$B7+8))/$B7 -> 0 | I7: =COUNTA(I$9:INDEX(I:I,$B7+8))/$B7 -> 0 | J7: =COUNTA(J$9:INDEX(J:J,$B7+8))/$B7 -> 0 | K7: =COUNTA(K$9:INDEX(K:K,$B7+8))/$B7 -> 0 | L7: =COUNTA(L$9:INDEX(L:L,$B7+8))/$B7 -> 0 | M7: =COUNTA(M$9:INDEX(M:M,$B7+8))/$B7 -> 0 | N7: =COUNTA(N$9:INDEX(N:N,$B7+8))/$B7 -> 0
B8: Sistema de dades | C8: Descripció | D8: Tecnologies principals | E8: Proveïdor | F8: Tipus de servei | G8: Arquitectura cloud | H8: Estat Sistema | I8: Data revisió estat | J8: Administrador del sistema (nom) | K8: Administrador del sistema (rol) | L8: Criticitat | M8: Integracions | N8: Model d’autenticació | O8: Núm. Conjunts de dades
B9: Padró municipal d’habitants | C9: Padró municipal d’habitants | D9: PMH - Berger levrault | E9: Diputació | O9: =IF(B9="","",COUNTIF('Rel.Conjunts-Sistemes'!$C:$C,$B9)) -> 0
B10: Enquesta retributiva per a ús municipal | C10: ERET Enquesta retributiva per a ús municipal | D10: Desenvolupament propi | E10: Diputació | O10: =IF(B10="","",COUNTIF('Rel.Conjunts-Sistemes'!$C:$C,$B10)) -> 0
B11: Tramitació d’expedients administratius | C11: SeTDIBA Registre i tramitació d’expedients als ajuntaments. | D11: Gestiona | E11: Diputació | O11: =IF(B11="","",COUNTIF('Rel.Conjunts-Sistemes'!$C:$C,$B11)) -> 0
B12: Registre d'entrada i sortida | C12: SeTDIBA-SECRETARIA Aplicació per gestionar els òrgans col·legiats | D12: Gestiona | E12: Diputació | O12: =IF(B12="","",COUNTIF('Rel.Conjunts-Sistemes'!$C:$C,$B12)) -> 0
B13: Registre d'analítiques de la qualitat de l’aigua | C13: ORALIMS Anàlisi de la qualitat de l’aigua | D13: ORACLE | E13: Diputació | O13: =IF(B13="","",COUNTIF('Rel.Conjunts-Sistemes'!$C:$C,$B13)) -> 1
B14: Gestió de nòmines municipals | C14: EPSILON Gestió de nòmines municipals | D14: EPSILOM | E14: Diputació | O14: =IF(B14="","",COUNTIF('Rel.Conjunts-Sistemes'!$C:$C,$B14)) -> 0
B15: Registre d'activitats econòmiques (GIA) | C15: GIA Expedients d’activitats econòmiques | D15: GIA - desenvolupament propi | E15: Diputació | O15: =IF(B15="","",COUNTIF('Rel.Conjunts-Sistemes'!$C:$C,$B15)) -> 1
B16: Gestió dels plans de protecció civil municipal | C16: PCOM Gestió dels plans de protecció civil municipal | D16: PCOM - desenvolupament propi | E16: Diputació | O16: =IF(B16="","",COUNTIF('Rel.Conjunts-Sistemes'!$C:$C,$B16)) -> 0
B17: Repositori imatges arxius municipals (IMAGINA ) | C17: IMAGINA Repositori imatges arxius municipals | D17: IMAGINA - desenvolupament propi | E17: Diputació | O17: =IF(B17="","",COUNTIF('Rel.Conjunts-Sistemes'!$C:$C,$B17)) -> 0
B18: Sistema per a la gestió de serveis locals d’ocupació (XALOC) | C18: XALOC Serveis locals d’ocupació | D18: XALOC - desenvolupament propi | E18: Diputació | O18: =IF(B18="","",COUNTIF('Rel.Conjunts-Sistemes'!$C:$C,$B18)) -> 3
B19: Comptabilitat municipal | C19: SICALWIN Comptabilitat per als ajuntaments | D19: SICALWIN - Berger Levrault | E19: Diputació | O19: =IF(B19="","",COUNTIF('Rel.Conjunts-Sistemes'!$C:$C,$B19)) -> 0
B20: Gestió de subvencions | C20: ACCEDE-SUB Subvencions | D20: ACCEDE-SUB - Berger Levrault | E20: Diputació | O20: =IF(B20="","",COUNTIF('Rel.Conjunts-Sistemes'!$C:$C,$B20)) -> 0
... B26: Sistema de gestió de les auditories pobresa energètica | C26: SIAPE Auditories pobresa energètica | D26: SIAPE - desenvolupament propi | E26: Diputació | O26: =IF(B26="","",COUNTIF('Rel.Conjunts-Sistemes'!$C:$C,$B26)) -> 0
B27: Portal de transparència municipal | E27: Consorci AOC | O27: =IF(B27="","",COUNTIF('Rel.Conjunts-Sistemes'!$C:$C,$B27)) -> 0
B28: Portal de dades obertes municipal | D28: CKAN | E28: Consorci AOC | O28: =IF(B28="","",COUNTIF('Rel.Conjunts-Sistemes'!$C:$C,$B28)) -> 0
B29: Catàleg de tràmits i eina de tramitació digital | D29: Gestiona | E29: Diputació | O29: =IF(B29="","",COUNTIF('Rel.Conjunts-Sistemes'!$C:$C,$B29)) -> 0
B30: Seu electrònica | E30: Consorci AOC | O30: =IF(B30="","",COUNTIF('Rel.Conjunts-Sistemes'!$C:$C,$B30)) -> 0
B31: Gestió de serveis bibliotecaris | C31: SIERRA - eina de gestió de serveis bibliotecaris | D31: SIERRA - desenvolupament propi | E31: Diputació | O31: =IF(B31="","",COUNTIF('Rel.Conjunts-Sistemes'!$C:$C,$B31)) -> 0
B32: GIAM | C32: Gestió de fons de l'arxiu municipal | D32: Base de dades Access | E32: Diputació | O32: =IF(B32="","",COUNTIF('Rel.Conjunts-Sistemes'!$C:$C,$B32)) -> 0
B33: Gestió de cementiris | E33: Ajuntament | O33: =IF(B33="","",COUNTIF('Rel.Conjunts-Sistemes'!$C:$C,$B33)) -> 0
B34: Gestió de queixes i suggeriments | E34: Ajuntament | O34: =IF(B34="","",COUNTIF('Rel.Conjunts-Sistemes'!$C:$C,$B34)) -> 0
B35: Gestió de representacions | D35: Representa | E35: Consorci AOC | O35: =IF(B35="","",COUNTIF('Rel.Conjunts-Sistemes'!$C:$C,$B35)) -> 0
B36: Sistema de cita prèvia | E36: Ajuntament | O36: =IF(B36="","",COUNTIF('Rel.Conjunts-Sistemes'!$C:$C,$B36)) -> 0
B37: Sistema de gestió d'impostos municipals | D37: ORGT | E37: Ajuntament | O37: =IF(B37="","",COUNTIF('Rel.Conjunts-Sistemes'!$C:$C,$B37)) -> 0
B38: Sistema de gestió de personal | E38: Ajuntament | O38: =IF(B38="","",COUNTIF('Rel.Conjunts-Sistemes'!$C:$C,$B38)) -> 0
B39: Control horari | E39: Ajuntament | O39: =IF(B39="","",COUNTIF('Rel.Conjunts-Sistemes'!$C:$C,$B39)) -> 0
B40: Gestió d'incidències a la via pública i manteniment d'equipaments | E40: Ajuntament | O40: =IF(B40="","",COUNTIF('Rel.Conjunts-Sistemes'!$C:$C,$B40)) -> 0
B41: Gestió de residus | E41: Ajuntament | O41: =IF(B41="","",COUNTIF('Rel.Conjunts-Sistemes'!$C:$C,$B41)) -> 0
B42: Gestió policial d'atestats | E42: Ajuntament | O42: =IF(B42="","",COUNTIF('Rel.Conjunts-Sistemes'!$C:$C,$B42)) -> 0
B43: Gestió dels sistemes de videovigilància | E43: Ajuntament | O43: =IF(B43="","",COUNTIF('Rel.Conjunts-Sistemes'!$C:$C,$B43)) -> 0
B44: Gestió de sancions | E44: Ajuntament | O44: =IF(B44="","",COUNTIF('Rel.Conjunts-Sistemes'!$C:$C,$B44)) -> 0
B45: Gestió d'aparcaments | E45: Ajuntament | O45: =IF(B45="","",COUNTIF('Rel.Conjunts-Sistemes'!$C:$C,$B45)) -> 0
B46: Web municipal | E46: Diputació | O46: =IF(B46="","",COUNTIF('Rel.Conjunts-Sistemes'!$C:$C,$B46)) -> 0
B47: Eina de gestió de la participació | D47: Participa311 | E47: Diputació | O47: =IF(B47="","",COUNTIF('Rel.Conjunts-Sistemes'!$C:$C,$B47)) -> 0
B48: Plataforma de gestió d'informació de sensors | O48: =IF(B48="","",COUNTIF('Rel.Conjunts-Sistemes'!$C:$C,$B48)) -> 0
O49: =IF(B49="","",COUNTIF('Rel.Conjunts-Sistemes'!$C:$C,$B49))
O50: =IF(B50="","",COUNTIF('Rel.Conjunts-Sistemes'!$C:$C,$B50))
...

Sheet Dominis de dades
B5: Dominis de dades
B6: =COUNTA(Dominis) -> 36 | C6: =COUNTA(C$8:INDEX(C:C,$B6+7))/$B6 -> 0.97222222 | D6: =COUNTA(D$8:INDEX(D:D,$B6+7))/$B6 -> 0.97222222 | E6: =COUNTA(E$8:INDEX(E:E,$B6+7))/$B6 -> 0.97222222
B7: Domini de dades | C7: Descripció | D7: Àmbit | E7: Àrea propietària | F7: Núm. Conjunts de dades
B8: Patrimoni i actius municipals (nou) | C8: Inclou edificis, locals, solars, vehicles, equipaments, mobiliari urbà, punts enllumenat, inventari patrimonial, sensors, equip informàtic, llicències, etc. | D8: Corporatiu (Dades mestres i de referència) | E8: Obres i Manteniment | F8: =IF(B8="","",COUNTIF('Conjunts de dades'!$D:$D,$B8)) -> 11
B9: Padró i identitat ciutadana (antic Població) | C9: Inclou el padró, altes i baixes, canvis de domicili i certificats. És clau per a serveis municipals, estadística i finançament. Permet garantir adreces correctes i traçabilitat de moviments de veïns. | D9: Corporatiu (Dades mestres i de referència) | E9: Padró i Estadística | F9: =IF(B9="","",COUNTIF('Conjunts de dades'!$D:$D,$B9)) -> 1
B10: Dades de referència (comú a tot l'ecosistema de dades de país) | C10: Inclou codis, classificacions, declaració d'unitats administratives, països. Etc | D10: Corporatiu (Dades mestres i de referència) | E10: Padró i Estadística | F10: =IF(B10="","",COUNTIF('Conjunts de dades'!$D:$D,$B10)) -> 0
B11: Medi ambient | C11: Inclou controls de qualitat de l'aire i soroll, gestió d'espais naturals, permisos ambientals i seguiment de sancions. Permet planificar campanyes, gestionar denúncies i elaborar indicadors per a informes i transparència. | D11: Gestió de l'espai públic i serveis al territori | E11: Medi Ambient | F11: =IF(B11="","",COUNTIF('Conjunts de dades'!$D:$D,$B11)) -> 4
B12: Residus | C12: Inclou recollida, contenidors, rutes, incidències, inspeccions i dades de pes o volum. Ajuda a millorar el servei, controlar objectius de reciclatge i gestionar contractes i campanyes amb la ciutadania. | D12: Gestió de l'espai públic i serveis al territori | E12: Medi Ambient | F12: =IF(B12="","",COUNTIF('Conjunts de dades'!$D:$D,$B12)) -> 1
B13: Mobilitat i trànsit | C13: Recull regulació de trànsit, zones d'estacionament, sancions, incidències, aforaments i informació de transport. Ajuda a prendre decisions de circulació, millorar el servei i coordinar actuacions amb operadors i policia. | D13: Gestió de l'espai públic i serveis al territori | E13: Mobilitat | F13: =IF(B13="","",COUNTIF('Conjunts de dades'!$D:$D,$B13)) -> 6
B14: Obres públiques i manteniment | C14: Inventari de projectes d'obres municipals, plans de manteniment i afectacions a la via. Serveix per controlar terminis, pressupostos i coordinació amb serveis afectats, incloent empreses contractistes i permisos. | D14: Gestió de l'espai públic i serveis al territori | E14: Obres i Manteniment | F14: =IF(B14="","",COUNTIF('Conjunts de dades'!$D:$D,$B14)) -> 1
B15: Protecció civil i emergències | C15: Reuneix plans d'emergència, inventari de recursos, avisos, activacions i informes d'incidents. Ajuda a coordinar operatius, gestionar comunicacions amb altres cossos i conservar evidències per avaluar i millorar respostes. | D15: Gestió de l'espai públic i serveis al territori | E15: Protecció Civil | F15: =IF(B15="","",COUNTIF('Conjunts de dades'!$D:$D,$B15)) -> 2
B16: Aigua i sanejament | C16: Inclou dades d'abonats, comptadors, lectures, incidències de xarxa i actuacions de manteniment. Serveix per planificar reparacions, controlar el consum i coordinar les empreses concessionàries amb el servei municipal. | D16: Gestió de l'espai públic i serveis al territori | E16: Serveis Urbans | F16: =IF(B16="","",COUNTIF('Conjunts de dades'!$D:$D,$B16)) -> 2
B17: Consum energètic | C17: Conté informació de consums, avaries i ordres de treball. Ajuda a prioritzar reparacions, optimitzar energia i comprovar el compliment del contracte de manteniment. | D17: Gestió de l'espai públic i serveis al territori | E17: Serveis Urbans | F17: =IF(B17="","",COUNTIF('Conjunts de dades'!$D:$D,$B17)) -> 1
B18: Neteja viària | C18: Inclou rutes de neteja, planificació de torns, incidències, inspeccions i control de qualitat del servei. Permet fer seguiment del contracte, registrar queixes i ajustar recursos segons zones i esdeveniments. | D18: Gestió de l'espai públic i serveis al territori | E18: Serveis Urbans | F18: =IF(B18="","",COUNTIF('Conjunts de dades'!$D:$D,$B18)) -> 1
B19: Informació territorial i geoespacial | C19: Agrupa cartografia, carrers, adreces, parcel·les, equipaments i capes temàtiques. Serveix per suportar tràmits, planificació i consultes internes, i per compartir mapes amb altres organismes quan cal. | D19: Gestió de l'espai públic i serveis al territori | E19: Urbanisme | F19: =IF(B19="","",COUNTIF('Conjunts de dades'!$D:$D,$B19)) -> 4
... B42: Turisme i oci | C42: Inclou recursos turístics, agenda d'activitats, reserves de visites, consultes i estadístiques de demanda. Permet informar visitants, coordinar agents locals i avaluar l'impacte d'esdeveniments amb dades clares i comparables. | D42: Serveis a les persones | E42: Turisme | F42: =IF(B42="","",COUNTIF('Conjunts de dades'!$D:$D,$B42)) -> 2
B43: Un domini de dades és una classificació lògica que agrupa dades relacionades per un significat, tema o propòsit comú, independentment de l’aplicació
F44: =IF(B44="","",COUNTIF('Conjunts de dades'!$D:$D,$B44))
F45: =IF(B45="","",COUNTIF('Conjunts de dades'!$D:$D,$B45))
F46: =IF(B46="","",COUNTIF('Conjunts de dades'!$D:$D,$B46))
F47: =IF(B47="","",COUNTIF('Conjunts de dades'!$D:$D,$B47))
F48: =IF(B48="","",COUNTIF('Conjunts de dades'!$D:$D,$B48))
F49: =IF(B49="","",COUNTIF('Conjunts de dades'!$D:$D,$B49))
F50: =IF(B50="","",COUNTIF('Conjunts de dades'!$D:$D,$B50))
F51: =IF(B51="","",COUNTIF('Conjunts de dades'!$D:$D,$B51))
F52: =IF(B52="","",COUNTIF('Conjunts de dades'!$D:$D,$B52))
F53: =IF(B53="","",COUNTIF('Conjunts de dades'!$D:$D,$B53))
F54: =IF(B54="","",COUNTIF('Conjunts de dades'!$D:$D,$B54))
F55: =IF(B55="","",COUNTIF('Conjunts de dades'!$D:$D,$B55))
... F62: =IF(B62="","",COUNTIF('Conjunts de dades'!$D:$D,$B62))

Sheet Conjunts de dades
B5: Conjunts de dades
B6: =COUNTA(ConjuntsDades) -> 111 | C6: =COUNTA(C$9:INDEX(C:C,$B6+8))/$B6 -> 1 | D6: =COUNTA(D$9:INDEX(D:D,$B6+8))/$B6 -> 1 | E6: =COUNTA(E$9:INDEX(E:E,$B6+8))/$B6 -> 1 | F6: =COUNTA(F$9:INDEX(F:F,$B6+8))/$B6 -> 0.009009009 | G6: =COUNTA(G$9:INDEX(G:G,$B6+8))/$B6 -> 0.009009009 | H6: =COUNTA(H$9:INDEX(H:H,$B6+8))/$B6 -> 0 | I6: =COUNTA(I$9:INDEX(I:I,$B6+8))/$B6 -> 0 | J6: =COUNTA(J$9:INDEX(J:J,$B6+8))/$B6 -> 0 | K6: =COUNTA(K$9:INDEX(K:K,$B6+8))/$B6 -> 0 | L6: =COUNTA(L$9:INDEX(L:L,$B6+8))/$B6 -> 0 | M6: =COUNTA(M$9:INDEX(M:M,$B6+8))/$B6 -> 0 | N6: =COUNTA(N$9:INDEX(N:N,$B6+8))/$B6 -> 0 | O6: =COUNTA(O$9:INDEX(O:O,$B6+8))/$B6 -> 0 | P6: =COUNTA(P$9:INDEX(P:P,$B6+8))/$B6 -> 0 | Q6: =COUNTA(Q$9:INDEX(Q:Q,$B6+8))/$B6 -> 0 | R6: =COUNTA(R$9:INDEX(R:R,$B6+8))/$B6 -> 0 | S6: =COUNTA(S$9:INDEX(S:S,$B6+8))/$B6 -> 0 | T6: =COUNTA(T$9:INDEX(T:T,$B6+8))/$B6 -> 0 | U6: =COUNTA(U$9:INDEX(U:U,$B6+8))/$B6 -> 0 | V6: =COUNTA(V$9:INDEX(V:V,$B6+8))/$B6 -> 0 | W6: =COUNTA(W$9:INDEX(W:W,$B6+8))/$B6 -> 0 | X6: =COUNTA(X$9:INDEX(X:X,$B6+8))/$B6 -> 0 | Y6: =COUNTA(Y$9:INDEX(Y:Y,$B6+8))/$B6 -> 0 | Z6: =COUNTA(Z$9:INDEX(Z:Z,$B6+8))/$B6 -> 0 | AA6: =COUNTA(AA$9:INDEX(AA:AA,$B6+8))/$B6 -> 0 | AB6: =COUNTA(AB$9:INDEX(AB:AB,$B6+8))/$B6 -> 0 | AC6: =COUNTA(AC$9:INDEX(AC:AC,$B6+8))/$B6 -> 0.009009009 | AD6: =COUNTA(AD$9:INDEX(AD:AD,$B6+8))/$B6 -> 0.009009009 | AE6: =COUNTA(AE$9:INDEX(AE:AE,$B6+8))/$B6 -> 0.009009009 | AF6: =COUNTA(AF$9:INDEX(AF:AF,$B6+8))/$B6 -> 0.009009009 | AG6: =COUNTA(AG$9:INDEX(AG:AG,$B6+8))/$B6 -> 0.009009009 | AH6: =COUNTA(AH$9:INDEX(AH:AH,$B6+8))/$B6 -> 0.009009009 | AI6: =COUNTA(AI$9:INDEX(AI:AI,$B6+8))/$B6 -> 0.009009009 | AJ6: =COUNTA(AJ$9:INDEX(AJ:AJ,$B6+8))/$B6 -> 0.009009009 | AK6: =COUNTA(AK$9:INDEX(AK:AK,$B6+8))/$B6 -> 0.009009009 | AL6: =COUNTA(AL$9:INDEX(AL:AL,$B6+8))/$B6 -> 0.009009009 | AM6: =COUNTA(AM$9:INDEX(AM:AM,$B6+8))/$B6 -> 0.009009009 | AN6: =COUNTA(AN$9:INDEX(AN:AN,$B6+8))/$B6 -> 0.009009009 | AO6: =COUNTA(AO$9:INDEX(AO:AO,$B6+8))/$B6 -> 0.009009009
H7: Sensibilitat de les dades | O7: Rols i responsabilitats | AC7: Riscos associats
B8: Nom Conjunt de dades | C8: Descripció | D8: Domini de dades | E8: Àrea propietària (Calculat pel Domini) | F8: Tipus conjunt de dades | G8: Ús previst de les dades | H8: Conté dades personals? | I8: Conté dades de gènere u orientació sexual? | J8: Conté dades d'ideologia o creences? | K8: Conté dades biomètriques? | L8: Conté dades de salut? | M8: Conté dades confidencials de l'ens local? | N8: Conté dades de seguretat i accés? | O8: Nom del responsable del Conjunt de dades (Propietari de dades) | P8: Càrrec del responsable del conjunt de dades | Q8: Nom del gestor del Conjunt de dades | R8: Càrrec del gestor del conjunt de dades | S8: Nom del custodi del Conjunt de dades | T8: Càrrec del custodi del conjunt de dades | U8: Categoria de les dades d'alt valor | V8: Cadència d'actualització | W8: Origen de les dades | X8: Persistència | Y8: Retenció | Z8: Disponibilitat històrica | AA8: Restriccions dades obertes | AB8: Reutilització de dades | AC8: Incoherència de dades | AD8: Informació desactualitzada | AE8: Publicació d'informació incorrecta | AF8: Registres duplicats | AG8: Accés a dades sensibles | AH8: Accés o ús indegut | AI8: Exposició de dades (menors, personals, sensibles o socials) | AJ8: Filtració o fuita de dades | AK8: Indisponiblitat del sistema | AL8: Pèrdua de dades | AM8: Falta de traçabilitat i evidències sobre la gestió de les dades | AN8: Falta de seguiment o auditories sobre accessos i usos | AO8: Falta de pla de resposta a incidents | AP8: Nivell de risc general | AQ8: Observacions | AR8: Núm. Sistemes d'informació | AS8: Núm. Dominis de dades
B9: Sol·licitants d'ocupació del servei local d'ocupació | C9: Registre anonimitzat del perfil sociodemogràfic dels demandants d'ocupació (edat, gènere, nivell d'estudis, sector professional, temps en atur). | D9: Formació i ocupació | E9: =IF(D9="","-",IF(ISERROR(VLOOKUP(D9,DominisDades,3,0)),"<<Domini erroni>>",VLOOKUP(D9,DominisDades,3,0))) -> Serveis a les persones | F9: Dades de referència / mestres no homogeneïtzades | G9: Intern transversal | AC9: Probabilitat: Baixa Impacte: Alt (2) | AD9: Probabilitat: Baixa Impacte: Moderat (1) | AE9: Probabilitat: Mitja Impacte: Baix (1) | AF9: Probabilitat: Mitja Impacte: Baix (1) | AG9: Probabilitat: Alta Impacte: Moderat (4) | AH9: Probabilitat: Mitja Impacte: Alt (4) | AI9: Probabilitat: Baixa Impacte: Alt (2) | AJ9: Probabilitat: Mitja Impacte: Alt (4) | AK9: Probabilitat: Mitja Impacte: Alt (4) | AL9: Probabilitat: Baixa Impacte: Alt (2) | AM9: Probabilitat: Baixa Impacte: Moderat (1) | AN9: Probabilitat: Baixa Impacte: Baix (1) | AO9: Probabilitat: Alta Impacte: Baix (3) | AP9: =AVERAGE(SUMIF(AnàlisiRiscos,AC9,AnàlisiRiscosGrau),SUMIF(AnàlisiRiscos,AD9,AnàlisiRiscosGrau),SUMIF(AnàlisiRiscos,AE9,AnàlisiRiscosGrau),SUMIF(AnàlisiRiscos,AF9,AnàlisiRiscosGrau),SUMIF(AnàlisiRiscos,AG9,AnàlisiRiscosGrau),SUMIF(AnàlisiRiscos,AH9,AnàlisiRiscosGrau),SUMIF(AnàlisiRiscos,AI9,AnàlisiRiscosGrau),SUMIF(AnàlisiRiscos,AJ9,AnàlisiRiscosGrau),SUMIF(AnàlisiRiscos,AK9,AnàlisiRiscosGrau),SUMIF(AnàlisiRiscos,AL9,AnàlisiRiscosGrau),SUMIF(AnàlisiRiscos,AM9,AnàlisiRiscosGrau),SUMIF(AnàlisiRiscos,AN9,AnàlisiRiscosGrau),SUMIF(AnàlisiRiscos,AO9,AnàlisiRiscosGrau)) -> 2.3076923 | AR9: =IF(B9="","",COUNTIF('Rel.Conjunts-Sistemes'!$B:$B,$B9)) -> 1 | AS9: =IF(B9="","",COUNTIF('Dominis de dades'!$B:$B,$D9)) -> 1
B10: Ofertes de treball del servei local d'ocupació | C10: Detall de les ofertes gestionades (sector, tipus de contracte, requisits) i indicadors d'eficiència (temps mitjà per cobrir la vacant). | D10: Formació i ocupació | E10: =IF(D10="","-",IF(ISERROR(VLOOKUP(D10,DominisDades,3,0)),"<<Domini erroni>>",VLOOKUP(D10,DominisDades,3,0))) -> Serveis a les persones | AP10: =AVERAGE(SUMIF(AnàlisiRiscos,AC10,AnàlisiRiscosGrau),SUMIF(AnàlisiRiscos,AD10,AnàlisiRiscosGrau),SUMIF(AnàlisiRiscos,AE10,AnàlisiRiscosGrau),SUMIF(AnàlisiRiscos,AF10,AnàlisiRiscosGrau),SUMIF(AnàlisiRiscos,AG10,AnàlisiRiscosGrau),SUMIF(AnàlisiRiscos,AH10,AnàlisiRiscosGrau),SUMIF(AnàlisiRiscos,AI10,AnàlisiRiscosGrau),SUMIF(AnàlisiRiscos,AJ10,AnàlisiRiscosGrau),SUMIF(AnàlisiRiscos,AK10,AnàlisiRiscosGrau),SUMIF(AnàlisiRiscos,AL10,AnàlisiRiscosGrau),SUMIF(AnàlisiRiscos,AM10,AnàlisiRiscosGrau),SUMIF(AnàlisiRiscos,AN10,AnàlisiRiscosGrau),SUMIF(AnàlisiRiscos,AO10,AnàlisiRiscosGrau)) -> 0 | AR10: =IF(B10="","",COUNTIF('Rel.Conjunts-Sistemes'!$B:$B,$B10)) -> 1 | AS10: =IF(B10="","",COUNTIF('Dominis de dades'!$B:$B,$D10)) -> 1
B11: Cens de locals comercials buits | C11: Indicador econòmic i cens geolocalitzat dels establiments comercials sense activitat a peu de carrer, orientat a plans de dinamització comercial. | D11: Economia local, comerç i mercats | E11: =IF(D11="","-",IF(ISERROR(VLOOKUP(D11,DominisDades,3,0)),"<<Domini erroni>>",VLOOKUP(D11,DominisDades,3,0))) -> Serveis a les persones | AP11: =AVERAGE(SUMIF(AnàlisiRiscos,AC11,AnàlisiRiscosGrau),SUMIF(AnàlisiRiscos,AD11,AnàlisiRiscosGrau),SUMIF(AnàlisiRiscos,AE11,AnàlisiRiscosGrau),SUMIF(AnàlisiRiscos,AF11,AnàlisiRiscosGrau),SUMIF(AnàlisiRiscos,AG11,AnàlisiRiscosGrau),SUMIF(AnàlisiRiscos,AH11,AnàlisiRiscosGrau),SUMIF(AnàlisiRiscos,AI11,AnàlisiRiscosGrau),SUMIF(AnàlisiRiscos,AJ11,AnàlisiRiscosGrau),SUMIF(AnàlisiRiscos,AK11,AnàlisiRiscosGrau),SUMIF(AnàlisiRiscos,AL11,AnàlisiRiscosGrau),SUMIF(AnàlisiRiscos,AM11,AnàlisiRiscosGrau),SUMIF(AnàlisiRiscos,AN11,AnàlisiRiscosGrau),SUMIF(AnàlisiRiscos,AO11,AnàlisiRiscosGrau)) -> 0 | AR11: =IF(B11="","",COUNTIF('Rel.Conjunts-Sistemes'!$B:$B,$B11)) -> 1 | AS11: =IF(B11="","",COUNTIF('Dominis de dades'!$B:$B,$D11)) -> 1
B12: Cens d'empreses, comerços i establiments | C12: Registre d'activitats econòmiques de la ciutat actives a peu de carrer o en oficines, classificades per sector econòmic. | D12: Economia local, comerç i mercats | E12: =IF(D12="","-",IF(ISERROR(VLOOKUP(D12,DominisDades,3,0)),"<<Domini erroni>>",VLOOKUP(D12,DominisDades,3,0))) -> Serveis a les persones | AP12: =AVERAGE(SUMIF(AnàlisiRiscos,AC12,AnàlisiRiscosGrau),SUMIF(AnàlisiRiscos,AD12,AnàlisiRiscosGrau),SUMIF(AnàlisiRiscos,AE12,AnàlisiRiscosGrau),SUMIF(AnàlisiRiscos,AF12,AnàlisiRiscosGrau),SUMIF(AnàlisiRiscos,AG12,AnàlisiRiscosGrau),SUMIF(AnàlisiRiscos,AH12,AnàlisiRiscosGrau),SUMIF(AnàlisiRiscos,AI12,AnàlisiRiscosGrau),SUMIF(AnàlisiRiscos,AJ12,AnàlisiRiscosGrau),SUMIF(AnàlisiRiscos,AK12,AnàlisiRiscosGrau),SUMIF(AnàlisiRiscos,AL12,AnàlisiRiscosGrau),SUMIF(AnàlisiRiscos,AM12,AnàlisiRiscosGrau),SUMIF(AnàlisiRiscos,AN12,AnàlisiRiscosGrau),SUMIF(AnàlisiRiscos,AO12,AnàlisiRiscosGrau)) -> 0 | AR12: =IF(B12="","",COUNTIF('Rel.Conjunts-Sistemes'!$B:$B,$B12)) -> 1 | AS12: =IF(B12="","",COUNTIF('Dominis de dades'!$B:$B,$D12)) -> 1
B13: Polígons de l'activitat econòmica i industrial | C13: Delimitació geogràfica, parcel·lari, serveis disponibles i directori d'empreses ubicades a les zones industrials de la localitat. | D13: Economia local, comerç i mercats | E13: =IF(D13="","-",IF(ISERROR(VLOOKUP(D13,DominisDades,3,0)),"<<Domini erroni>>",VLOOKUP(D13,DominisDades,3,0))) -> Serveis a les persones | AP13: =AVERAGE(SUMIF(AnàlisiRiscos,AC13,AnàlisiRiscosGrau),SUMIF(AnàlisiRiscos,AD13,AnàlisiRiscosGrau),SUMIF(AnàlisiRiscos,AE13,AnàlisiRiscosGrau),SUMIF(AnàlisiRiscos,AF13,AnàlisiRiscosGrau),SUMIF(AnàlisiRiscos,AG13,AnàlisiRiscosGrau),SUMIF(AnàlisiRiscos,AH13,AnàlisiRiscosGrau),SUMIF(AnàlisiRiscos,AI13,AnàlisiRiscosGrau),SUMIF(AnàlisiRiscos,AJ13,AnàlisiRiscosGrau),SUMIF(AnàlisiRiscos,AK13,AnàlisiRiscosGrau),SUMIF(AnàlisiRiscos,AL13,AnàlisiRiscosGrau),SUMIF(AnàlisiRiscos,AM13,AnàlisiRiscosGrau),SUMIF(AnàlisiRiscos,AN13,AnàlisiRiscosGrau),SUMIF(AnàlisiRiscos,AO13,AnàlisiRiscosGrau)) -> 0 | AR13: =IF(B13="","",COUNTIF('Rel.Conjunts-Sistemes'!$B:$B,$B13)) -> 1 | AS13: =IF(B13="","",COUNTIF('Dominis de dades'!$B:$B,$D13)) -> 1
B14: Tramitació i expedients administratius | C14: Traçabilitat de la gestió interna: expedients oberts, procediment, sèrie documental, àrea responsable, terminis de resolució i estat actual. | D14: Secretaria | E14: =IF(D14="","-",IF(ISERROR(VLOOKUP(D14,DominisDades,3,0)),"<<Domini erroni>>",VLOOKUP(D14,DominisDades,3,0))) -> Govern i administració | AP14: =AVERAGE(SUMIF(AnàlisiRiscos,AC14,AnàlisiRiscosGrau),SUMIF(AnàlisiRiscos,AD14,AnàlisiRiscosGrau),SUMIF(AnàlisiRiscos,AE14,AnàlisiRiscosGrau),SUMIF(AnàlisiRiscos,AF14,AnàlisiRiscosGrau),SUMIF(AnàlisiRiscos,AG14,AnàlisiRiscosGrau),SUMIF(AnàlisiRiscos,AH14,AnàlisiRiscosGrau),SUMIF(AnàlisiRiscos,AI14,AnàlisiRiscosGrau),SUMIF(AnàlisiRiscos,AJ14,AnàlisiRiscosGrau),SUMIF(AnàlisiRiscos,AK14,AnàlisiRiscosGrau),SUMIF(AnàlisiRiscos,AL14,AnàlisiRiscosGrau),SUMIF(AnàlisiRiscos,AM14,AnàlisiRiscosGrau),SUMIF(AnàlisiRiscos,AN14,AnàlisiRiscosGrau),SUMIF(AnàlisiRiscos,AO14,AnàlisiRiscosGrau)) -> 0 | AR14: =IF(B14="","",COUNTIF('Rel.Conjunts-Sistemes'!$B:$B,$B14)) -> 1 | AS14: =IF(B14="","",COUNTIF('Dominis de dades'!$B:$B,$D14)) -> 1
B15: Registre general d'entrada i sortida de documents | C15: Flux de documents de la corporació (presencial i online) amb indicació del canal d'entrada/sortida, tipus de document i classificació. | D15: Activitat administrativa | E15: =IF(D15="","-",IF(ISERROR(VLOOKUP(D15,DominisDades,3,0)),"<<Domini erroni>>",VLOOKUP(D15,DominisDades,3,0))) -> Govern i administració | AP15: =AVERAGE(SUMIF(AnàlisiRiscos,AC15,AnàlisiRiscosGrau),SUMIF(AnàlisiRiscos,AD15,AnàlisiRiscosGrau),SUMIF(AnàlisiRiscos,AE15,AnàlisiRiscosGrau),SUMIF(AnàlisiRiscos,AF15,AnàlisiRiscosGrau),SUMIF(AnàlisiRiscos,AG15,AnàlisiRiscosGrau),SUMIF(AnàlisiRiscos,AH15,AnàlisiRiscosGrau),SUMIF(AnàlisiRiscos,AI15,AnàlisiRiscosGrau),SUMIF(AnàlisiRiscos,AJ15,AnàlisiRiscosGrau),SUMIF(AnàlisiRiscos,AK15,AnàlisiRiscosGrau),SUMIF(AnàlisiRiscos,AL15,AnàlisiRiscosGrau),SUMIF(AnàlisiRiscos,AM15,AnàlisiRiscosGrau),SUMIF(AnàlisiRiscos,AN15,AnàlisiRiscosGrau),SUMIF(AnàlisiRiscos,AO15,AnàlisiRiscosGrau)) -> 0 | AR15: =IF(B15="","",COUNTIF('Rel.Conjunts-Sistemes'!$B:$B,$B15)) -> 1 | AS15: =IF(B15="","",COUNTIF('Dominis de dades'!$B:$B,$D15)) -> 1
B16: Registre municipal de convenis i acords institucionals | C16: Llistat i detall de convenis signats per l'Ajuntament amb altres administracions, entitats del tercer sector o empreses. | D16: Secretaria | E16: =IF(D16="","-",IF(ISERROR(VLOOKUP(D16,DominisDades,3,0)),"<<Domini erroni>>",VLOOKUP(D16,DominisDades,3,0))) -> Govern i administració | AP16: =AVERAGE(SUMIF(AnàlisiRiscos,AC16,AnàlisiRiscosGrau),SUMIF(AnàlisiRiscos,AD16,AnàlisiRiscosGrau),SUMIF(AnàlisiRiscos,AE16,AnàlisiRiscosGrau),SUMIF(AnàlisiRiscos,AF16,AnàlisiRiscosGrau),SUMIF(AnàlisiRiscos,AG16,AnàlisiRiscosGrau),SUMIF(AnàlisiRiscos,AH16,AnàlisiRiscosGrau),SUMIF(AnàlisiRiscos,AI16,AnàlisiRiscosGrau),SUMIF(AnàlisiRiscos,AJ16,AnàlisiRiscosGrau),SUMIF(AnàlisiRiscos,AK16,AnàlisiRiscosGrau),SUMIF(AnàlisiRiscos,AL16,AnàlisiRiscosGrau),SUMIF(AnàlisiRiscos,AM16,AnàlisiRiscosGrau),SUMIF(AnàlisiRiscos,AN16,AnàlisiRiscosGrau),SUMIF(AnàlisiRiscos,AO16,AnàlisiRiscosGrau)) -> 0 | AR16: =IF(B16="","",COUNTIF('Rel.Conjunts-Sistemes'!$B:$B,$B16)) -> 1 | AS16: =IF(B16="","",COUNTIF('Dominis de dades'!$B:$B,$D16)) -> 1
B17: Taulell d'anuncis i edictes oficials | C17: Registre de les publicacions obligatòries, ordenances aprovades, anuncis de licitació i notificacions exposades al tauler digital. | D17: Secretaria | E17: =IF(D17="","-",IF(ISERROR(VLOOKUP(D17,DominisDades,3,0)),"<<Domini erroni>>",VLOOKUP(D17,DominisDades,3,0))) -> Govern i administració | AP17: =AVERAGE(SUMIF(AnàlisiRiscos,AC17,AnàlisiRiscosGrau),SUMIF(AnàlisiRiscos,AD17,AnàlisiRiscosGrau),SUMIF(AnàlisiRiscos,AE17,AnàlisiRiscosGrau),SUMIF(AnàlisiRiscos,AF17,AnàlisiRiscosGrau),SUMIF(AnàlisiRiscos,AG17,AnàlisiRiscosGrau),SUMIF(AnàlisiRiscos,AH17,AnàlisiRiscosGrau),SUMIF(AnàlisiRiscos,AI17,AnàlisiRiscosGrau),SUMIF(AnàlisiRiscos,AJ17,AnàlisiRiscosGrau),SUMIF(AnàlisiRiscos,AK17,AnàlisiRiscosGrau),SUMIF(AnàlisiRiscos,AL17,AnàlisiRiscosGrau),SUMIF(AnàlisiRiscos,AM17,AnàlisiRiscosGrau),SUMIF(AnàlisiRiscos,AN17,AnàlisiRiscosGrau),SUMIF(AnàlisiRiscos,AO17,AnàlisiRiscosGrau)) -> 0 | AR17: =IF(B17="","",COUNTIF('Rel.Conjunts-Sistemes'!$B:$B,$B17)) -> 1 | AS17: =IF(B17="","",COUNTIF('Dominis de dades'!$B:$B,$D17)) -> 1
B18: Quadre de classificació documental | C18: Estructura jeràrquica de referència utilitzada per a l'organització, codificació i emmagatzematgede la informació dins de l'organització. | D18: Secretaria | E18: =IF(D18="","-",IF(ISERROR(VLOOKUP(D18,DominisDades,3,0)),"<<Domini erroni>>",VLOOKUP(D18,DominisDades,3,0))) -> Govern i administració | AP18: =AVERAGE(SUMIF(AnàlisiRiscos,AC18,AnàlisiRiscosGrau),SUMIF(AnàlisiRiscos,AD18,AnàlisiRiscosGrau),SUMIF(AnàlisiRiscos,AE18,AnàlisiRiscosGrau),SUMIF(AnàlisiRiscos,AF18,AnàlisiRiscosGrau),SUMIF(AnàlisiRiscos,AG18,AnàlisiRiscosGrau),SUMIF(AnàlisiRiscos,AH18,AnàlisiRiscosGrau),SUMIF(AnàlisiRiscos,AI18,AnàlisiRiscosGrau),SUMIF(AnàlisiRiscos,AJ18,AnàlisiRiscosGrau),SUMIF(AnàlisiRiscos,AK18,AnàlisiRiscosGrau),SUMIF(AnàlisiRiscos,AL18,AnàlisiRiscosGrau),SUMIF(AnàlisiRiscos,AM18,AnàlisiRiscosGrau),SUMIF(AnàlisiRiscos,AN18,AnàlisiRiscosGrau),SUMIF(AnàlisiRiscos,AO18,AnàlisiRiscosGrau)) -> 0 | AR18: =IF(B18="","",COUNTIF('Rel.Conjunts-Sistemes'!$B:$B,$B18)) -> 1 | AS18: =IF(B18="","",COUNTIF('Dominis de dades'!$B:$B,$D18)) -> 1
B19: Resultats electorals per mesa i secció censal | C19: Resultats històrics d'eleccions (municipals, autonòmiques, generals) desglossats per partits, vots en blanc, nuls i abstenció per mesa. | D19: Secretaria | E19: =IF(D19="","-",IF(ISERROR(VLOOKUP(D19,DominisDades,3,0)),"<<Domini erroni>>",VLOOKUP(D19,DominisDades,3,0))) -> Govern i administració | AP19: =AVERAGE(SUMIF(AnàlisiRiscos,AC19,AnàlisiRiscosGrau),SUMIF(AnàlisiRiscos,AD19,AnàlisiRiscosGrau),SUMIF(AnàlisiRiscos,AE19,AnàlisiRiscosGrau),SUMIF(AnàlisiRiscos,AF19,AnàlisiRiscosGrau),SUMIF(AnàlisiRiscos,AG19,AnàlisiRiscosGrau),SUMIF(AnàlisiRiscos,AH19,AnàlisiRiscosGrau),SUMIF(AnàlisiRiscos,AI19,AnàlisiRiscosGrau),SUMIF(AnàlisiRiscos,AJ19,AnàlisiRiscosGrau),SUMIF(AnàlisiRiscos,AK19,AnàlisiRiscosGrau),SUMIF(AnàlisiRiscos,AL19,AnàlisiRiscosGrau),SUMIF(AnàlisiRiscos,AM19,AnàlisiRiscosGrau),SUMIF(AnàlisiRiscos,AN19,AnàlisiRiscosGrau),SUMIF(AnàlisiRiscos,AO19,AnàlisiRiscosGrau)) -> 0 | AR19: =IF(B19="","",COUNTIF('Rel.Conjunts-Sistemes'!$B:$B,$B19)) -> 1 | AS19: =IF(B19="","",COUNTIF('Dominis de dades'!$B:$B,$D19)) -> 1
B20: Registre municipal de parelles de fet | C20: Llistat històric i vigent de les inscripcions d'unions civils no matrimonials formalitzades a l'ajuntament. | D20: Secretaria | E20: =IF(D20="","-",IF(ISERROR(VLOOKUP(D20,DominisDades,3,0)),"<<Domini erroni>>",VLOOKUP(D20,DominisDades,3,0))) -> Govern i administració | AP20: =AVERAGE(SUMIF(AnàlisiRiscos,AC20,AnàlisiRiscosGrau),SUMIF(AnàlisiRiscos,AD20,AnàlisiRiscosGrau),SUMIF(AnàlisiRiscos,AE20,AnàlisiRiscosGrau),SUMIF(AnàlisiRiscos,AF20,AnàlisiRiscosGrau),SUMIF(AnàlisiRiscos,AG20,AnàlisiRiscosGrau),SUMIF(AnàlisiRiscos,AH20,AnàlisiRiscosGrau),SUMIF(AnàlisiRiscos,AI20,AnàlisiRiscosGrau),SUMIF(AnàlisiRiscos,AJ20,AnàlisiRiscosGrau),SUMIF(AnàlisiRiscos,AK20,AnàlisiRiscosGrau),SUMIF(AnàlisiRiscos,AL20,AnàlisiRiscosGrau),SUMIF(AnàlisiRiscos,AM20,AnàlisiRiscosGrau),SUMIF(AnàlisiRiscos,AN20,AnàlisiRiscosGrau),SUMIF(AnàlisiRiscos,AO20,AnàlisiRiscosGrau)) -> 0 | AR20: =IF(B20="","",COUNTIF('Rel.Conjunts-Sistemes'!$B:$B,$B20)) -> 1 | AS20: =IF(B20="","",COUNTIF('Dominis de dades'!$B:$B,$D20)) -> 1
B21: Subvencions i ajuts atorgats | C21: Registre oficial de subvencions concedides a entitats i ciutadans, estructurat segons els camps de la Base de Dades Nacional de Subvencions (BDNS). | D21: Contractació, convenis i subvencions | E21: =IF(D21="","-",IF(ISERROR(VLOOKUP(D21,DominisDades,3,0)),"<<Domini erroni>>",VLOOKUP(D21,DominisDades,3,0))) -> Govern i administració | AP21: =AVERAGE(SUMIF(AnàlisiRiscos,AC21,AnàlisiRiscosGrau),SUMIF(AnàlisiRiscos,AD21,AnàlisiRiscosGrau),SUMIF(AnàlisiRiscos,AE21,AnàlisiRiscosGrau),SUMIF(AnàlisiRiscos,AF21,AnàlisiRiscosGrau),SUMIF(AnàlisiRiscos,AG21,AnàlisiRiscosGrau),SUMIF(AnàlisiRiscos,AH21,AnàlisiRiscosGrau),SUMIF(AnàlisiRiscos,AI21,AnàlisiRiscosGrau),SUMIF(AnàlisiRiscos,AJ21,AnàlisiRiscosGrau),SUMIF(AnàlisiRiscos,AK21,AnàlisiRiscosGrau),SUMIF(AnàlisiRiscos,AL21,AnàlisiRiscosGrau),SUMIF(AnàlisiRiscos,AM21,AnàlisiRiscosGrau),SUMIF(AnàlisiRiscos,AN21,AnàlisiRiscosGrau),SUMIF(AnàlisiRiscos,AO21,AnàlisiRiscosGrau)) -> 0 | AR21: =IF(B21="","",COUNTIF('Rel.Conjunts-Sistemes'!$B:$B,$B21)) -> 1 | AS21: =IF(B21="","",COUNTIF('Dominis de dades'!$B:$B,$D21)) -> 1
... B119: Tramitació administrativa | C119: Conjunt de dades amb el detall dels expedients administratius, el seu estat, tipus d'interessat, sèrie documental, temps de resolució entre d'altres | D119: Activitat administrativa | E119: =IF(D119="","-",IF(ISERROR(VLOOKUP(D119,DominisDades,3,0)),"<<Domini erroni>>",VLOOKUP(D119,DominisDades,3,0))) -> Govern i administració | AP119: =AVERAGE(SUMIF(AnàlisiRiscos,AC119,AnàlisiRiscosGrau),SUMIF(AnàlisiRiscos,AD119,AnàlisiRiscosGrau),SUMIF(AnàlisiRiscos,AE119,AnàlisiRiscosGrau),SUMIF(AnàlisiRiscos,AF119,AnàlisiRiscosGrau),SUMIF(AnàlisiRiscos,AG119,AnàlisiRiscosGrau),SUMIF(AnàlisiRiscos,AH119,AnàlisiRiscosGrau),SUMIF(AnàlisiRiscos,AI119,AnàlisiRiscosGrau),SUMIF(AnàlisiRiscos,AJ119,AnàlisiRiscosGrau),SUMIF(AnàlisiRiscos,AK119,AnàlisiRiscosGrau),SUMIF(AnàlisiRiscos,AL119,AnàlisiRiscosGrau),SUMIF(AnàlisiRiscos,AM119,AnàlisiRiscosGrau),SUMIF(AnàlisiRiscos,AN119,AnàlisiRiscosGrau),SUMIF(AnàlisiRiscos,AO119,AnàlisiRiscosGrau)) -> 0 | AR119: =IF(B119="","",COUNTIF('Rel.Conjunts-Sistemes'!$B:$B,$B119)) -> 0 | AS119: =IF(B119="","",COUNTIF('Dominis de dades'!$B:$B,$D119)) -> 1
E120: =IF(D120="","-",IF(ISERROR(VLOOKUP(D120,DominisDades,3,0)),"<<Domini erroni>>",VLOOKUP(D120,DominisDades,3,0))) -> - | AP120: =AVERAGE(SUMIF(AnàlisiRiscos,AC120,AnàlisiRiscosGrau),SUMIF(AnàlisiRiscos,AD120,AnàlisiRiscosGrau),SUMIF(AnàlisiRiscos,AE120,AnàlisiRiscosGrau),SUMIF(AnàlisiRiscos,AF120,AnàlisiRiscosGrau),SUMIF(AnàlisiRiscos,AG120,AnàlisiRiscosGrau),SUMIF(AnàlisiRiscos,AH120,AnàlisiRiscosGrau),SUMIF(AnàlisiRiscos,AI120,AnàlisiRiscosGrau),SUMIF(AnàlisiRiscos,AJ120,AnàlisiRiscosGrau),SUMIF(AnàlisiRiscos,AK120,AnàlisiRiscosGrau),SUMIF(AnàlisiRiscos,AL120,AnàlisiRiscosGrau),SUMIF(AnàlisiRiscos,AM120,AnàlisiRiscosGrau),SUMIF(AnàlisiRiscos,AN120,AnàlisiRiscosGrau),SUMIF(AnàlisiRiscos,AO120,AnàlisiRiscosGrau)) -> 0 | AR120: =IF(B120="","",COUNTIF('Rel.Conjunts-Sistemes'!$B:$B,$B120)) | AS120: =IF(B120="","",COUNTIF('Dominis de dades'!$B:$B,$D120))
E121: =IF(D121="","-",IF(ISERROR(VLOOKUP(D121,DominisDades,3,0)),"<<Domini erroni>>",VLOOKUP(D121,DominisDades,3,0))) -> - | AP121: =AVERAGE(SUMIF(AnàlisiRiscos,AC121,AnàlisiRiscosGrau),SUMIF(AnàlisiRiscos,AD121,AnàlisiRiscosGrau),SUMIF(AnàlisiRiscos,AE121,AnàlisiRiscosGrau),SUMIF(AnàlisiRiscos,AF121,AnàlisiRiscosGrau),SUMIF(AnàlisiRiscos,AG121,AnàlisiRiscosGrau),SUMIF(AnàlisiRiscos,AH121,AnàlisiRiscosGrau),SUMIF(AnàlisiRiscos,AI121,AnàlisiRiscosGrau),SUMIF(AnàlisiRiscos,AJ121,AnàlisiRiscosGrau),SUMIF(AnàlisiRiscos,AK121,AnàlisiRiscosGrau),SUMIF(AnàlisiRiscos,AL121,AnàlisiRiscosGrau),SUMIF(AnàlisiRiscos,AM121,AnàlisiRiscosGrau),SUMIF(AnàlisiRiscos,AN121,AnàlisiRiscosGrau),SUMIF(AnàlisiRiscos,AO121,AnàlisiRiscosGrau)) -> 0 | AR121: =IF(B121="","",COUNTIF('Rel.Conjunts-Sistemes'!$B:$B,$B121)) | AS121: =IF(B121="","",COUNTIF('Dominis de dades'!$B:$B,$D121))
E122: =IF(D122="","-",IF(ISERROR(VLOOKUP(D122,DominisDades,3,0)),"<<Domini erroni>>",VLOOKUP(D122,DominisDades,3,0))) -> - | AP122: =AVERAGE(SUMIF(AnàlisiRiscos,AC122,AnàlisiRiscosGrau),SUMIF(AnàlisiRiscos,AD122,AnàlisiRiscosGrau),SUMIF(AnàlisiRiscos,AE122,AnàlisiRiscosGrau),SUMIF(AnàlisiRiscos,AF122,AnàlisiRiscosGrau),SUMIF(AnàlisiRiscos,AG122,AnàlisiRiscosGrau),SUMIF(AnàlisiRiscos,AH122,AnàlisiRiscosGrau),SUMIF(AnàlisiRiscos,AI122,AnàlisiRiscosGrau),SUMIF(AnàlisiRiscos,AJ122,AnàlisiRiscosGrau),SUMIF(AnàlisiRiscos,AK122,AnàlisiRiscosGrau),SUMIF(AnàlisiRiscos,AL122,AnàlisiRiscosGrau),SUMIF(AnàlisiRiscos,AM122,AnàlisiRiscosGrau),SUMIF(AnàlisiRiscos,AN122,AnàlisiRiscosGrau),SUMIF(AnàlisiRiscos,AO122,AnàlisiRiscosGrau)) -> 0 | AR122: =IF(B122="","",COUNTIF('Rel.Conjunts-Sistemes'!$B:$B,$B122)) | AS122: =IF(B122="","",COUNTIF('Dominis de dades'!$B:$B,$D122))
E123: =IF(D123="","-",IF(ISERROR(VLOOKUP(D123,DominisDades,3,0)),"<<Domini erroni>>",VLOOKUP(D123,DominisDades,3,0))) -> - | AP123: =AVERAGE(SUMIF(AnàlisiRiscos,AC123,AnàlisiRiscosGrau),SUMIF(AnàlisiRiscos,AD123,AnàlisiRiscosGrau),SUMIF(AnàlisiRiscos,AE123,AnàlisiRiscosGrau),SUMIF(AnàlisiRiscos,AF123,AnàlisiRiscosGrau),SUMIF(AnàlisiRiscos,AG123,AnàlisiRiscosGrau),SUMIF(AnàlisiRiscos,AH123,AnàlisiRiscosGrau),SUMIF(AnàlisiRiscos,AI123,AnàlisiRiscosGrau),SUMIF(AnàlisiRiscos,AJ123,AnàlisiRiscosGrau),SUMIF(AnàlisiRiscos,AK123,AnàlisiRiscosGrau),SUMIF(AnàlisiRiscos,AL123,AnàlisiRiscosGrau),SUMIF(AnàlisiRiscos,AM123,AnàlisiRiscosGrau),SUMIF(AnàlisiRiscos,AN123,AnàlisiRiscosGrau),SUMIF(AnàlisiRiscos,AO123,AnàlisiRiscosGrau)) -> 0 | AR123: =IF(B123="","",COUNTIF('Rel.Conjunts-Sistemes'!$B:$B,$B123)) | AS123: =IF(B123="","",COUNTIF('Dominis de dades'!$B:$B,$D123))
E124: =IF(D124="","-",IF(ISERROR(VLOOKUP(D124,DominisDades,3,0)),"<<Domini erroni>>",VLOOKUP(D124,DominisDades,3,0))) -> - | AP124: =AVERAGE(SUMIF(AnàlisiRiscos,AC124,AnàlisiRiscosGrau),SUMIF(AnàlisiRiscos,AD124,AnàlisiRiscosGrau),SUMIF(AnàlisiRiscos,AE124,AnàlisiRiscosGrau),SUMIF(AnàlisiRiscos,AF124,AnàlisiRiscosGrau),SUMIF(AnàlisiRiscos,AG124,AnàlisiRiscosGrau),SUMIF(AnàlisiRiscos,AH124,AnàlisiRiscosGrau),SUMIF(AnàlisiRiscos,AI124,AnàlisiRiscosGrau),SUMIF(AnàlisiRiscos,AJ124,AnàlisiRiscosGrau),SUMIF(AnàlisiRiscos,AK124,AnàlisiRiscosGrau),SUMIF(AnàlisiRiscos,AL124,AnàlisiRiscosGrau),SUMIF(AnàlisiRiscos,AM124,AnàlisiRiscosGrau),SUMIF(AnàlisiRiscos,AN124,AnàlisiRiscosGrau),SUMIF(AnàlisiRiscos,AO124,AnàlisiRiscosGrau)) -> 0 | AR124: =IF(B124="","",COUNTIF('Rel.Conjunts-Sistemes'!$B:$B,$B124)) | AS124: =IF(B124="","",COUNTIF('Dominis de dades'!$B:$B,$D124))
E125: =IF(D125="","-",IF(ISERROR(VLOOKUP(D125,DominisDades,3,0)),"<<Domini erroni>>",VLOOKUP(D125,DominisDades,3,0))) -> - | AP125: =AVERAGE(SUMIF(AnàlisiRiscos,AC125,AnàlisiRiscosGrau),SUMIF(AnàlisiRiscos,AD125,AnàlisiRiscosGrau),SUMIF(AnàlisiRiscos,AE125,AnàlisiRiscosGrau),SUMIF(AnàlisiRiscos,AF125,AnàlisiRiscosGrau),SUMIF(AnàlisiRiscos,AG125,AnàlisiRiscosGrau),SUMIF(AnàlisiRiscos,AH125,AnàlisiRiscosGrau),SUMIF(AnàlisiRiscos,AI125,AnàlisiRiscosGrau),SUMIF(AnàlisiRiscos,AJ125,AnàlisiRiscosGrau),SUMIF(AnàlisiRiscos,AK125,AnàlisiRiscosGrau),SUMIF(AnàlisiRiscos,AL125,AnàlisiRiscosGrau),SUMIF(AnàlisiRiscos,AM125,AnàlisiRiscosGrau),SUMIF(AnàlisiRiscos,AN125,AnàlisiRiscosGrau),SUMIF(AnàlisiRiscos,AO125,AnàlisiRiscosGrau)) -> 0 | AR125: =IF(B125="","",COUNTIF('Rel.Conjunts-Sistemes'!$B:$B,$B125)) | AS125: =IF(B125="","",COUNTIF('Dominis de dades'!$B:$B,$D125))
E126: =IF(D126="","-",IF(ISERROR(VLOOKUP(D126,DominisDades,3,0)),"<<Domini erroni>>",VLOOKUP(D126,DominisDades,3,0))) -> - | AP126: =AVERAGE(SUMIF(AnàlisiRiscos,AC126,AnàlisiRiscosGrau),SUMIF(AnàlisiRiscos,AD126,AnàlisiRiscosGrau),SUMIF(AnàlisiRiscos,AE126,AnàlisiRiscosGrau),SUMIF(AnàlisiRiscos,AF126,AnàlisiRiscosGrau),SUMIF(AnàlisiRiscos,AG126,AnàlisiRiscosGrau),SUMIF(AnàlisiRiscos,AH126,AnàlisiRiscosGrau),SUMIF(AnàlisiRiscos,AI126,AnàlisiRiscosGrau),SUMIF(AnàlisiRiscos,AJ126,AnàlisiRiscosGrau),SUMIF(AnàlisiRiscos,AK126,AnàlisiRiscosGrau),SUMIF(AnàlisiRiscos,AL126,AnàlisiRiscosGrau),SUMIF(AnàlisiRiscos,AM126,AnàlisiRiscosGrau),SUMIF(AnàlisiRiscos,AN126,AnàlisiRiscosGrau),SUMIF(AnàlisiRiscos,AO126,AnàlisiRiscosGrau)) -> 0 | AR126: =IF(B126="","",COUNTIF('Rel.Conjunts-Sistemes'!$B:$B,$B126)) | AS126: =IF(B126="","",COUNTIF('Dominis de dades'!$B:$B,$D126))
E127: =IF(D127="","-",IF(ISERROR(VLOOKUP(D127,DominisDades,3,0)),"<<Domini erroni>>",VLOOKUP(D127,DominisDades,3,0))) -> - | AP127: =AVERAGE(SUMIF(AnàlisiRiscos,AC127,AnàlisiRiscosGrau),SUMIF(AnàlisiRiscos,AD127,AnàlisiRiscosGrau),SUMIF(AnàlisiRiscos,AE127,AnàlisiRiscosGrau),SUMIF(AnàlisiRiscos,AF127,AnàlisiRiscosGrau),SUMIF(AnàlisiRiscos,AG127,AnàlisiRiscosGrau),SUMIF(AnàlisiRiscos,AH127,AnàlisiRiscosGrau),SUMIF(AnàlisiRiscos,AI127,AnàlisiRiscosGrau),SUMIF(AnàlisiRiscos,AJ127,AnàlisiRiscosGrau),SUMIF(AnàlisiRiscos,AK127,AnàlisiRiscosGrau),SUMIF(AnàlisiRiscos,AL127,AnàlisiRiscosGrau),SUMIF(AnàlisiRiscos,AM127,AnàlisiRiscosGrau),SUMIF(AnàlisiRiscos,AN127,AnàlisiRiscosGrau),SUMIF(AnàlisiRiscos,AO127,AnàlisiRiscosGrau)) -> 0 | AR127: =IF(B127="","",COUNTIF('Rel.Conjunts-Sistemes'!$B:$B,$B127)) | AS127: =IF(B127="","",COUNTIF('Dominis de dades'!$B:$B,$D127))
E128: =IF(D128="","-",IF(ISERROR(VLOOKUP(D128,DominisDades,3,0)),"<<Domini erroni>>",VLOOKUP(D128,DominisDades,3,0))) -> - | AP128: =AVERAGE(SUMIF(AnàlisiRiscos,AC128,AnàlisiRiscosGrau),SUMIF(AnàlisiRiscos,AD128,AnàlisiRiscosGrau),SUMIF(AnàlisiRiscos,AE128,AnàlisiRiscosGrau),SUMIF(AnàlisiRiscos,AF128,AnàlisiRiscosGrau),SUMIF(AnàlisiRiscos,AG128,AnàlisiRiscosGrau),SUMIF(AnàlisiRiscos,AH128,AnàlisiRiscosGrau),SUMIF(AnàlisiRiscos,AI128,AnàlisiRiscosGrau),SUMIF(AnàlisiRiscos,AJ128,AnàlisiRiscosGrau),SUMIF(AnàlisiRiscos,AK128,AnàlisiRiscosGrau),SUMIF(AnàlisiRiscos,AL128,AnàlisiRiscosGrau),SUMIF(AnàlisiRiscos,AM128,AnàlisiRiscosGrau),SUMIF(AnàlisiRiscos,AN128,AnàlisiRiscosGrau),SUMIF(AnàlisiRiscos,AO128,AnàlisiRiscosGrau)) -> 0 | AR128: =IF(B128="","",COUNTIF('Rel.Conjunts-Sistemes'!$B:$B,$B128)) | AS128: =IF(B128="","",COUNTIF('Dominis de dades'!$B:$B,$D128))
E129: =IF(D129="","-",IF(ISERROR(VLOOKUP(D129,DominisDades,3,0)),"<<Domini erroni>>",VLOOKUP(D129,DominisDades,3,0))) -> - | AP129: =AVERAGE(SUMIF(AnàlisiRiscos,AC129,AnàlisiRiscosGrau),SUMIF(AnàlisiRiscos,AD129,AnàlisiRiscosGrau),SUMIF(AnàlisiRiscos,AE129,AnàlisiRiscosGrau),SUMIF(AnàlisiRiscos,AF129,AnàlisiRiscosGrau),SUMIF(AnàlisiRiscos,AG129,AnàlisiRiscosGrau),SUMIF(AnàlisiRiscos,AH129,AnàlisiRiscosGrau),SUMIF(AnàlisiRiscos,AI129,AnàlisiRiscosGrau),SUMIF(AnàlisiRiscos,AJ129,AnàlisiRiscosGrau),SUMIF(AnàlisiRiscos,AK129,AnàlisiRiscosGrau),SUMIF(AnàlisiRiscos,AL129,AnàlisiRiscosGrau),SUMIF(AnàlisiRiscos,AM129,AnàlisiRiscosGrau),SUMIF(AnàlisiRiscos,AN129,AnàlisiRiscosGrau),SUMIF(AnàlisiRiscos,AO129,AnàlisiRiscosGrau)) -> 0 | AR129: =IF(B129="","",COUNTIF('Rel.Conjunts-Sistemes'!$B:$B,$B129)) | AS129: =IF(B129="","",COUNTIF('Dominis de dades'!$B:$B,$D129))
E130: =IF(D130="","-",IF(ISERROR(VLOOKUP(D130,DominisDades,3,0)),"<<Domini erroni>>",VLOOKUP(D130,DominisDades,3,0))) -> - | AP130: =AVERAGE(SUMIF(AnàlisiRiscos,AC130,AnàlisiRiscosGrau),SUMIF(AnàlisiRiscos,AD130,AnàlisiRiscosGrau),SUMIF(AnàlisiRiscos,AE130,AnàlisiRiscosGrau),SUMIF(AnàlisiRiscos,AF130,AnàlisiRiscosGrau),SUMIF(AnàlisiRiscos,AG130,AnàlisiRiscosGrau),SUMIF(AnàlisiRiscos,AH130,AnàlisiRiscosGrau),SUMIF(AnàlisiRiscos,AI130,AnàlisiRiscosGrau),SUMIF(AnàlisiRiscos,AJ130,AnàlisiRiscosGrau),SUMIF(AnàlisiRiscos,AK130,AnàlisiRiscosGrau),SUMIF(AnàlisiRiscos,AL130,AnàlisiRiscosGrau),SUMIF(AnàlisiRiscos,AM130,AnàlisiRiscosGrau),SUMIF(AnàlisiRiscos,AN130,AnàlisiRiscosGrau),SUMIF(AnàlisiRiscos,AO130,AnàlisiRiscosGrau)) -> 0 | AR130: =IF(B130="","",COUNTIF('Rel.Conjunts-Sistemes'!$B:$B,$B130)) | AS130: =IF(B130="","",COUNTIF('Dominis de dades'!$B:$B,$D130))
E131: =IF(D131="","-",IF(ISERROR(VLOOKUP(D131,DominisDades,3,0)),"<<Domini erroni>>",VLOOKUP(D131,DominisDades,3,0))) -> - | AP131: =AVERAGE(SUMIF(AnàlisiRiscos,AC131,AnàlisiRiscosGrau),SUMIF(AnàlisiRiscos,AD131,AnàlisiRiscosGrau),SUMIF(AnàlisiRiscos,AE131,AnàlisiRiscosGrau),SUMIF(AnàlisiRiscos,AF131,AnàlisiRiscosGrau),SUMIF(AnàlisiRiscos,AG131,AnàlisiRiscosGrau),SUMIF(AnàlisiRiscos,AH131,AnàlisiRiscosGrau),SUMIF(AnàlisiRiscos,AI131,AnàlisiRiscosGrau),SUMIF(AnàlisiRiscos,AJ131,AnàlisiRiscosGrau),SUMIF(AnàlisiRiscos,AK131,AnàlisiRiscosGrau),SUMIF(AnàlisiRiscos,AL131,AnàlisiRiscosGrau),SUMIF(AnàlisiRiscos,AM131,AnàlisiRiscosGrau),SUMIF(AnàlisiRiscos,AN131,AnàlisiRiscosGrau),SUMIF(AnàlisiRiscos,AO131,AnàlisiRiscosGrau)) -> 0 | AR131: =IF(B131="","",COUNTIF('Rel.Conjunts-Sistemes'!$B:$B,$B131)) | AS131: =IF(B131="","",COUNTIF('Dominis de dades'!$B:$B,$D131))
... E200: =IF(D200="","-",IF(ISERROR(VLOOKUP(D200,DominisDades,3,0)),"<<Domini erroni>>",VLOOKUP(D200,DominisDades,3,0))) -> - | AP200: =AVERAGE(SUMIF(AnàlisiRiscos,AC200,AnàlisiRiscosGrau),SUMIF(AnàlisiRiscos,AD200,AnàlisiRiscosGrau),SUMIF(AnàlisiRiscos,AE200,AnàlisiRiscosGrau),SUMIF(AnàlisiRiscos,AF200,AnàlisiRiscosGrau),SUMIF(AnàlisiRiscos,AG200,AnàlisiRiscosGrau),SUMIF(AnàlisiRiscos,AH200,AnàlisiRiscosGrau),SUMIF(AnàlisiRiscos,AI200,AnàlisiRiscosGrau),SUMIF(AnàlisiRiscos,AJ200,AnàlisiRiscosGrau),SUMIF(AnàlisiRiscos,AK200,AnàlisiRiscosGrau),SUMIF(AnàlisiRiscos,AL200,AnàlisiRiscosGrau),SUMIF(AnàlisiRiscos,AM200,AnàlisiRiscosGrau),SUMIF(AnàlisiRiscos,AN200,AnàlisiRiscosGrau),SUMIF(AnàlisiRiscos,AO200,AnàlisiRiscosGrau)) -> 0 | AR200: =IF(B200="","",COUNTIF('Rel.Conjunts-Sistemes'!$B:$B,$B200)) | AS200: =IF(B200="","",COUNTIF('Dominis de dades'!$B:$B,$D200))

Sheet Rel.Conjunts-Sistemes
B5: Relacions de Conjunts de dades amb sistemes | E5: PENDENTS DE DADES COHERENTS
B8: Conjunt de dades | C8: Sistema de dades | D8: Descripció de la relació | E8: Control conjunts de dades | F8: Control sistemes d'informació | G8: Control relacións correctes
B9: Sol·licitants d'ocupació del servei local d'ocupació | C9: Sistema per a la gestió de serveis locals d’ocupació (XALOC) | D9: Ajut | E9: =IF('Rel.Conjunts-Sistemes'!B9="","",IF(COUNTIF(ConjuntsDades,'Rel.Conjunts-Sistemes'!B9)>0,"OK","Conjunt de dades erroni")) -> OK | F9: =IF('Rel.Conjunts-Sistemes'!C9="","",IF(COUNTIF(Sistemes,'Rel.Conjunts-Sistemes'!C9)>0,"OK","Conjunt de dades erroni")) -> OK | G9: =IF(AND(E9="",F9=""),"",IF(AND(E9="OK",F9="OK"),"OK","Error")) -> OK
B10: Ofertes de treball del servei local d'ocupació | C10: Sistema per a la gestió de serveis locals d’ocupació (XALOC) | D10: Sol·licitud d'ajut | E10: =IF('Rel.Conjunts-Sistemes'!B10="","",IF(COUNTIF(ConjuntsDades,'Rel.Conjunts-Sistemes'!B10)>0,"OK","Conjunt de dades erroni")) -> OK | F10: =IF('Rel.Conjunts-Sistemes'!C10="","",IF(COUNTIF(Sistemes,'Rel.Conjunts-Sistemes'!C10)>0,"OK","Conjunt de dades erroni")) -> OK | G10: =IF(AND(E10="",F10=""),"",IF(AND(E10="OK",F10="OK"),"OK","Error")) -> OK
B11: Cens de locals comercials buits | C11: Eina per al càlcul del copagament SSAD i teleassistència | D11: Persona sol·licitant d'ajut | E11: =IF('Rel.Conjunts-Sistemes'!B11="","",IF(COUNTIF(ConjuntsDades,'Rel.Conjunts-Sistemes'!B11)>0,"OK","Conjunt de dades erroni")) -> OK | F11: =IF('Rel.Conjunts-Sistemes'!C11="","",IF(COUNTIF(Sistemes,'Rel.Conjunts-Sistemes'!C11)>0,"OK","Conjunt de dades erroni")) -> OK | G11: =IF(AND(E11="",F11=""),"",IF(AND(E11="OK",F11="OK"),"OK","Error")) -> OK
B12: Cens d'empreses, comerços i establiments | C12: Eina per al càlcul del copagament SSAD i teleassistència | D12: Persones que estan inscrites al registre de voluntaris | E12: =IF('Rel.Conjunts-Sistemes'!B12="","",IF(COUNTIF(ConjuntsDades,'Rel.Conjunts-Sistemes'!B12)>0,"OK","Conjunt de dades erroni")) -> OK | F12: =IF('Rel.Conjunts-Sistemes'!C12="","",IF(COUNTIF(Sistemes,'Rel.Conjunts-Sistemes'!C12)>0,"OK","Conjunt de dades erroni")) -> OK | G12: =IF(AND(E12="",F12=""),"",IF(AND(E12="OK",F12="OK"),"OK","Error")) -> OK
B13: Polígons de l'activitat econòmica i industrial | C13: Registre d'activitats econòmiques (GIA) | D13: Documentació ajut aportada | E13: =IF('Rel.Conjunts-Sistemes'!B13="","",IF(COUNTIF(ConjuntsDades,'Rel.Conjunts-Sistemes'!B13)>0,"OK","Conjunt de dades erroni")) -> OK | F13: =IF('Rel.Conjunts-Sistemes'!C13="","",IF(COUNTIF(Sistemes,'Rel.Conjunts-Sistemes'!C13)>0,"OK","Conjunt de dades erroni")) -> OK | G13: =IF(AND(E13="",F13=""),"",IF(AND(E13="OK",F13="OK"),"OK","Error")) -> OK
B14: Tramitació i expedients administratius | C14: Registre d'analítiques de la qualitat de l’aigua | D14: Resolució ajut | E14: =IF('Rel.Conjunts-Sistemes'!B14="","",IF(COUNTIF(ConjuntsDades,'Rel.Conjunts-Sistemes'!B14)>0,"OK","Conjunt de dades erroni")) -> OK | F14: =IF('Rel.Conjunts-Sistemes'!C14="","",IF(COUNTIF(Sistemes,'Rel.Conjunts-Sistemes'!C14)>0,"OK","Conjunt de dades erroni")) -> OK | G14: =IF(AND(E14="",F14=""),"",IF(AND(E14="OK",F14="OK"),"OK","Error")) -> OK
B15: Registre general d'entrada i sortida de documents | C15: Sistema per a la gestió de serveis locals d’ocupació (XALOC) | E15: =IF('Rel.Conjunts-Sistemes'!B15="","",IF(COUNTIF(ConjuntsDades,'Rel.Conjunts-Sistemes'!B15)>0,"OK","Conjunt de dades erroni")) -> OK | F15: =IF('Rel.Conjunts-Sistemes'!C15="","",IF(COUNTIF(Sistemes,'Rel.Conjunts-Sistemes'!C15)>0,"OK","Conjunt de dades erroni")) -> OK | G15: =IF(AND(E15="",F15=""),"",IF(AND(E15="OK",F15="OK"),"OK","Error")) -> OK
B16: Registre municipal de convenis i acords institucionals | E16: =IF('Rel.Conjunts-Sistemes'!B16="","",IF(COUNTIF(ConjuntsDades,'Rel.Conjunts-Sistemes'!B16)>0,"OK","Conjunt de dades erroni")) -> OK | F16: =IF('Rel.Conjunts-Sistemes'!C16="","",IF(COUNTIF(Sistemes,'Rel.Conjunts-Sistemes'!C16)>0,"OK","Conjunt de dades erroni")) | G16: =IF(AND(E16="",F16=""),"",IF(AND(E16="OK",F16="OK"),"OK","Error")) -> Error
B17: Taulell d'anuncis i edictes oficials | E17: =IF('Rel.Conjunts-Sistemes'!B17="","",IF(COUNTIF(ConjuntsDades,'Rel.Conjunts-Sistemes'!B17)>0,"OK","Conjunt de dades erroni")) -> OK | F17: =IF('Rel.Conjunts-Sistemes'!C17="","",IF(COUNTIF(Sistemes,'Rel.Conjunts-Sistemes'!C17)>0,"OK","Conjunt de dades erroni")) | G17: =IF(AND(E17="",F17=""),"",IF(AND(E17="OK",F17="OK"),"OK","Error")) -> Error
B18: Quadre de classificació documental | E18: =IF('Rel.Conjunts-Sistemes'!B18="","",IF(COUNTIF(ConjuntsDades,'Rel.Conjunts-Sistemes'!B18)>0,"OK","Conjunt de dades erroni")) -> OK | F18: =IF('Rel.Conjunts-Sistemes'!C18="","",IF(COUNTIF(Sistemes,'Rel.Conjunts-Sistemes'!C18)>0,"OK","Conjunt de dades erroni")) | G18: =IF(AND(E18="",F18=""),"",IF(AND(E18="OK",F18="OK"),"OK","Error")) -> Error
B19: Resultats electorals per mesa i secció censal | E19: =IF('Rel.Conjunts-Sistemes'!B19="","",IF(COUNTIF(ConjuntsDades,'Rel.Conjunts-Sistemes'!B19)>0,"OK","Conjunt de dades erroni")) -> OK | F19: =IF('Rel.Conjunts-Sistemes'!C19="","",IF(COUNTIF(Sistemes,'Rel.Conjunts-Sistemes'!C19)>0,"OK","Conjunt de dades erroni")) | G19: =IF(AND(E19="",F19=""),"",IF(AND(E19="OK",F19="OK"),"OK","Error")) -> Error
B20: Registre Municipal de Parelles de Fet | E20: =IF('Rel.Conjunts-Sistemes'!B20="","",IF(COUNTIF(ConjuntsDades,'Rel.Conjunts-Sistemes'!B20)>0,"OK","Conjunt de dades erroni")) -> OK | F20: =IF('Rel.Conjunts-Sistemes'!C20="","",IF(COUNTIF(Sistemes,'Rel.Conjunts-Sistemes'!C20)>0,"OK","Conjunt de dades erroni")) | G20: =IF(AND(E20="",F20=""),"",IF(AND(E20="OK",F20="OK"),"OK","Error")) -> Error
B21: Subvencions i ajuts Atorgats | E21: =IF('Rel.Conjunts-Sistemes'!B21="","",IF(COUNTIF(ConjuntsDades,'Rel.Conjunts-Sistemes'!B21)>0,"OK","Conjunt de dades erroni")) -> OK | F21: =IF('Rel.Conjunts-Sistemes'!C21="","",IF(COUNTIF(Sistemes,'Rel.Conjunts-Sistemes'!C21)>0,"OK","Conjunt de dades erroni")) | G21: =IF(AND(E21="",F21=""),"",IF(AND(E21="OK",F21="OK"),"OK","Error")) -> Error
B22: Tresoreria: pagaments, ingressos i indicador de morositat | E22: =IF('Rel.Conjunts-Sistemes'!B22="","",IF(COUNTIF(ConjuntsDades,'Rel.Conjunts-Sistemes'!B22)>0,"OK","Conjunt de dades erroni")) -> OK | F22: =IF('Rel.Conjunts-Sistemes'!C22="","",IF(COUNTIF(Sistemes,'Rel.Conjunts-Sistemes'!C22)>0,"OK","Conjunt de dades erroni")) | G22: =IF(AND(E22="",F22=""),"",IF(AND(E22="OK",F22="OK"),"OK","Error")) -> Error
B23: Pressupost municipal i previsions financeres | E23: =IF('Rel.Conjunts-Sistemes'!B23="","",IF(COUNTIF(ConjuntsDades,'Rel.Conjunts-Sistemes'!B23)>0,"OK","Conjunt de dades erroni")) -> OK | F23: =IF('Rel.Conjunts-Sistemes'!C23="","",IF(COUNTIF(Sistemes,'Rel.Conjunts-Sistemes'!C23)>0,"OK","Conjunt de dades erroni")) | G23: =IF(AND(E23="",F23=""),"",IF(AND(E23="OK",F23="OK"),"OK","Error")) -> Error
B24: Execució del presupost municipal | E24: =IF('Rel.Conjunts-Sistemes'!B24="","",IF(COUNTIF(ConjuntsDades,'Rel.Conjunts-Sistemes'!B24)>0,"OK","Conjunt de dades erroni")) -> OK | F24: =IF('Rel.Conjunts-Sistemes'!C24="","",IF(COUNTIF(Sistemes,'Rel.Conjunts-Sistemes'!C24)>0,"OK","Conjunt de dades erroni")) | G24: =IF(AND(E24="",F24=""),"",IF(AND(E24="OK",F24="OK"),"OK","Error")) -> Error
B25: Padrons fiscals i tributs locals | E25: =IF('Rel.Conjunts-Sistemes'!B25="","",IF(COUNTIF(ConjuntsDades,'Rel.Conjunts-Sistemes'!B25)>0,"OK","Conjunt de dades erroni")) -> OK | F25: =IF('Rel.Conjunts-Sistemes'!C25="","",IF(COUNTIF(Sistemes,'Rel.Conjunts-Sistemes'!C25)>0,"OK","Conjunt de dades erroni")) | G25: =IF(AND(E25="",F25=""),"",IF(AND(E25="OK",F25="OK"),"OK","Error")) -> Error
B26: Relació de contractes menors | E26: =IF('Rel.Conjunts-Sistemes'!B26="","",IF(COUNTIF(ConjuntsDades,'Rel.Conjunts-Sistemes'!B26)>0,"OK","Conjunt de dades erroni")) -> OK | F26: =IF('Rel.Conjunts-Sistemes'!C26="","",IF(COUNTIF(Sistemes,'Rel.Conjunts-Sistemes'!C26)>0,"OK","Conjunt de dades erroni")) | G26: =IF(AND(E26="",F26=""),"",IF(AND(E26="OK",F26="OK"),"OK","Error")) -> Error
B27: Licitacions de l'ens local | E27: =IF('Rel.Conjunts-Sistemes'!B27="","",IF(COUNTIF(ConjuntsDades,'Rel.Conjunts-Sistemes'!B27)>0,"OK","Conjunt de dades erroni")) -> OK | F27: =IF('Rel.Conjunts-Sistemes'!C27="","",IF(COUNTIF(Sistemes,'Rel.Conjunts-Sistemes'!C27)>0,"OK","Conjunt de dades erroni")) | G27: =IF(AND(E27="",F27=""),"",IF(AND(E27="OK",F27="OK"),"OK","Error")) -> Error
... B111: Cens d'Activitats de Risc i Plans d'Autoprotecció (PAU) | E111: =IF('Rel.Conjunts-Sistemes'!B111="","",IF(COUNTIF(ConjuntsDades,'Rel.Conjunts-Sistemes'!B111)>0,"OK","Conjunt de dades erroni")) -> Conjunt de dades erroni | F111: =IF('Rel.Conjunts-Sistemes'!C111="","",IF(COUNTIF(Sistemes,'Rel.Conjunts-Sistemes'!C111)>0,"OK","Conjunt de dades erroni")) | G111: =IF(AND(E111="",F111=""),"",IF(AND(E111="OK",F111="OK"),"OK","Error")) -> Error
E112: =IF('Rel.Conjunts-Sistemes'!B112="","",IF(COUNTIF(ConjuntsDades,'Rel.Conjunts-Sistemes'!B112)>0,"OK","Conjunt de dades erroni")) | F112: =IF('Rel.Conjunts-Sistemes'!C112="","",IF(COUNTIF(Sistemes,'Rel.Conjunts-Sistemes'!C112)>0,"OK","Conjunt de dades erroni")) | G112: =IF(AND(E112="",F112=""),"",IF(AND(E112="OK",F112="OK"),"OK","Error"))
E113: =IF('Rel.Conjunts-Sistemes'!B113="","",IF(COUNTIF(ConjuntsDades,'Rel.Conjunts-Sistemes'!B113)>0,"OK","Conjunt de dades erroni")) | F113: =IF('Rel.Conjunts-Sistemes'!C113="","",IF(COUNTIF(Sistemes,'Rel.Conjunts-Sistemes'!C113)>0,"OK","Conjunt de dades erroni")) | G113: =IF(AND(E113="",F113=""),"",IF(AND(E113="OK",F113="OK"),"OK","Error"))
E114: =IF('Rel.Conjunts-Sistemes'!B114="","",IF(COUNTIF(ConjuntsDades,'Rel.Conjunts-Sistemes'!B114)>0,"OK","Conjunt de dades erroni")) | F114: =IF('Rel.Conjunts-Sistemes'!C114="","",IF(COUNTIF(Sistemes,'Rel.Conjunts-Sistemes'!C114)>0,"OK","Conjunt de dades erroni")) | G114: =IF(AND(E114="",F114=""),"",IF(AND(E114="OK",F114="OK"),"OK","Error"))
E115: =IF('Rel.Conjunts-Sistemes'!B115="","",IF(COUNTIF(ConjuntsDades,'Rel.Conjunts-Sistemes'!B115)>0,"OK","Conjunt de dades erroni")) | F115: =IF('Rel.Conjunts-Sistemes'!C115="","",IF(COUNTIF(Sistemes,'Rel.Conjunts-Sistemes'!C115)>0,"OK","Conjunt de dades erroni")) | G115: =IF(AND(E115="",F115=""),"",IF(AND(E115="OK",F115="OK"),"OK","Error"))
E116: =IF('Rel.Conjunts-Sistemes'!B116="","",IF(COUNTIF(ConjuntsDades,'Rel.Conjunts-Sistemes'!B116)>0,"OK","Conjunt de dades erroni")) | F116: =IF('Rel.Conjunts-Sistemes'!C116="","",IF(COUNTIF(Sistemes,'Rel.Conjunts-Sistemes'!C116)>0,"OK","Conjunt de dades erroni")) | G116: =IF(AND(E116="",F116=""),"",IF(AND(E116="OK",F116="OK"),"OK","Error"))
E117: =IF('Rel.Conjunts-Sistemes'!B117="","",IF(COUNTIF(ConjuntsDades,'Rel.Conjunts-Sistemes'!B117)>0,"OK","Conjunt de dades erroni")) | F117: =IF('Rel.Conjunts-Sistemes'!C117="","",IF(COUNTIF(Sistemes,'Rel.Conjunts-Sistemes'!C117)>0,"OK","Conjunt de dades erroni")) | G117: =IF(AND(E117="",F117=""),"",IF(AND(E117="OK",F117="OK"),"OK","Error"))
E118: =IF('Rel.Conjunts-Sistemes'!B118="","",IF(COUNTIF(ConjuntsDades,'Rel.Conjunts-Sistemes'!B118)>0,"OK","Conjunt de dades erroni")) | F118: =IF('Rel.Conjunts-Sistemes'!C118="","",IF(COUNTIF(Sistemes,'Rel.Conjunts-Sistemes'!C118)>0,"OK","Conjunt de dades erroni")) | G118: =IF(AND(E118="",F118=""),"",IF(AND(E118="OK",F118="OK"),"OK","Error"))
E119: =IF('Rel.Conjunts-Sistemes'!B119="","",IF(COUNTIF(ConjuntsDades,'Rel.Conjunts-Sistemes'!B119)>0,"OK","Conjunt de dades erroni")) | F119: =IF('Rel.Conjunts-Sistemes'!C119="","",IF(COUNTIF(Sistemes,'Rel.Conjunts-Sistemes'!C119)>0,"OK","Conjunt de dades erroni")) | G119: =IF(AND(E119="",F119=""),"",IF(AND(E119="OK",F119="OK"),"OK","Error"))
E120: =IF('Rel.Conjunts-Sistemes'!B120="","",IF(COUNTIF(ConjuntsDades,'Rel.Conjunts-Sistemes'!B120)>0,"OK","Conjunt de dades erroni")) | F120: =IF('Rel.Conjunts-Sistemes'!C120="","",IF(COUNTIF(Sistemes,'Rel.Conjunts-Sistemes'!C120)>0,"OK","Conjunt de dades erroni")) | G120: =IF(AND(E120="",F120=""),"",IF(AND(E120="OK",F120="OK"),"OK","Error"))
